Workbook

Sheet Anleitung
A1: Art.74 LAI: Dossier dès 2015 pour la saisie des données
A3: Instruction
A5: Ce classeur contient les tableaux suivants (voir marquage des onglets en couleur):
B6: Tableaux obligatoires pour la saisie des coûts et des prestations (à remplir impérativement pour le décompte OFAS)
B7: Modèle pour la CA en tant que sous-traitant UVN et le calcul du substrat du capital ainsi qu'un exemple du programme de travail PROSPREH réalisé (Bsp. Real. Arbeitsprog. LUFEB)
B8: Outils d'évaluation pour cours en bloc et cours d'un jour "Auswertungstool Blockkkurse und Auswertungstool Tageskurse" (utilisation à bien plaire)
A10: Prière de ne pas modifier les tableaux. Merci d'avance
A12: SVP, veuillez prendre note des adaptations de tableaux suivants concernant la saisie des
A13: prestations dès 2015 :
A14: - Données des organisations (Informations de base)
A15: - Comptabilité analytique consolidée
A16: - Statistique consolidée des bénéficiaires et types de cours Pour les champs en fond gris, les données ne sont plus nécessaires.
A17: Nouveaux tableaux pour la saisie des prestations:
A18: - Catégories de cours Ce tableau sera nécessaire au cas où des cours dans diverses catégories seront proposés voir annexe 9.2 CSOAPH
A19: - Programme de travail PROSPREH réalisé avec l'évaluation de l'atteinte des objectifs Relevé d'heures pour les prestations PROSPREH effectuées, voir Ch. 3021 CSOAPH
A20: Rapport sur les PROSPREH : instructions
B21: Les champs en jaune énumèrent les diverses prestations et activités.
B22: Les champs en vert indiquent les heures effectives déclarées.
B23: Les champs en orange sont réservés à l’évaluation de l'atteinte des objectifs et à la description des mesures concrètes/ réorientations prévues pour l’année ou la période contractuelle suivante.
A24: Evaluation de l'atteinte des objectifs
A25: Le mandataire a documenté la planification des activités PROSPREH dans le plan des PROSPREH lors de de la conclusion du contrat. La mise en œuvre des activités PROSPREH prévues a lieu dans l’année sous revue. A la fin de l’année, le mandataire évalue les activités PROSPREH afin d’en contrôler l'atteinte des objectifs/résultats. L’évaluation de l'atteinte des objectifs a pour but de montrer quelles PROSPREH ont été fournies pour atteindre quels objectifs. A cet effet, la référence au plan des PROSPREH est importante.
A26: Il n’est pas nécessaire d’évaluer les résultats obtenus pour toutes les prestations. L’évaluation doit porter à chaque mandataire, sur 5 à 10 prestations de manière consolidée. L’accent est mis sur les prestations qui nécessitent un grand nombre d’heures et effectuées à l’initiative du mandataire. Il s’agit d’activités essentiels, comme les exemples de bonnes pratiques. Les prestations que l'organisation ne peut contrôler, comme les réponses aux médias ou la diffusion d’information, ne vont pas être évaluées. Là où il n’y a pas d’évaluation, il faut l’indiquer en inscrivant « Pas d’évaluation ». Dans ce cas précis, aucune autre justification n’est demandée.
A27: La colonne Mesures/réorientations indique les mesures ou les réorientations adoptées ; autrement dit, elle vise ce qui est prévu pour l’année ou la période contractuelle suivante lorsqu’un objectif n’a pas été atteint, ou atteint partiellement, ou lorsque l’objectif a été redéfini. Cela correspond au cycle de conduite : plan => do => check => act.
A28: Le degré de précision des mesures prévues ou des réorientations peut varier en fonction du degré d'influence de facteurs externes non prises en compte sur une activité ou un projet . Pour chaque mesure, des objectifs partiels doivent également être formulés pour des activités ou projets d’envergure.
A29: La feuille du tableau « Exemple de programme de travail PROSPREH réalisé » contient divers exemples pour l’évaluation des objectifs qui ont été élaborés par le groupe d’échange d’expériences relatif à l’art. 74 LAI.

Sheet Organisationsdaten (Basisinfo)
A1: Données des organisations pour l'année: | D1: 2017 | F1: No de contrat: | H1: 3158 | J1: Perioden ID | K1: 5
B2: Exemple | C2: Cellules jaunes: No OFAS de chaque organisation partie au contrat de prestations. Cellules vertes: Données des organisations
A3: BSV-Nr. | B3: 2388 | C3: 3158 | CE3: Total
A4: Nombre total d'equivalents plein temps (EPT) des collaborateurs engagés dans toute l'organisation | B4: 1.3 | C4: 18.966316 | CE4: =SUM(C4:CD4) -> 18.966316
A5: Nombre d'EPT des collaborateurs engagés dans l'exploitation au sens de l'art. 74 LAI | B5: 1.2 | C5: 12.803316 | CE5: =SUM(C5:CD5) -> 12.803316
A6: Nombre total d'EPT des bénévoles actifs (dans toute l'organisation, ev. estimation) | B6: 1 | C6: 1.2736842 | CE6: =SUM(C6:CD6) -> 1.2736842
A7: Nombre d’EPT des bénévoles actifs dans l’exploitation au sens de l’art. 74 LAI | B7: 0 | C7: 1.2736842 | CE7: =SUM(C7:CD7) -> 1.2736842
A8: Nombre total d’EPT des personnes actives à titre honorifique (dans toute l’organisation, év. estimation) | B8: 0 | C8: 0.80578947 | CE8: =SUM(C8:CD8) -> 0.80578947
A9: Nombre d’EPT des personnes actives à titre honorifique dans l’exploitation au sens de l’art. 74 LAI | B9: 0 | C9: 0.45684211 | CE9: =SUM(C9:CD9) -> 0.45684211
A10: Substrat du capital relatif à l’art. 74 LAI | B10: 250000 | C10: 245798.41 | CE10: =SUM(C10:CD10) -> 245798.41
A11: Total des charges sous l’angle de la comptabilité financière (CF) (CA sous-traitant cellule B11) | B11: 320000 | C11: 995820.89 | CE11: =SUM(C11:CD11) -> 995820.89
A12: Coûts complets de l’exploitation au sens de l’art. 74 LAI après répartition (CA sous-traitant cellule W16) | B12: 340000 | C12: 763338.64 | CE12: =SUM(C12:CD12) -> 763338.64
A13: Subvention AI (CA sous-traitant cellule W18) | B13: 120000 | C13: 220636 | CE13: =SUM(C13:CD13) -> 220636
A14: Contribution de couverture de l’AI (CA sous-traitant cellule W28) | B14: 12000 | C14: -17722.976 | CE14: =SUM(C14:CD14) -> -17722.976
A15: Facteur (B10/B12) | B15: =B10/B12 -> 0.73529412 | C15: =IF(C12=0,0,C10/C12) -> 0.32200441 | D15: =IF(D12=0,0,D10/D12) -> 0 | E15: =IF(E12=0,0,E10/E12) -> 0 | F15: =IF(F12=0,0,F10/F12) -> 0 | G15: =IF(G12=0,0,G10/G12) -> 0 | H15: =IF(H12=0,0,H10/H12) -> 0 | I15: =IF(I12=0,0,I10/I12) -> 0 | J15: =IF(J12=0,0,J10/J12) -> 0 | ... CD15: =IF(CD12=0,0,CD10/CD12) -> 0
A16: Nom de l'organisation (s'affiche avec l'insertion du n° OFAS) | C16: =IF(C3="","",VLOOKUP(C3,$K22:$L671,2,0)) -> Association Cerebral Valais | D16: =IF(D3="","",VLOOKUP(D3,$K22:$L671,2,0)) | E16: =IF(E3="","",VLOOKUP(E3,$K22:$L671,2,0)) | F16: =IF(F3="","",VLOOKUP(F3,$K22:$L671,2,0)) | G16: =IF(G3="","",VLOOKUP(G3,$K22:$L671,2,0)) | H16: =IF(H3="","",VLOOKUP(H3,$K22:$L671,2,0)) | I16: =IF(I3="","",VLOOKUP(I3,$K22:$L671,2,0)) | J16: =IF(J3="","",VLOOKUP(J3,$K22:$L671,2,0)) | ... CD16: =IF(CD3="","",VLOOKUP(CD3,$K22:$L671,2,0))
A17: Attention en cas d'impression: le marquage en vert totalise 10 feuilles. | C17: =IF(AND(SUM(C4:C14)<>0,C3=0),1,"") | D17: =IF(AND(SUM(D4:D14)<>0,D3=0),1,"") | E17: =IF(AND(SUM(E4:E14)<>0,E3=0),1,"") | F17: =IF(AND(SUM(F4:F14)<>0,F3=0),1,"") | G17: =IF(AND(SUM(G4:G14)<>0,G3=0),1,"") | H17: =IF(AND(SUM(H4:H14)<>0,H3=0),1,"") | I17: =IF(AND(SUM(I4:I14)<>0,I3=0),1,"") | J17: =IF(AND(SUM(J4:J14)<>0,J3=0),1,"") | ... CD17: =IF(AND(SUM(CD4:CD14)<>0,CD3=0),1,"")
C18: =IF(AND(SUM(C4:E14)<>0,OR(D1=0,H1=0)),"Bitte geben Sie das Jahr in die Zelle D1 und Ihre Vertrags-Nr. in die Zelle H1 ein","")
C19: =IF(SUM($C17:$CD17)>0,"Bitte BSV-Nr. in rotmarkiete Felder eintragen","") | M19: =C19 | W19: =C19 | AH19: =C19 | AS19: =C19 | BD19: =C19 | BO19: =C19 | BY19: =C19
C20: VERTRAG_NR | D20: PERIODE_ID | E20: JAHR | F20: BSV_NR | G20: TABELLE | H20: FELD | I20: WERT | J20: ADRESSE | Q20: ID | R20: TABELLE | S20: FELD | T20: WERT | U20: ADRESSE
C21: =H$1 -> 3158 | D21: =K$1 -> 5 | E21: =D$1 -> 2017 | F21: =C$3 -> 3158 | G21: ORGANISATIONSDATEN | H21: ANZ_MITARBEITER | I21: =IF(ISBLANK(C4),"",C4) -> 18.966316 | J21: C4 | K21: BSV Nr. | L21: Name | Q21: 1 | R21: VERTRAG | S21: VERTRAG_NR | T21: =H1 -> 3158 | U21: H1 | CE21: =SUM(C19:CD19) -> 0
C22: =H$1 -> 3158 | D22: =K$1 -> 5 | E22: =D$1 -> 2017 | F22: =C$3 -> 3158 | G22: ORGANISATIONSDATEN | H22: ANZ_MITARBEITER_BEHINDERT | I22: =IF(ISBLANK(C5),"",C5) -> 12.803316 | J22: C5 | K22: 2011 | L22: Verein für Hörbehinderte Baden und Umgebung | Q22: 1 | R22: VERTRAG | S22: PERIODE_ID | T22: =K1 -> 5 | U22: K1
C23: =H$1 -> 3158 | D23: =K$1 -> 5 | E23: =D$1 -> 2017 | F23: =C$3 -> 3158 | G23: ORGANISATIONSDATEN | H23: ANZ_MITARBEITER_FREIWILLIG | I23: =IF(ISBLANK(C6),"",C6) -> 1.2736842 | J23: C6 | K23: 2013 | L23: Schwerhörigen-Verein Basel | Q23: 1 | R23: VERTRAG | S23: JAHR | T23: =D1 -> 2017 | U23: D1
C24: =H$1 -> 3158 | D24: =K$1 -> 5 | E24: =D$1 -> 2017 | F24: =C$3 -> 3158 | G24: ORGANISATIONSDATEN | H24: ANZ_MA_FREIWILLIG_BEHINDERT | I24: =IF(ISBLANK(C7),"",C7) -> 1.2736842 | J24: C7 | K24: 2014 | L24: Vereinigung Cerebral Basel | Q24: 1 | R24: ORGANISATION | S24: BSV_NR1 | T24: =C3 -> 3158 | U24: C3
C25: =H$1 -> 3158 | D25: =K$1 -> 5 | E25: =D$1 -> 2017 | F25: =C$3 -> 3158 | G25: ORGANISATIONSDATEN | H25: ANZ_MITARBEITER_EHRENAMTLICH | I25: =IF(ISBLANK(C8),"",C8) -> 0.80578947 | J25: C8 | K25: 2015 | L25: Behinderten Forum Dachorg. der Behinderten-Selbsthilfe Region Basel | Q25: 1 | R25: ORGANISATION | S25: BSV_NR2 | T25: =D3 -> 0 | U25: D3
C26: =H$1 -> 3158 | D26: =K$1 -> 5 | E26: =D$1 -> 2017 | F26: =C$3 -> 3158 | G26: ORGANISATIONSDATEN | H26: ANZ_MA_EHRENAMTLICH_BEHINDERT | I26: =IF(ISBLANK(C9),"",C9) -> 0.45684211 | J26: C9 | K26: 2016 | L26: SBH - Sehbehindertenhilfe Basel, Basel | Q26: 1 | R26: ORGANISATION | S26: BSV_NR3 | T26: =E3 -> 0 | U26: E3
C27: =H$1 -> 3158 | D27: =K$1 -> 5 | E27: =D$1 -> 2017 | F27: =C$3 -> 3158 | G27: ORGANISATIONSDATEN | H27: PERSONALAUFWAND | I27: =IF(ISBLANK(C10),"",C10) -> 245798.41 | J27: C10 | K27: 2018 | L27: BSBS Beratungsstelle für Gehörlose Basel | Q27: 1 | R27: ORGANISATION | S27: BSV_NR4 | T27: =F3 -> 0 | U27: F3
C28: =H$1 -> 3158 | D28: =K$1 -> 5 | E28: =D$1 -> 2017 | F28: =C$3 -> 3158 | G28: ORGANISATIONSDATEN | H28: BETRIEBSAUFWAND | I28: =IF(ISBLANK(C11),"",C11) -> 995820.89 | J28: C11 | K28: 2021 | L28: insieme Solothurn | Q28: 1 | R28: ORGANISATION | S28: BSV_NR5 | T28: =G3 -> 0 | U28: G3
C29: =H$1 -> 3158 | D29: =K$1 -> 5 | E29: =D$1 -> 2017 | F29: =C$3 -> 3158 | G29: ORGANISATIONSDATEN | H29: BETRIEBSERTRAG | I29: =IF(ISBLANK(C12),"",C12) -> 763338.64 | J29: C12 | K29: 2022 | L29: SBH Schweiz. Verein. Zug. V. Pers. Mit… | Q29: 1 | R29: ORGANISATION | S29: BSV_NR6 | T29: =H3 -> 0 | U29: H3
C30: =H$1 -> 3158 | D30: =K$1 -> 5 | E30: =D$1 -> 2017 | F30: =C$3 -> 3158 | G30: ORGANISATIONSDATEN | H30: BEITRAG_IV | I30: =IF(ISBLANK(C13),"",C13) -> 220636 | J30: C13 | K30: 2023 | L30: BSBE Beratungsstelle für Gehörlose Bern | Q30: 1 | R30: ORGANISATION | S30: BSV_NR7 | T30: =I3 -> 0 | U30: I3
C31: =H$1 -> 3158 | D31: =K$1 -> 5 | E31: =D$1 -> 2017 | F31: =C$3 -> 3158 | G31: ORGANISATIONSDATEN | H31: BEITRAG_AHV | I31: =IF(ISBLANK(C14),"",C14) -> -17722.976 | J31: C14 | K31: 2024 | L31: insieme Region Bern | Q31: 1 | R31: ORGANISATION | S31: BSV_NR8 | T31: =J3 -> 0 | U31: J3
C32: =H$1 -> 3158 | D32: =K$1 -> 5 | E32: =D$1 -> 2017 | F32: =D$3 -> 0 | G32: ORGANISATIONSDATEN | H32: ANZ_MITARBEITER | I32: =IF(ISBLANK(D4),"",D4) | J32: D4 | K32: 2026 | L32: ilco Schweiz | Q32: 1 | R32: ORGANISATION | S32: BSV_NR9 | T32: =K3 -> 0 | U32: K3
C33: =H$1 -> 3158 | D33: =K$1 -> 5 | E33: =D$1 -> 2017 | F33: =D$3 -> 0 | G33: ORGANISATIONSDATEN | H33: ANZ_MITARBEITER_BEHINDERT | I33: =IF(ISBLANK(D5),"",D5) | J33: D5 | K33: 2028 | L33: Schwerhörigen-Verein Bern | Q33: 1 | R33: ORGANISATION | S33: BSV_NR10 | T33: =L3 -> 0 | U33: L3
C34: =H$1 -> 3158 | D34: =K$1 -> 5 | E34: =D$1 -> 2017 | F34: =D$3 -> 0 | G34: ORGANISATIONSDATEN | H34: ANZ_MITARBEITER_FREIWILLIG | I34: =IF(ISBLANK(D6),"",D6) | J34: D6 | K34: 2033 | L34: Entlastungsdienst Kanton Bern | Q34: 1 | R34: ORGANISATION | S34: BSV_NR11 | T34: =M3 -> 0 | U34: M3
C35: =H$1 -> 3158 | D35: =K$1 -> 5 | E35: =D$1 -> 2017 | F35: =D$3 -> 0 | G35: ORGANISATIONSDATEN | H35: ANZ_MA_FREIWILLIG_BEHINDERT | I35: =IF(ISBLANK(D7),"",D7) | J35: D7 | K35: 2034 | L35: Team Selbsthilfe Thurgau, Weinfelden | Q35: 1 | R35: ORGANISATION | S35: BSV_NR12 | T35: =N3 -> 0 | U35: N3
C36: =H$1 -> 3158 | D36: =K$1 -> 5 | E36: =D$1 -> 2017 | F36: =D$3 -> 0 | G36: ORGANISATIONSDATEN | H36: ANZ_MITARBEITER_EHRENAMTLICH | I36: =IF(ISBLANK(D8),"",D8) | J36: D8 | K36: 2036 | L36: insieme Freiamt Wohlen | Q36: 1 | R36: ORGANISATION | S36: BSV_NR13 | T36: =O3 -> 0 | U36: O3
C37: =H$1 -> 3158 | D37: =K$1 -> 5 | E37: =D$1 -> 2017 | F37: =D$3 -> 0 | G37: ORGANISATIONSDATEN | H37: ANZ_MA_EHRENAMTLICH_BEHINDERT | I37: =IF(ISBLANK(D9),"",D9) | J37: D9 | K37: 2037 | L37: Schwerhörigen-Verein Oberwallis | Q37: 1 | R37: ORGANISATION | S37: BSV_NR14 | T37: =P3 -> 0 | U37: P3
C38: =H$1 -> 3158 | D38: =K$1 -> 5 | E38: =D$1 -> 2017 | F38: =D$3 -> 0 | G38: ORGANISATIONSDATEN | H38: PERSONALAUFWAND | I38: =IF(ISBLANK(D10),"",D10) | J38: D10 | K38: 2040 | L38: insieme-zwirniträff | Q38: 1 | R38: ORGANISATION | S38: BSV_NR15 | T38: =Q3 -> 0 | U38: Q3
C39: =H$1 -> 3158 | D39: =K$1 -> 5 | E39: =D$1 -> 2017 | F39: =D$3 -> 0 | G39: ORGANISATIONSDATEN | H39: BETRIEBSAUFWAND | I39: =IF(ISBLANK(D11),"",D11) | J39: D11 | K39: 2041 | L39: Freizeitgruppe Burgdorf | Q39: 1 | R39: ORGANISATION | S39: BSV_NR16 | T39: =R3 -> 0 | U39: R3
C40: =H$1 -> 3158 | D40: =K$1 -> 5 | E40: =D$1 -> 2017 | F40: =D$3 -> 0 | G40: ORGANISATIONSDATEN | H40: BETRIEBSERTRAG | I40: =IF(ISBLANK(D12),"",D12) | J40: D12 | K40: 2043 | L40: insieme Graubünden ED | Q40: 1 | R40: ORGANISATION | S40: BSV_NR17 | T40: =S3 -> 0 | U40: S3
...

Sheet Kostenrechnung konsolidiert
B1: CA consolidée au niveau du mandataire (CP) pour l'année: | J1: ='Organisationsdaten (Basisinfo)'!D1 -> 2017 | M1: numéro de contrat | P1: ='Organisationsdaten (Basisinfo)'!H1 -> 3158 | W1: Perioden ID | X1: ='Organisationsdaten (Basisinfo)'!K1 -> 5
B2: A | C2: B | D2: C | E2: D | F2: E | G2: F | H2: G | I2: H | J2: I | K2: J | L2: K | M2: L | N2: M | O2: N | P2: O | Q2: P | U2: T | W2: U | X2: V | Y2: W
A3: 1 | B3: Genre de coûts (indiquer les chiffres de manière complète et non seulement par tranches de mille) | C3: CF-CA | G3: Centre de coûts (coûts indirects/-produits) | J3: Unités d'imputation (Coûts directs/-produits + répartition de coûts indirects/-produits) | Y3: Total
A4: 2 | C4: Charges/Produits selon CF | D4: Délimitations CF-CA | E4: Délimitations des charges propres à la fonction d'organisation faîtière | F4: Charges/Produits selon CA | G4: Personnel | H4: Locaux | I4: Direction, administration et organes | J4: Conseil et aide aux handicapés et aux proches | K4: Aide dans les lieux d'accueil | L4: Conseil en matière de construction | M4: Conseil juridique | N4: Mise en relation avec des services d'aide et d'interprètes | O4: Cours en bloc pour handicapés et proches | P4: Cours d'un jour pour handicapés et proches | Q4: Cours annuels et semestriels pour handicapés et proches | U4: Prestation ayant pour objet de soutenir et de promouvoir la réadaptation des handicapés | W4: Accompagnement à domicile | X4: Récolte de fonds
A5: 3 | B5: Salaires | C5: - | D5: - | E5: 0 | F5: - | G5: - | H5: - | I5: - | J5: 2079.3412 | K5: 0 | L5: 0 | M5: 0 | N5: 0 | O5: 227427.32 | P5: 35858.253 | Q5: 0 | U5: 4050.1469 | W5: 0 | X5: 0 | Y5: =SUM(J5:X5) -> 269415.06 | Z5: Charges directes
A6: 4 | B6: Charges sociales | C6: - | D6: - | E6: 0 | F6: - | G6: - | H6: - | I6: - | J6: 275.33232 | K6: 0 | L6: 0 | M6: 0 | N6: 0 | O6: 30114.39 | P6: 4748.1077 | Q6: 0 | U6: 536.2931 | W6: 0 | X6: 0 | Y6: =SUM(J6:X6) -> 35674.123
A7: 5 | B7: Autres charges de personnel | C7: - | D7: - | E7: 0 | F7: - | G7: - | H7: - | I7: - | J7: 18.913683 | K7: 0 | L7: 0 | M7: 0 | N7: 0 | O7: 2068.6784 | P7: 326.16659 | Q7: 0 | U7: 36.840128 | W7: 0 | X7: 0 | Y7: =SUM(J7:X7) -> 2450.5988
A8: 6 | B8: Honoraires | C8: - | D8: - | E8: 0 | F8: - | G8: - | H8: - | I8: - | J8: 0 | K8: 0 | L8: 0 | M8: 0 | N8: 0 | O8: 0 | P8: 0 | Q8: 0 | U8: 0 | W8: 0 | X8: 0 | Y8: =SUM(J8:X8) -> 0
A9: 7 | B9: Total des charges de personnel/ Coûts | C9: - | D9: - | E9: =SUM(E5:E8) -> 0 | F9: - | G9: - | H9: - | I9: - | J9: =SUM(J5:J8) -> 2373.5872 | K9: =SUM(K5:K8) -> 0 | L9: =SUM(L5:L8) -> 0 | M9: =SUM(M5:M8) -> 0 | N9: =SUM(N5:N8) -> 0 | O9: =SUM(O5:O8) -> 259610.39 | P9: =SUM(P5:P8) -> 40932.528 | Q9: =SUM(Q5:Q8) -> 0 | U9: =SUM(U5:U8) -> 4623.2802 | W9: =SUM(W5:W8) -> 0 | X9: =SUM(X5:X8) -> 0 | Y9: =SUM(J9:X9) -> 307539.79
A10: 8 | B10: Frais de locaux | C10: - | D10: - | E10: 0 | F10: - | G10: - | H10: - | I10: - | J10: 0 | K10: 0 | L10: 0 | M10: 0 | N10: 0 | O10: 0 | P10: 0 | Q10: 0 | U10: 0 | W10: 0 | X10: 0 | Y10: =SUM(J10:X10) -> 0
A11: 9 | B11: Autres frais d'exploitation | C11: - | D11: - | E11: 0 | F11: - | G11: - | H11: - | I11: - | J11: 0 | K11: 0 | L11: 0 | M11: 0 | N11: 0 | O11: 167265.66 | P11: 28497.15 | Q11: 0 | U11: 0 | W11: 0 | X11: 0 | Y11: =SUM(J11:X11) -> 195762.81
A12: 10 | B12: amortissements (immeubles exclus) | C12: - | D12: - | E12: 0.32127082 | F12: - | G12: - | H12: - | I12: - | J12: 0 | K12: 0 | L12: 0 | M12: 0 | N12: 0 | O12: 0 | P12: 0 | Q12: 0 | U12: 0 | W12: 0 | X12: 0 | Y12: =SUM(J12:X12) -> 0
A13: 11 | B13: Total charges/coûts | C13: - | D13: - | E13: =SUM(E9:E12) -> 0.32127082 | F13: - | G13: - | H13: - | I13: - | J13: =SUM(J9:J12) -> 2373.5872 | K13: =SUM(K9:K12) -> 0 | L13: =SUM(L9:L12) -> 0 | M13: =SUM(M9:M12) -> 0 | N13: =SUM(N9:N12) -> 0 | O13: =SUM(O9:O12) -> 426876.05 | P13: =SUM(P9:P12) -> 69429.678 | Q13: =SUM(Q9:Q12) -> 0 | U13: =SUM(U9:U12) -> 4623.2802 | W13: =SUM(W9:W12) -> 0 | X13: =SUM(X9:X12) -> 0 | Y13: =SUM(J13:X13) -> 503302.6
A14: 12 | B14: Répartition charges de personnel | C14: - | D14: - | E14: 0 | F14: - | G14: - | H14: - | I14: - | J14: 0 | K14: 0 | L14: 0 | M14: 0 | N14: 0 | O14: 0 | P14: 0 | Q14: 0 | U14: 0 | W14: 0 | X14: 0 | Y14: =ROUND(SUM(J14:X14),0) -> 0 | Z14: Frais généraux
A15: 13 | B15: Répartition frais de locaux | C15: - | D15: - | E15: 0 | F15: - | G15: - | H15: - | I15: - | J15: 221.47887 | K15: 0 | L15: 0 | M15: 0 | N15: 0 | O15: 39831.704 | P15: 6478.4669 | Q15: 0 | U15: 431.39718 | W15: 0 | X15: 0 | Y15: =ROUND(SUM(J15:X15),0) -> 46963
A16: 14 | B16: Répartition direction/administration/ organes | C16: - | D16: - | E16: 0 | F16: - | G16: - | H16: - | I16: - | J16: 1004.8574 | K16: 0 | L16: 0 | M16: 0 | N16: 0 | O16: 180717.85 | P16: 29393.033 | Q16: 0 | U16: 1957.2642 | W16: 0 | X16: 0 | Y16: =ROUND(SUM(J16:X16),0) -> 213073
A17: 15 | B17: Total des répartitions | C17: - | D17: - | E17: =SUM(E14:E16) -> 0 | F17: - | G17: - | H17: - | I17: - | J17: =SUM(J14:J16) -> 1226.3363 | K17: =SUM(K14:K16) -> 0 | L17: =SUM(L14:L16) -> 0 | M17: =SUM(M14:M16) -> 0 | N17: =SUM(N14:N16) -> 0 | O17: =SUM(O14:O16) -> 220549.55 | P17: =SUM(P14:P16) -> 35871.5 | Q17: =SUM(Q14:Q16) -> 0 | U17: =SUM(U14:U16) -> 2388.6614 | W17: =SUM(W14:W16) -> 0 | X17: =SUM(X14:X16) -> 0 | Y17: =SUM(J17:X17) -> 260036.05
A18: 16 | B18: coûts complets après répartition | C18: - | D18: - | E18: =E17+E13 -> 0.32127082 | F18: - | G18: - | H18: - | I18: - | J18: =J17+J13 -> 3599.9235 | K18: =K17+K13 -> 0 | L18: =L17+L13 -> 0 | M18: =M17+M13 -> 0 | N18: =N17+N13 -> 0 | O18: =O17+O13 -> 647425.6 | P18: =P17+P13 -> 105301.18 | Q18: =Q17+Q13 -> 0 | U18: =U17+U13 -> 7011.9416 | W18: =W17+W13 -> 0 | X18: =X17+X13 -> 0 | Y18: =SUM(J18:X18) -> 763338.64
A19: 17 | B19: Produits des prestations | C19: - | D19: - | E19: - | F19: - | G19: - | H19: - | I19: - | J19: 0 | K19: 0 | L19: 0 | M19: 0 | N19: 0 | O19: 49931.05 | P19: 3929 | Q19: 0 | U19: 0 | W19: 0 | X19: 0 | Y19: =SUM(J19:Q19,U19,W19,X19) -> 53860.05
A20: 18 | B20: Subventions AI (art. 74 LAI et art. 101bis LAVS) | C20: - | D20: - | E20: 0 | F20: - | G20: - | H20: - | I20: - | J20: 12600 | K20: 0 | L20: 0 | M20: 0 | N20: 0 | O20: 200036 | P20: 0 | Q20: 0 | U20: 8000 | W20: 0 | Y20: =SUM(J20:Q20,U20,W20) -> 220636
A21: 19 | B21: Autres subventions de la confédération/ Subventions des cantons/communes | C21: - | D21: - | E21: - | F21: - | G21: - | H21: - | I21: - | J21: 0 | K21: 0 | L21: 0 | M21: 0 | N21: 0 | O21: 148049.22 | P21: 23342.782 | Q21: 0 | U21: 0 | W21: 0 | X21: 0 | Y21: =SUM(J21:Q21,U21,W21,X21) -> 171392
A22: 20 | B22: Donations directes/ Autres produits art. 74 LAI1) | C22: - | D22: - | E22: - | F22: - | G22: - | H22: - | I22: - | J22: 0 | K22: 0 | L22: 0 | M22: 0 | N22: 0 | O22: 26470 | P22: 15000 | Q22: 0 | U22: 0 | W22: 0 | X22: 0 | Y22: =SUM(J22:Q22,U22,W22,X22) -> 41470
A23: 21 | B23: Donations indirectes/ autres produits (clé de répartition) 2) | C23: - | D23: - | E23: - | F23: - | G23: - | H23: - | I23: - | J23: 1217.9492 | K23: 0 | L23: 0 | M23: 0 | N23: 0 | O23: 219041.18 | P23: 35626.169 | Q23: 0 | U23: 2372.325 | W23: 0 | X23: 0 | Y23: =SUM(J23:Q23,U23,W23,X23) -> 258257.62
A24: 22 | B24: Donations directes/ autres produits hors Art. 74 LAI 3) | C24: - | D24: - | E24: - | F24: - | G24: - | H24: - | I24: - | J24: 0 | K24: 0 | L24: 0 | M24: 0 | N24: 0 | O24: 0 | P24: 0 | Q24: 0 | U24: 0 | W24: 0 | X24: 0 | Y24: - | AB24: Plausibilisierung Kostenträger Leistungsstatistik
A25: 23 | B25: Total des produits | C25: - | D25: - | E25: =SUM(E19:E24) -> 0 | F25: - | G25: - | H25: - | I25: - | J25: =SUM(J19:J24) -> 13817.949 | K25: =SUM(K19:K24) -> 0 | L25: =SUM(L19:L24) -> 0 | M25: =SUM(M19:M24) -> 0 | N25: =SUM(N19:N24) -> 0 | O25: =SUM(O19:O24) -> 643527.44 | P25: =SUM(P19:P24) -> 77897.95 | Q25: =SUM(Q19:Q24) -> 0 | U25: =SUM(U19:U24) -> 10372.325 | W25: =SUM(W19:W24) -> 0 | X25: =SUM(X19:X24) -> 0 | Y25: =SUM(Y19:Y24) -> 745615.67 | AB25: Beratung Beh | AC25: Treffpunkte | AD25: Bauberatung | AE25: Rechtsberatung | AF25: Vermittlung Betr | AG25: Blockkurse Beh | AH25: Tageskurse Beh | AI25: Semesterk. Beh | AJ25: Blockkurse F | AK25: Tageskurse F | AL25: Semesterk. F | AM25: LUFEB | AN25: Kontrolle
A26: 24 | AB26: ='Beratung und Betreuung'!F15+'Beratung und Betreuung'!I15 -> 47 | AC26: ='Beratung und Betreuung'!K15 -> 0 | AD26: ='Beratung und Betreuung'!N15 -> 0 | AE26: ='Beratung und Betreuung'!Q15 -> 0 | AF26: ='Beratung und Betreuung'!S15 -> 0 | AG26: =KlientInnenstatistik!B15+KlientInnenstatistik!C15 -> 338 | AI26: =KlientInnenstatistik!F15+KlientInnenstatistik!G15 -> 0 | AJ26: ='Kurse Fachpersonal'!C10 -> 0 | AK26: ='Kurse Fachpersonal'!C11 -> 0 | AL26: ='Kurse Fachpersonal'!C12 -> 0 | AM26: =LUFEB!B14 -> 353
A27: 25 | B27: Contribution de couverture (Cc) I (Produit des prestations - Coûts directs) | J27: =J19-J13 -> -2373.5872 | K27: =K19-K13 -> 0 | L27: =L19-L13 -> 0 | M27: =M19-M13 -> 0 | N27: =N19-N13 -> 0 | O27: =O19-O13 -> -376945 | P27: =P19-P13 -> -65500.678 | Q27: =Q19-Q13 -> 0 | U27: =U19-U13 -> -4623.2802 | W27: =W19-W13 -> 0 | X27: - | Y27: =Y19-Y13 -> -449442.55 | AB27: =J18 -> 3599.9235 | AC27: =K18 -> 0 | AD27: =L18 -> 0 | AE27: =M18 -> 0 | AF27: =N18 -> 0 | AG27: =O18 -> 647425.6 | AH27: =P18 -> 105301.18 | AI27: =Q18 -> 0 | AJ27: =#REF! -> #REF! | AK27: =#REF! -> #REF! | AL27: =#REF! -> #REF! | AM27: =U18 -> 7011.9416
A28: 26 | B28: Contribution de couverture II ( Cc I - coûts indirects + Donations directes/ Autres produits Art.74 LAI + Donations indirectes, Autres produits (clé de répartition)) | C28: - | D28: - | F28: - | G28: - | H28: - | I28: - | J28: =J27-J17+J22+J23 -> -2381.9743 | K28: =K27-K17+K22+K23 -> 0 | L28: =L27-L17+L22+L23 -> 0 | M28: =M27-M17+M22+M23 -> 0 | N28: =N27-N17+N22+N23 -> 0 | O28: =O27-O17+O22+O23 -> -351983.38 | P28: =P27-P17+P22+P23 -> -50746.009 | Q28: =Q27-Q17+Q22+Q23 -> 0 | U28: =U27-U17+U22+U23 -> -4639.6166 | W28: =W27-W17+W22+W23 -> 0 | X28: - | Y28: =Y27-Y17+Y22+Y23 -> -409750.98 | AC28: =COUNTIF(AC26:AC27,">0") -> 0 | AD28: =COUNTIF(AD26:AD27,">0") -> 0 | AE28: =COUNTIF(AE26:AE27,">0") -> 0 | AF28: =COUNTIF(AF26:AF27,">0") -> 0 | AG28: =COUNTIF(AG26:AG27,">0") -> 2 | AH28: 0 | AI28: =COUNTIF(AI26:AI27,">0") -> 0 | AJ28: =COUNTIF(AJ26:AJ27,">0") -> 0 | AK28: =COUNTIF(AK26:AK27,">0") -> 0 | AL28: =COUNTIF(AL26:AL27,">0") -> 0 | AM28: =COUNTIF(AM26:AM27,">0") -> 2 | AN28: =COUNTIF(AB28:AM28,1) -> 0
A29: 27 | B29: Contribution de couverture III ( Cc II + autres subventions Confédération, subventions des cantons et communes) | C29: - | D29: - | F29: - | G29: - | H29: - | I29: - | J29: =J28+J21 -> -2381.9743 | K29: =K28+K21 -> 0 | L29: =L28+L21 -> 0 | M29: =M28+M21 -> 0 | N29: =N28+N21 -> 0 | O29: =O28+O21 -> -203934.16 | P29: =P28+P21 -> -27403.227 | Q29: =Q28+Q21 -> 0 | U29: =U28+U21 -> -4639.6166 | W29: =W28+W21 -> 0 | X29: - | Y29: =Y28+Y21 -> -238358.98
A30: 28 | B30: Contribution de couverture IV (Cc III + Subvention AI) | C30: - | D30: - | F30: - | G30: - | H30: - | I30: - | J30: =J29+J20 -> 10218.026 | K30: =K29+K20 -> 0 | L30: =L29+L20 -> 0 | M30: =M29+M20 -> 0 | N30: =N29+N20 -> 0 | O30: =O29+O20 -> -3898.1581 | P30: =P29+P20 -> -27403.227 | Q30: =Q29+Q20 -> 0 | U30: =U29+U20 -> 3360.3834 | W30: =W29+W20 -> 0 | X30: - | Y30: =Y29+Y20 -> -17722.976 | AB30: Plausibilisierung Direkte- Indirekte Kosten
A31: 1) Donations liées art. 74 LAI, subventions, prestations de services, sponsoring pour l'art.74 LAI | AB31: =J13 -> 2373.5872 | AC31: =K13 -> 0 | AD31: =L13 -> 0 | AE31: =M13 -> 0 | AF31: =N13 -> 0 | AG31: =O13 -> 426876.05 | AH31: =P13 -> 69429.678 | AI31: =Q13 -> 0 | AJ31: =#REF! -> #REF! | AK31: =#REF! -> #REF! | AL31: =#REF! -> #REF! | AM31: =U13 -> 4623.2802 | AN31: =#REF! -> #REF! | AO31: =W13 -> 0 | AP31: =X13 -> 0
A32: 2) Tous autres produits non affectés / donations /héritages, cotisations des membres, résultat financier, produits extraordinaires etc. sont délimités selon clé de répartition et attribués à l'activité Art. 74 LAI. | AB32: =J18 -> 3599.9235 | AC32: =K18 -> 0 | AD32: =L18 -> 0 | AE32: =M18 -> 0 | AF32: =N18 -> 0 | AG32: =O18 -> 647425.6 | AH32: =P18 -> 105301.18 | AI32: =Q18 -> 0 | AJ32: =#REF! -> #REF! | AK32: =#REF! -> #REF! | AL32: =#REF! -> #REF! | AM32: =U18 -> 7011.9416 | AN32: =#REF! -> #REF! | AO32: =W18 -> 0 | AP32: =X18 -> 0
J33: =IF(AN28<>0,"Die blaue Markierung verschwindet, sobald die Angaben für diese Leistung sowohl in der Kostenrechnung als auch in der Leistungstatistik vorhanden sind.","") | AB33: =COUNTIF(AB31:AB32,">0") -> 2 | AC33: =COUNTIF(AC31:AC32,">0") -> 0 | AD33: =COUNTIF(AD31:AD32,">0") -> 0 | AE33: =COUNTIF(AE31:AE32,">0") -> 0 | AF33: =COUNTIF(AF31:AF32,">0") -> 0 | AG33: =COUNTIF(AG31:AG32,">0") -> 2 | AH33: =COUNTIF(AH31:AH32,">0") -> 2 | AI33: =COUNTIF(AI31:AI32,">0") -> 0 | ... AP33: =COUNTIF(AP31:AP32,">0") -> 0 | AQ33: =COUNTIF(AB33:AP33,1) -> 0
A34: 3) Produits affectés hors art. 74 LAI
J35: =IF(AQ33<>0,"Die rote Markierung verschwindet, sobald für diesen Kostenträger auch direkte Kosten erfasst worden sind.","")
C40: VERTRAG_NR | D40: PERIODE_ID | E40: JAHR | F40: KOSTENTRAEGER_ID | G40: TABELLE | H40: FELD | I40: WERT | J40: ADRESSE
C41: =P$1 -> 3158 | D41: =X$1 -> 5 | E41: =J$1 -> 2017 | F41: 1 | G41: KOSTENRECHNUNG_KOSTENTRAEGER | H41: LOHNAUFWAND | I41: =IF(ISBLANK(J5),"",J5) -> 2079.3412 | J41: J5 | K41: Spaltenweise von links nach rechts | L41: Beratung und Betreuung von Behinderten&Angehörigen
C42: =P$1 -> 3158 | D42: =X$1 -> 5 | E42: =J$1 -> 2017 | F42: 1 | G42: KOSTENRECHNUNG_KOSTENTRAEGER | H42: VERSICHERUNGSAUFWAND | I42: =IF(ISBLANK(J6),"",J6) -> 275.33232 | J42: J6
C43: =P$1 -> 3158 | D43: =X$1 -> 5 | E43: =J$1 -> 2017 | F43: 1 | G43: KOSTENRECHNUNG_KOSTENTRAEGER | H43: PERSONALAUFWAND_REST | I43: =IF(ISBLANK(J7),"",J7) -> 18.913683 | J43: J7
C44: =P$1 -> 3158 | D44: =X$1 -> 5 | E44: =J$1 -> 2017 | F44: 1 | G44: KOSTENRECHNUNG_KOSTENTRAEGER | H44: HONORARE | I44: =IF(ISBLANK(J8),"",J8) -> 0 | J44: J8
...

Sheet Beratung und Betreuung
A1: Conseil et aide pour l'année: | D1: ='Organisationsdaten (Basisinfo)'!D1 -> 2017 | E1: Contrat n° | F1: ='Organisationsdaten (Basisinfo)'!H1 -> 3158 | G1: =D1 -> 2017 | H1: =E1 -> Contrat n° | I1: =F1 -> 3158 | J1: =G1 -> 2017 | K1: =I1 -> 3158 | L1: =G1 -> 2017 | M1: =H1 -> Contrat n° | N1: =I1 -> 3158 | O1: =L1 -> 2017 | P1: =M1 -> Contrat n° | Q1: =N1 -> 3158 | R1: =O1 -> 2017 | S1: =Q1 -> 3158
C3: Conseil social + aide aux handicapés | G3: Conseil aux proches et aux personnes de référence | J3: Aide dans les lieux d'accueil | L3: Conseil en matière de construction | O3: Conseil juridique | R3: Mise en relation avec des services d'aide ou d'interprète
C4: Bref conseil social | D4: Conseil individuel | E4: Conseil en groupe | F4: Total nombre de handicapés | G4: Conseil individuel | H4: Conseil en groupe | I4: Nombre de proches et de pers. de réf. Conseillés. | J4: Nombre d'heures d'aide | K4: Nombre de visites (présences) | L4: Bref conseil | M4: Conseil avec tenue de dossier | O4: Bref conseil | P4: Conseil avec tenue de dossier | R4: Nombre d'heures | S4: Nombre d'interventions
C5: Nombre d'heures | D5: Nombre d'heures | E5: Nombre d'heures | G5: Nombre d'heures | H5: Nombre d'heures | L5: Nombre d'heures | M5: Nombre d'heures | N5: Nombre de handicapés | O5: Nombre d'heures | P5: Nombre d'heures | Q5: Nombre de handicapés
A7: Bénéficiaires reconnus | B7: Handic. mentaux/ayant des difficultés pour apprendre | D7: 16.25 | F7: 1 | G7: 72 | I7: 17
B8: Handicapés de l'ouïe
B9: Handicapés physiques | C9: 13 | D9: 17.25 | F9: 8 | G9: 50.5 | I9: 18
B10: Handicapés par suite de maladie
B11: Handicapés psychiques | D11: 12 | F11: 2 | G11: 17 | I11: 1
B12: Handicapés de la vue
B13: Handicapés du langage | U13: Plausibilisierung der Totale
B14: Handicapés par suite de dépendance | U14: D | V14: E | W14: F | X14: G | Y14: H | Z14: I | AA14: J | AB14: K | AC14: M | AD14: N | AE14: P | AF14: Q | AG14: R | AH14: S | AI14: Kontrolle
B15: Total | C15: =ROUND(SUM(C7:C14),2) -> 13 | D15: =ROUND(SUM(D7:D14),2) -> 45.5 | E15: =ROUND(SUM(E7:E14),2) -> 0 | F15: =SUM(F7:F14) -> 11 | G15: =ROUND(SUM(G7:G14),2) -> 139.5 | H15: =ROUND(SUM(H7:H14),2) -> 0 | I15: =SUM(I7:I14) -> 36 | J15: =ROUND(SUM(J7:J14),2) -> 0 | K15: =SUM(K7:K14) -> 0 | L15: =ROUND(SUM(L7:L14),2) -> 0 | M15: =ROUND(SUM(M7:M14),2) -> 0 | N15: =SUM(N7:N14) -> 0 | O15: =ROUND(SUM(O7:O14),2) -> 0 | P15: =ROUND(SUM(P7:P14),2) -> 0 | Q15: =SUM(Q7:Q14) -> 0 | R15: =ROUND(SUM(R7:R14),2) -> 0 | S15: =SUM(S7:S14) -> 0 | U15: =D15-D19 -> 0 | V15: =E15-E19 -> 0 | W15: =IF(OR(F15-F19<>0,F48-F51<>0,F15-F48<>0),1,0) -> 0 | X15: =G15-G19 -> 0 | Y15: =H15-H19 -> 0 | Z15: =IF(OR(I15-I19<>0,I48-I51<>0,I15-I48<>0),1,0) -> 0 | AA15: 0 | AB15: =IF(K15-K48<>0,1,0) -> 0 | AC15: =M15-M19 -> 0 | AD15: =IF(OR(N15-N19<>0,N48-N51<>0,N15-N48<>0),1,0) -> 0 | AE15: =P15-P19 -> 0 | AF15: =IF(OR(Q15-Q19<>0,Q48-Q51<>0,Q15-Q48<>0),1,0) -> 0 | AG15: =R15-R19 -> 0 | AH15: =IF(OR(S15-S19<>0,S15-S48<>0),1,0) -> 0 | AI15: =SUM(COUNTIF(U15:AH15,"<>0")) -> 0
B16: dont plurihandicapés | D16: 8.25 | F16: 5 | G16: 72.5 | I16: 24
B17: subventionnés selon l'art. 74 LAI | D17: 45.5 | F17: 11 | G17: 139.5 | I17: 36
B18: subventionnés selon l'art. 101bis LAVS | U18: Plausibilisierung Kostenträger Leistungsstatistik
B19: Total | D19: =ROUND(SUM(D17:D18),2) -> 45.5 | E19: =ROUND(SUM(E17:E18),2) -> 0 | F19: =SUM(F17:F18) -> 11 | G19: =ROUND(SUM(G17:G18),2) -> 139.5 | H19: =ROUND(SUM(H17:H18),2) -> 0 | I19: =SUM(I17:I18) -> 36 | M19: =ROUND(SUM(M17:M18),2) -> 0 | N19: =SUM(N17:N18) -> 0 | P19: =ROUND(SUM(P17:P18),2) -> 0 | Q19: =SUM(Q17:Q18) -> 0 | R19: =ROUND(SUM(R17:R18),2) -> 0 | S19: =SUM(S17:S18) -> 0 | U19: Beratung Beh | V19: Treffpunkte | W19: Bauberatung | X19: Rechtsberatung | Y19: Vermittlung | Z19: Kontrolle
A20: Total des bénéficiaires non reconnus | U20: ='Kostenrechnung konsolidiert'!J18 -> 3599.9235 | V20: ='Kostenrechnung konsolidiert'!K18 -> 0 | W20: ='Kostenrechnung konsolidiert'!L18 -> 0 | X20: ='Kostenrechnung konsolidiert'!M18 -> 0 | Y20: ='Kostenrechnung konsolidiert'!N18 -> 0
A21: Bénéficiaires reconnus | B21: AG | I21: 1 | U21: =SUM(C15:I15) -> 245 | V21: =J15+K15 -> 0 | W21: =L15+M15+N15 -> 0 | X21: =O15+P15+Q15 -> 0 | Y21: =R15+S15 -> 0
B22: AI | V22: =COUNTIF(V20:V21,">0") -> 0 | W22: =COUNTIF(W20:W21,">0") -> 0 | X22: =COUNTIF(X20:X21,">0") -> 0 | Y22: =COUNTIF(Y20:Y21,">0") -> 0 | Z22: =COUNTIF(U22:Y22,1) -> 0
B23: AR | C23: =IF(Z22<>0,"Die blaue Markierung verschwindet, sobald die Angaben für diese Leistung sowohl in der Kostenrechnung als auch in der Leistungstatistik vorhanden sind.","")
B24: BE
B25: BL
B26: BS
B27: FR
B28: GE
B29: GL
B30: GR
B31: JU | C31: =IF(AI15<>0,"Die rote Markierung verschwindet, sobald die Totale übereinstimmen","")
B32: LU
B33: NE
B34: NW
B35: OW
B36: SG
B37: SH
B38: SO
B39: SZ
B40: TG
B41: TI
B42: UR
...

Sheet Kurstypen
A1: Cours pour les handicapés et leurs proches pour l’année | D1: ='Organisationsdaten (Basisinfo)'!D1 -> 2017 | F1: Contrat n°. | G1: ='Organisationsdaten (Basisinfo)'!H1 -> 3158 | K1: P-ID | L1: ='Organisationsdaten (Basisinfo)'!K1 -> 5
A3: Catégories de prestations | B3: Type de cours | C3: Nombre de cours | D3: Nombre de participants (personnes) | F3: Journées ou heures participant effectives
F4: Bénéficiaires reconnus au titre de l'art. 74 LAI | H4: Bénéficiaires reconnus au titre de l'art. 101bis LAVS | J4: Bénéficiaires non reconnus
F6: Handicapés/ personnes valides 1) | G6: Proches | H6: Handicapés | I6: Proches | M6: Plausibilisierung TeilnehmerInnentage/-stunden
B7: Kurstyp | C7: Anzahl Kurse | D7: Anzahl TeilnehmerInnen1) | M7: Behinderte | P7: Angehörige
M8: KlientInnenstatistik | N8: Kurstypen | O8: Kontrolle | P8: KlientInnenstatistik | Q8: Kurstypen | R8: Kontrolle
A9: Cours en bloc (journées participant) | B9: - Réadaptation | M9: =IF(AND($R9>0,C9=0),1,"") | N9: =IF(AND($R9>0,D9=0),1,"") | O9: =IF(AND($R9>0,E9=0),1,"") | P9: =IF(AND($R9>0,F9=0),1,"") | Q9: =IF(AND($R9>0,G9=0),1,"") | R9: =SUM(C9:J9) -> 0
B10: - Formation continue | R10: =SUM(C10:J10) -> 0
B11: - Loisirs et sport | C11: 29 | D11: 338 | F11: 941 | R11: =SUM(C11:J11) -> 1308
B12: Total | C12: =ROUND(SUM(C9:C11),2) -> 29 | D12: =ROUND(SUM(D9:D11),2) -> 338 | F12: =ROUND(SUM(F9:F11),2) -> 941 | G12: =ROUND(SUM(G9:G11),2) -> 0 | H12: =ROUND(SUM(H9:H11),2) -> 0 | I12: =ROUND(SUM(I9:I11),2) -> 0 | J12: =ROUND(SUM(J9:J11),2) -> 0 | L12: Blockkurse | M12: =KlientInnenstatistik!B15 -> 338 | N12: =SUM(F12,H12) -> 941 | O12: =COUNTIF(M12:N12,">0") -> 2 | P12: =KlientInnenstatistik!C15 -> 0 | Q12: =SUM(G12,I12) -> 0 | R12: =COUNTIF(P12:Q12,">0") -> 0
A13: Cours d’un jour (journées participant) | B13: - Réadaptation | R13: 0
B14: - Formation continue | R14: 0
B15: - Loisirs et sport | C15: 19 | D15: 192 | F15: 192 | R15: 0
B16: Total | C16: =ROUND(SUM(C13:C15),2) -> 19 | D16: =ROUND(SUM(D13:D15),2) -> 192 | F16: =ROUND(SUM(F13:F15),2) -> 192 | L16: Tageskurse | M16: 0 | N16: 0 | O16: 0 | P16: 0 | Q16: 0 | R16: 0
A17: Cours semestriels/ annuels (heures participant) | B17: - Réadaptation | R17: =SUM(C17:J17) -> 0
B18: - Formation continue | R18: =SUM(C18:J18) -> 0
B19: - Loisirs et sport | R19: =SUM(C19:J19) -> 0
B20: Total | C20: =ROUND(SUM(C17:C19),2) -> 0 | D20: =ROUND(SUM(D17:D19),2) -> 0 | F20: =ROUND(SUM(F17:F19),2) -> 0 | G20: =ROUND(SUM(G17:G19),2) -> 0 | H20: =ROUND(SUM(H17:H19),2) -> 0 | I20: =ROUND(SUM(I17:I19),2) -> 0 | J20: =ROUND(SUM(J17:J19),2) -> 0 | L20: Semesterkurse | M20: =KlientInnenstatistik!F15 -> 0 | N20: =SUM(F20,H20) -> 0 | O20: =COUNTIF(M20:N20,">0") -> 0 | P20: =KlientInnenstatistik!G15 -> 0 | Q20: =SUM(G20,I20) -> 0 | R20: =COUNTIF(P20:Q20,">0") -> 0
A21: Total global | C21: =SUM(C12,C16,C20) -> 48 | D21: =SUM(D12,D16,D20) -> 530 | F21: - | G21: - | H21: - | I21: - | J21: - | N21: Feld für Text | O21: =IF(OR(O12=1,O16=1,O20=1,R12=1,R16=1,R20=1),1,"") | R21: =SUM(R9:R11,R13:R15,R17:R19) -> 1308
A22: 1) Dans les cours d'un jour, les personnes non-handicapées (proches inclus) peuvent aussi être comptabilisées.
A24: =IF(OR(O21=1),"Die rote Markierung verschwindet, sobald die entsprechenden Angaben in den Tabellen Klientenstatistik und Kurstypen eingetragen sind.","")
A25: =IF(P31<>0,"Das Summentotal der Beitragsberechtigten für die Tageskurse stimmt nicht mit dem Total (Anzahl Behinderte + Anzahl Angehörige) in der Tabelle KlientInnenstatistik überein.","")
M26: Plausibilisierung Anzahl TeilnehmerInnen:
N27: KlientInnenstatistik | O27: Kurstypen | P27: Kontrolle
M28: Blockkurse | N28: =KlientInnenstatistik!B15+KlientInnenstatistik!C15 -> 338 | O28: =D12 -> 338
M29: Tageskurse | N29: 0 | O29: =SUM(F16:I16) -> 192
C30: VERTRAG_NR | D30: PERIODE_ID | E30: JAHR | F30: KURSTYP_ID | G30: KURSFORM_ID | H30: TABELLE | I30: FELD | J30: WERT | K30: ADRESSE | M30: Semesterkurse | N30: =KlientInnenstatistik!F15+KlientInnenstatistik!G15 -> 0 | O30: =D20 -> 0
C31: =G$1 -> 3158 | D31: =L$1 -> 5 | E31: =D$1 -> 2017 | F31: 1 | G31: 1 | H31: LEISTUNG_KURS_BEHINDERTE | I31: ANZAHL_KURSE | J31: =IF(ISBLANK(C9),"",C9) | K31: C9 | L31: Zeilenweise von oben nach unten (jeweils ohne "Total") | O31: Für den Text | P31: =SUM(P28:P30) -> 0
C32: =G$1 -> 3158 | D32: =L$1 -> 5 | E32: =D$1 -> 2017 | F32: 1 | G32: 1 | H32: LEISTUNG_KURS_BEHINDERTE | I32: ANZAHL_TEILNEHMER | J32: =IF(ISBLANK(D9),"",D9) | K32: D9
C33: =G$1 -> 3158 | D33: =L$1 -> 5 | E33: =D$1 -> 2017 | F33: 1 | G33: 1 | H33: LEISTUNG_KURS_BEHINDERTE | I33: PRAESENZ | J33: =IF(ISBLANK(E9),"",E9) | K33: E9
C34: =G$1 -> 3158 | D34: =L$1 -> 5 | E34: =D$1 -> 2017 | F34: 1 | G34: 1 | H34: LEISTUNG_KURS_BEHINDERTE | I34: LEISTUNG_BEH_BERECHTIGT_IVG | J34: =IF(ISBLANK(F9),"",F9) | K34: F9
C35: =G$1 -> 3158 | D35: =L$1 -> 5 | E35: =D$1 -> 2017 | F35: 1 | G35: 1 | H35: LEISTUNG_KURS_BEHINDERTE | I35: LEISTUNG_ANGEH_BERECHTIGT_IVG | J35: =IF(ISBLANK(G9),"",G9) | K35: G9
C36: =G$1 -> 3158 | D36: =L$1 -> 5 | E36: =D$1 -> 2017 | F36: 1 | G36: 1 | H36: LEISTUNG_KURS_BEHINDERTE | I36: LEISTUNG_BEH_BERECHTIGT_AHVG | J36: =IF(ISBLANK(H9),"",H9) | K36: H9
C37: =G$1 -> 3158 | D37: =L$1 -> 5 | E37: =D$1 -> 2017 | F37: 1 | G37: 1 | H37: LEISTUNG_KURS_BEHINDERTE | I37: LEISTUNG_ANGEH_BERECHTIGT_AHVG | J37: =IF(ISBLANK(I9),"",I9) | K37: I9
C38: =G$1 -> 3158 | D38: =L$1 -> 5 | E38: =D$1 -> 2017 | F38: 1 | G38: 1 | H38: LEISTUNG_KURS_BEHINDERTE | I38: LEISTUNG_NICHT_BERECHTIGT | J38: =IF(ISBLANK(J9),"",J9) | K38: J9
C39: =G$1 -> 3158 | D39: =L$1 -> 5 | E39: =D$1 -> 2017 | F39: 1 | G39: 2 | H39: LEISTUNG_KURS_BEHINDERTE | I39: ANZAHL_KURSE | J39: =IF(ISBLANK(C10),"",C10) | K39: C10
C40: =G$1 -> 3158 | D40: =L$1 -> 5 | E40: =D$1 -> 2017 | F40: 1 | G40: 2 | H40: LEISTUNG_KURS_BEHINDERTE | I40: ANZAHL_TEILNEHMER | J40: =IF(ISBLANK(D10),"",D10) | K40: D10
C41: =G$1 -> 3158 | D41: =L$1 -> 5 | E41: =D$1 -> 2017 | F41: 1 | G41: 2 | H41: LEISTUNG_KURS_BEHINDERTE | I41: PRAESENZ | J41: =IF(ISBLANK(E10),"",E10) | K41: E10
C42: =G$1 -> 3158 | D42: =L$1 -> 5 | E42: =D$1 -> 2017 | F42: 1 | G42: 2 | H42: LEISTUNG_KURS_BEHINDERTE | I42: LEISTUNG_BEH_BERECHTIGT_IVG | J42: =IF(ISBLANK(F10),"",F10) | K42: F10
C43: =G$1 -> 3158 | D43: =L$1 -> 5 | E43: =D$1 -> 2017 | F43: 1 | G43: 2 | H43: LEISTUNG_KURS_BEHINDERTE | I43: LEISTUNG_ANGEH_BERECHTIGT_IVG | J43: =IF(ISBLANK(G10),"",G10) | K43: G10
...

Sheet Kurskategorien
A1: Cours par type de cours pour l'année… | D1: ='Organisationsdaten (Basisinfo)'!D1 -> 2017 | F1: Contrat n° | G1: ='Organisationsdaten (Basisinfo)'!H1 -> 3158
A3: Catégories de prestations | B3: Type de cours | C3: Nombre de cours | D3: Total des coûts complets | E3: Journées ou heures participant effectives | J3: Total
E4: Bénéficaires reconnus selon l'art. 74 LAI | G4: Bénéficiaires reconnus selon l'art. 101bis LAVS | I4: Bénéficaires non reconnus
E6: Handicapés /personnes valides 1) | F6: Proches | G6: Handicapés | H6: Proches
B7: Kurstyp | C7: Anzahl Kurse
A9: Cours en bloc (journées participant) nuitée à l'hôtel obligatoire | B9: Catégorie 1 | J9: =SUM(E9:I9) -> 0
B10: Catégorie 2 | J10: =SUM(E10:I10) -> 0
B11: Catégorie 3 | C11: 29 | D11: 647425.6 | E11: 941 | J11: =SUM(E11:I11) -> 941
B12: Total | C12: =SUM(C9:C11) -> 29 | D12: =SUM(D9:D11) -> 647425.6 | E12: =SUM(E9:E11) -> 941 | F12: =SUM(F9:F11) -> 0 | G12: =SUM(G9:G11) -> 0 | H12: =SUM(H9:H11) -> 0 | I12: =SUM(I9:I11) -> 0 | J12: =SUM(E12:I12) -> 941
A13: Cours d'un jour (journées participant) | B13: Catégorie 1 | J13: =SUM(E13:I13) -> 0
B14: Catégorie 2 | C14: 5 | D14: 27710.836 | E14: 61 | J14: =SUM(E14:I14) -> 61
B15: Catégorie 3 | C15: 14 | D15: 77590.341 | E15: 131 | J15: =SUM(E15:I15) -> 131
B16: Total | C16: =SUM(C13:C15) -> 19 | D16: =SUM(D13:D15) -> 105301.18 | E16: =SUM(E13:E15) -> 192 | F16: =SUM(F13:F15) -> 0 | G16: =SUM(G13:G15) -> 0 | H16: =SUM(H13:H15) -> 0 | I16: =SUM(I13:I15) -> 0 | J16: =SUM(E16:I16) -> 192
A17: Cours semestriels/annuels (heures participant) | B17: Catégorie 1 | J17: =SUM(E17:I17) -> 0
B20: Total | C20: =SUM(C17:C19) -> 0 | D20: =SUM(D17:D19) -> 0 | E20: =SUM(E17:E19) -> 0 | F20: =SUM(F17:F19) -> 0 | G20: =SUM(G17:G19) -> 0 | H20: =SUM(H17:H19) -> 0 | I20: =SUM(I17:I19) -> 0 | J20: =SUM(E20:I20) -> 0
A21: Total global | C21: =SUM(C20,C16,C12) -> 48 | D21: =SUM(D20,D16,D12) -> 752726.78 | E21: - | F21: - | G21: - | H21: - | I21: - | J21: =SUM(E21:I21) -> 0
A22: 1) Dans les cours d'un jour, les personnes non-handicapées (proches inclus) peuvent aussi être comptabilisées.
A24: Reporting:
A25: Le mandataire indique dans le reporting les cours et les unités de prestation selon la catégorie de cours en tenant compte des coûts complets par UP et des critères d’attribution. L’affectation se fait selon les tableaux suivants :
A28: Coûts complets/UP | B28: Critères d'attribution cours en bloc | F28: Coûts complets/UP | H28: Critères d'attribution cours d'un jour
B29: A | C29: B | D29: C | H29: A | I29: B | J29: C
A30: < 442 | B30: Cat 1 | C30: Cat 1 | D30: Cat 1 | F30: < 341 | H30: Cat 1 | I30: Cat 1 | J30: Cat 1
A31: 442 à 642 | B31: Cat 1 | C31: Cat 2 | D31: Cat 2 | F31: 341 à 475 | H31: Cat 1 | I31: Cat 2 | J31: Cat 2
A32: > 643 | B32: Cat 1 | C32: Cat 2 | D32: Cat 3 | F32: > 475 | H32: Cat 1 | I32: Cat 2 | J32: Cat 3

Sheet KlientInnenstatistik
F1: Contrat n° | G1: ='Organisationsdaten (Basisinfo)'!H1 -> 3158 | H1: P-ID | I1: ='Organisationsdaten (Basisinfo)'!K1 -> 5
A2: Statistique des bénéficiaires : cours pour les handicapés et leurs proches pour l’année | G2: ='Organisationsdaten (Basisinfo)'!D1 -> 2017
A3: (N’indiquer que les bénéficiaires reconnus)
B4: Cours en bloc | D4: Cours d’un jour1) | F4: Cours semestriels/annuels
B5: Nombre de handicapés (personnes) | C5: Nombre de proches (personnes) | D5: - | E5: - | F5: Nombre de handicapés (personnes) | G5: Nombre de proches (personnes)
D6: - | E6: -
A7: Handicapés mentaux ou ayant des difficultés d’apprentissage | B7: 10
A8: Handicapés de l’ouïe
A9: Handicapés physiques | B9: 328 | H9: =IF(M23<>0,"Die blaue Markierung verschwindet, sobald die Angaben für diese Leistung sowohl in der Kostenrechnung als auch in der Leistungs-statistik vorhanden sind.","")
A10: Handicapés par suite de maladie
A11: Handicapés psychiques
A12: Handicapés de la vue
A13: Handicapés du langage
A14: Handicapés par suite de dépendance
A15: Total | B15: =SUM(B7:B14) -> 338 | C15: =SUM(C7:C14) -> 0 | D15: - | E15: - | F15: =SUM(F7:F14) -> 0 | G15: =SUM(G7:G14) -> 0 | J15: Plausibilisierung der Totale
A16: dont plurihandicapés | B16: 319 | J16: Blockkurse | L16: Tageskurse | N16: Semesterkurse | P16: Kontrolle
A17: AG | J17: Behinderte | K17: Angehörige | L17: Behinderte | M17: Angehörige | N17: Behinderte | O17: Angehörige
A18: AI | J18: =B15-B44 -> 0 | K18: =C15-C44 -> 0 | L18: 0 | M18: 0 | N18: =F15-F44 -> 0 | O18: =G15-G44 -> 0 | P18: =SUM(COUNTIF(J18:O18,"<>0")) -> 0
A19: AR | J19: Plausibilisierung Kostenträger Leistungsstatistik
A20: BE | H20: =IF(P18<>0,"Die rote Markierung verschwindet, sobald die Totale übereinstimmen.","") | J20: Blockkurse Beh | K20: Tageskurse Beh | L20: Semesterk. Beh | M20: Kontrolle
A21: BL | J21: ='Kostenrechnung konsolidiert'!O18 -> 647425.6 | K21: ='Kostenrechnung konsolidiert'!P18 -> 105301.18 | L21: ='Kostenrechnung konsolidiert'!Q18 -> 0
A22: BS | J22: =B15+C15 -> 338 | K22: 0 | L22: =F15+G15 -> 0
A23: FR | J23: =COUNTIF(J21:J22,">0") -> 2 | K23: 0 | L23: =COUNTIF(L21:L22,">0") -> 0 | M23: =COUNTIF(J23:L23,1) -> 0
A24: GE
A25: GL
A26: GR
A27: JU
A28: LU
A29: NE
A30: NW
A31: OW
A32: SG
A33: SH
A34: SO
A35: SZ
... A39: VD
A40: VS | B40: 338
A41: ZG
A42: ZH
A43: Autre provenance (seulement ayants droit)
...

Sheet Kurse Fachpersonal
E1: LV-Nr. | F1: ='Organisationsdaten (Basisinfo)'!H1 -> 3158 | G1: P-ID | H1: ='Organisationsdaten (Basisinfo)'!K1 -> 5 | I1: Plausibilisierung Kostenträger Leistungsstatistik
A2: Kurse zur Fortbildung von Fach- und Sekretariatspersonal für das Jahr | F2: ='Organisationsdaten (Basisinfo)'!D1 -> 2017 | I2: Blockkurse F | J2: Tageskurse F | K2: Semesterk. F | L2: Kontrolle
I3: ='Kostenrechnung konsolidiert'!#REF! -> #REF! | J3: ='Kostenrechnung konsolidiert'!#REF! -> #REF! | K3: ='Kostenrechnung konsolidiert'!#REF! -> #REF!
A4: Leistungskategorien | B4: Anzahl Kurse | C4: Anzahl Teilnehmer- Innen (Personen) | E4: Tatsächliche TeilnehmerInnentage resp. -stunden | I4: =C10 -> 0 | J4: =C11 -> 0 | K4: =C12 -> 0
E5: Beitragsberechtigte Art. 74 IVG | F5: Nicht Beitrags- berechtigte | I5: =COUNTIF(I3:I4,">0") -> 0 | J5: =COUNTIF(J3:J4,">0") -> 0 | K5: =COUNTIF(K3:K4,">0") -> 0 | L5: =COUNTIF(I5:K5,1) -> 0
I7: Plausibilisierung
A8: Leistungskategorie | B8: Anzahl Kurse | C8: Anzahl TeilnehmerInnen1) | I8: Kontrolle | J8: Kurse | K8: TeilneherInnen | L8: Präsenz | M8: TeilnehmerInnentate
A10: Blockkurse (TeilnehmerInnentage) | I10: =SUM(B10:F10) -> 0 | J10: =IF(AND($I10>0,B10=0),1,"") | K10: =IF(AND($I10>0,C10=0),1,"") | M10: =IF(AND($I10>0,E10=0),1,"")
A11: Tageskurse (TeilnehmerInnentage) | G11: =IF(C11<E11+F11,"Es gibt mehr TeilnehmerInnentage als TeilnehmerInnen","") | I11: =SUM(E11:F11) -> 0 | J11: =IF(AND($I11>0,B11=0),1,"") | K11: =IF(AND($I11>0,C11=0),1,"") | M11: =IF(AND($I11>0,E11=0),1,"")
A12: Semester- und Jahreskurse (TeilnehmerInnenstunden) | I12: =SUM(B12:F12) -> 0 | J12: =IF(AND($I12>0,B12=0),1,"") | K12: =IF(AND($I12>0,C12=0),1,"") | M12: =IF(AND($I12>0,E12=0),1,"")
A13: Total | B13: =SUM(B10:B12) -> 0 | C13: =SUM(C10:C12) -> 0 | E13: - | F13: -
I14: Feld für Text | J14: =SUM(J10:M12) -> 0
A15: =IF(L5<>0,"Die blaue Markierung verschwindet, sobald die Angaben für diese Leistung sowohl in der Kostenrechnung als auch in der Leistungstatistik vorhanden sind.","") | J15: =IF(AND(I10=1,B10<>0),1,"")
A17: =IF(J14<>0,"Die rote Markierung verschwindet, sobald alle notwendigen Angaben in der entsprechenden Zeile gemacht sind.","")
B20: VERTRAG_NR | C20: PERIODE_ID | D20: JAHR | E20: KURSTYP_ID | F20: TABELLE | G20: FELD | H20: WERT | I20: ADRESSE
B21: =F$1 -> 3158 | C21: =H$1 -> 5 | D21: =F$2 -> 2017 | E21: 1 | F21: LEISTUNG_KURS_FORTBILDUNG | G21: ANZAHL_KURSE | H21: =IF(ISBLANK(B10),"",B10) | I21: B10
B22: =F$1 -> 3158 | C22: =H$1 -> 5 | D22: =F$2 -> 2017 | E22: 1 | F22: LEISTUNG_KURS_FORTBILDUNG | G22: ANZAHL_TEILNEHMER | H22: =IF(ISBLANK(C10),"",C10) | I22: C10
B23: =F$1 -> 3158 | C23: =H$1 -> 5 | D23: =F$2 -> 2017 | E23: 1 | F23: LEISTUNG_KURS_FORTBILDUNG | G23: PRAESENZ | H23: =IF(ISBLANK(D10),"",D10) | I23: D10
B24: =F$1 -> 3158 | C24: =H$1 -> 5 | D24: =F$2 -> 2017 | E24: 1 | F24: LEISTUNG_KURS_FORTBILDUNG | G24: LEISTUNG_IVG_AHVG | H24: =IF(ISBLANK(E10),"",E10) | I24: E10
B25: =F$1 -> 3158 | C25: =H$1 -> 5 | D25: =F$2 -> 2017 | E25: 1 | F25: LEISTUNG_KURS_FORTBILDUNG | G25: LEISTUNG_NICHT_BERECHTIGT | H25: =IF(ISBLANK(F10),"",F10) | I25: F10
B26: =F$1 -> 3158 | C26: =H$1 -> 5 | D26: =F$2 -> 2017 | E26: 2 | F26: LEISTUNG_KURS_FORTBILDUNG | G26: ANZAHL_KURSE | H26: =IF(ISBLANK(B11),"",B11) | I26: B11
B27: =F$1 -> 3158 | C27: =H$1 -> 5 | D27: =F$2 -> 2017 | E27: 2 | F27: LEISTUNG_KURS_FORTBILDUNG | G27: ANZAHL_TEILNEHMER | H27: =IF(ISBLANK(C11),"",C11) | I27: C11
B28: =F$1 -> 3158 | C28: =H$1 -> 5 | D28: =F$2 -> 2017 | E28: 2 | F28: LEISTUNG_KURS_FORTBILDUNG | G28: PRAESENZ | H28: =IF(ISBLANK(D11),"",D11) | I28: D11
B29: =F$1 -> 3158 | C29: =H$1 -> 5 | D29: =F$2 -> 2017 | E29: 2 | F29: LEISTUNG_KURS_FORTBILDUNG | G29: LEISTUNG_IVG_AHVG | H29: =IF(ISBLANK(E11),"",E11) | I29: E11
B30: =F$1 -> 3158 | C30: =H$1 -> 5 | D30: =F$2 -> 2017 | E30: 2 | F30: LEISTUNG_KURS_FORTBILDUNG | G30: LEISTUNG_NICHT_BERECHTIGT | H30: =IF(ISBLANK(F11),"",F11) | I30: F11
B31: =F$1 -> 3158 | C31: =H$1 -> 5 | D31: =F$2 -> 2017 | E31: 3 | F31: LEISTUNG_KURS_FORTBILDUNG | G31: ANZAHL_KURSE | H31: =IF(ISBLANK(B12),"",B12) | I31: B12
B32: =F$1 -> 3158 | C32: =H$1 -> 5 | D32: =F$2 -> 2017 | E32: 3 | F32: LEISTUNG_KURS_FORTBILDUNG | G32: ANZAHL_TEILNEHMER | H32: =IF(ISBLANK(C12),"",C12) | I32: C12
B33: =F$1 -> 3158 | C33: =H$1 -> 5 | D33: =F$2 -> 2017 | E33: 3 | F33: LEISTUNG_KURS_FORTBILDUNG | G33: PRAESENZ | H33: =IF(ISBLANK(D12),"",D12) | I33: D12
B34: =F$1 -> 3158 | C34: =H$1 -> 5 | D34: =F$2 -> 2017 | E34: 3 | F34: LEISTUNG_KURS_FORTBILDUNG | G34: LEISTUNG_IVG_AHVG | H34: =IF(ISBLANK(E12),"",E12) | I34: E12
B35: =F$1 -> 3158 | C35: =H$1 -> 5 | D35: =F$2 -> 2017 | E35: 3 | F35: LEISTUNG_KURS_FORTBILDUNG | G35: LEISTUNG_NICHT_BERECHTIGT | H35: =IF(ISBLANK(F12),"",F12) | I35: F12

Sheet LUFEB
A1: Contrat n° | B1: ='Organisationsdaten (Basisinfo)'!H1 -> 3158 | D1: P-ID | E1: ='Organisationsdaten (Basisinfo)'!K1 -> 5
A2: PROSPREH | B2: ='Organisationsdaten (Basisinfo)'!D1 -> 2017
B3: Total heures 1) | C3: Handicapés mentaux ou ayant des difficultés d’apprentissage | D3: Handicapés de l’ouïe | E3: Handicapés physiques | F3: Handicapés par suite de maladie | G3: Handicapés psychiques | H3: Handicapés de la vue | I3: Handicapés du langage | J3: Handicapés par suite de dépendance | K3: Pluri-handicapés
C4: =SUM(C5:C7) -> 0 | D4: =SUM(D5:D7) -> 0 | E4: =SUM(E5:E7) -> 282.4 | F4: =SUM(F5:F7) -> 0 | G4: =SUM(G5:G7) -> 0 | H4: =SUM(H5:H7) -> 0 | I4: =SUM(I5:I7) -> 0 | J4: =SUM(J5:J7) -> 0 | K4: =SUM(K5:K7) -> 70.6
A5: Tâches générales d’information et de relations publiques (GC B) | B5: 69 | C5: 0 | D5: 0 | E5: 55.2 | F5: 0 | G5: 0 | H5: 0 | I5: 0 | J5: 0 | K5: 13.8 | P5: =SUM(C5:K5)-B5 -> 0
A6: Médias et publications du mandataire accessibles au public (GC C) | B6: 284 | C6: 0 | D6: 0 | E6: 227.2 | F6: 0 | G6: 0 | H6: 0 | I6: 0 | J6: 0 | K6: 56.8 | P6: =SUM(C6:K6)-B6 -> 0
A7: Centre d’information et de documentation (GC C) | P7: =SUM(C7:K7)-B7 -> 0
C8: =C9 -> 0 | D8: =D9 -> 0 | E8: =E9 -> 0 | F8: =F9 -> 0 | G8: =G9 -> 0 | H8: =H9 -> 0 | I8: =I9 -> 0 | J8: =J9 -> 0 | K8: =K9 -> 0
A9: Développement, élaboration et diffusion de matériel d’information destiné aux handicapés sensoriels ou ayant des difficultés d’apprentissage (GC C) | P9: =SUM(C9:K9)-B9 -> 0
A12: Travail de fonds sur des thèmes spécifiques / collaboration dans des projets (GC C) | P12: =SUM(C12:K12)-B12 -> 0
A13: Prestations de base pour l'encouragement de l'entraide / conseil aux organisations et groupes d'entraide (GC C) | P13: =SUM(C13:K13)-B13 -> 0
A14: Total PROSPREH | B14: =SUM(B5,B6,B7,B9,B12,B13) -> 353 | C14: =SUM(C5,C6,C7,C9,C12,C13) -> 0 | D14: =SUM(D5,D6,D7,D9,D12,D13) -> 0 | E14: =SUM(E5,E6,E7,E9,E12,E13) -> 282.4 | F14: =SUM(F5,F6,F7,F9,F12,F13) -> 0 | G14: =SUM(G5,G6,G7,G9,G12,G13) -> 0 | H14: =SUM(H5,H6,H7,H9,H12,H13) -> 0 | I14: =SUM(I5,I6,I7,I9,I12,I13) -> 0 | ... K14: =SUM(K5,K6,K7,K9,K12,K13) -> 70.6 | P14: =SUM(C14:K14)-B14 -> 0
A15: 1) Le total des heures doit être réparti autant que possible sur les différents groupes de personnes handicapés. | P15: =SUM(P5,P6,P7,P9,P12,P13,P14) -> 0
A16: GC=Groupe de compensation
A17: =IF(L39<>0,"Die blaue Markierung verschwindet, sobald die Angaben für diese Leistung sowohl in der Kostenrechnung als auch in der Leistungstatistik vorhanden sind.","")
A20: =IF(P15<>0,"Die Summe der Stunden nach Zielgruppen stimmen nicht mit dem Total überein.","")
C35: VERTRAG_NR | D35: PERIODE_ID | E35: JAHR | F35: ZIELGRUPPE_ID | G35: TABELLE | H35: FELD | I35: WERT | J35: ADRESSE
C36: =B$1 -> 3158 | D36: =E$1 -> 5 | E36: =B$2 -> 2017 | G36: LUFEB | H36: STUNDEN_OEFFENTLICHKEITSARBEIT | I36: =IF(ISBLANK(B4),"",B4) | K36: LUFEB | L36: Kontrolle
C37: =B$1 -> 3158 | D37: =E$1 -> 5 | E37: =B$2 -> 2017 | G37: LUFEB | H37: OEFFENTLICHKEITSARBEIT_ALLG | I37: =IF(ISBLANK(B5),"",B5) -> 69 | J37: B5 | K37: ='Kostenrechnung konsolidiert'!U18 -> 7011.9416
C38: =B$1 -> 3158 | D38: =E$1 -> 5 | E38: =B$2 -> 2017 | G38: LUFEB | H38: PUBLIKATIONEN | I38: =IF(ISBLANK(B6),"",B6) -> 284 | J38: B6 | K38: =B14 -> 353
C39: =B$1 -> 3158 | D39: =E$1 -> 5 | E39: =B$2 -> 2017 | G39: LUFEB | H39: INFORMATIONSSTELLEN | I39: =IF(ISBLANK(B7),"",B7) | J39: B7 | K39: =COUNTIF(K37:K38,">0") -> 2 | L39: =COUNTIF(K39,1) -> 0
C40: =B$1 -> 3158 | D40: =E$1 -> 5 | E40: =B$2 -> 2017 | G40: LUFEB | H40: STUNDEN_DIENSTLEISTUNGEN | I40: =IF(ISBLANK(B8),"",B8)
C41: =B$1 -> 3158 | D41: =E$1 -> 5 | E41: =B$2 -> 2017 | G41: LUFEB | H41: INFORMATIONSMATERIALIEN | I41: =IF(ISBLANK(B9),"",B9) | J41: B9
C42: =B$1 -> 3158 | D42: =E$1 -> 5 | E42: =B$2 -> 2017 | G42: LUFEB | H42: BETREUUNGSDIENSTE | I42: =IF(ISBLANK(B10),"",B10) | J42: B10
C43: =B$1 -> 3158 | D43: =E$1 -> 5 | E43: =B$2 -> 2017 | G43: LUFEB | H43: DOLMETSCHDIENSTE | I43: =IF(ISBLANK(B11),"",B11) | J43: B11
C44: =B$1 -> 3158 | D44: =E$1 -> 5 | E44: =B$2 -> 2017 | G44: LUFEB | H44: STUNDEN_GRUNDLAGENARBEIT | I44: =IF(ISBLANK(B12),"",B12) | J44: B12
C45: =B$1 -> 3158 | D45: =E$1 -> 5 | E45: =B$2 -> 2017 | G45: LUFEB | H45: STUNDEN_FOERDERUNG_SELBSTHILFE | I45: =IF(ISBLANK(B13),"",B13) | J45: B13
C46: =B$1 -> 3158 | D46: =E$1 -> 5 | E46: =B$2 -> 2017 | F46: 1 | G46: LUFEB_ZIELGRUPPE | H46: STUNDEN_OEFFENTLICHKEITSARBEIT | I46: =C4 -> 0 | J46: C4
C47: =B$1 -> 3158 | D47: =E$1 -> 5 | E47: =B$2 -> 2017 | F47: 2 | G47: LUFEB_ZIELGRUPPE | H47: STUNDEN_OEFFENTLICHKEITSARBEIT | I47: =D4 -> 0 | J47: D4
C48: =B$1 -> 3158 | D48: =E$1 -> 5 | E48: =B$2 -> 2017 | F48: 3 | G48: LUFEB_ZIELGRUPPE | H48: STUNDEN_OEFFENTLICHKEITSARBEIT | I48: =E4 -> 282.4 | J48: E4
C49: =B$1 -> 3158 | D49: =E$1 -> 5 | E49: =B$2 -> 2017 | F49: 4 | G49: LUFEB_ZIELGRUPPE | H49: STUNDEN_OEFFENTLICHKEITSARBEIT | I49: =F4 -> 0 | J49: F4
C50: =B$1 -> 3158 | D50: =E$1 -> 5 | E50: =B$2 -> 2017 | F50: 5 | G50: LUFEB_ZIELGRUPPE | H50: STUNDEN_OEFFENTLICHKEITSARBEIT | I50: =G4 -> 0 | J50: G4
C51: =B$1 -> 3158 | D51: =E$1 -> 5 | E51: =B$2 -> 2017 | F51: 6 | G51: LUFEB_ZIELGRUPPE | H51: STUNDEN_OEFFENTLICHKEITSARBEIT | I51: =H4 -> 0 | J51: H4
C52: =B$1 -> 3158 | D52: =E$1 -> 5 | E52: =B$2 -> 2017 | F52: 7 | G52: LUFEB_ZIELGRUPPE | H52: STUNDEN_OEFFENTLICHKEITSARBEIT | I52: =I4 -> 0 | J52: I4
C53: =B$1 -> 3158 | D53: =E$1 -> 5 | E53: =B$2 -> 2017 | F53: 8 | G53: LUFEB_ZIELGRUPPE | H53: STUNDEN_OEFFENTLICHKEITSARBEIT | I53: =J4 -> 0 | J53: J4
C54: =B$1 -> 3158 | D54: =E$1 -> 5 | E54: =B$2 -> 2017 | F54: -2 | G54: LUFEB_ZIELGRUPPE | H54: STUNDEN_OEFFENTLICHKEITSARBEIT | I54: =K4 -> 70.6 | J54: K4
C55: =B$1 -> 3158 | D55: =E$1 -> 5 | E55: =B$2 -> 2017 | F55: 1 | G55: LUFEB_ZIELGRUPPE | H55: STUNDEN_DIENSTLEISTUNGEN | I55: =C8 -> 0 | J55: C8
C56: =B$1 -> 3158 | D56: =E$1 -> 5 | E56: =B$2 -> 2017 | F56: 2 | G56: LUFEB_ZIELGRUPPE | H56: STUNDEN_DIENSTLEISTUNGEN | I56: =D8 -> 0 | J56: D8
C57: =B$1 -> 3158 | D57: =E$1 -> 5 | E57: =B$2 -> 2017 | F57: 3 | G57: LUFEB_ZIELGRUPPE | H57: STUNDEN_DIENSTLEISTUNGEN | I57: =E8 -> 0 | J57: E8
C58: =B$1 -> 3158 | D58: =E$1 -> 5 | E58: =B$2 -> 2017 | F58: 4 | G58: LUFEB_ZIELGRUPPE | H58: STUNDEN_DIENSTLEISTUNGEN | I58: =F8 -> 0 | J58: F8
...

Sheet Begleitetes Wohnen
A1: Accompagnement pour l'année | C1: ='Organisationsdaten (Basisinfo)'!D1 -> 2017 | D1: Contrat n°. | E1: ='Organisationsdaten (Basisinfo)'!H1 -> 3158
C3: Accompagnement à domicile de personnes handicapées
C4: Total d’heures d’accompagnement brutes | D4: Nombre de semaines de présence | E4: Nombre de bénéficiaires
A7: Bénéficiaires reconnus | B7: Handicapés mentaux ou ayant des difficultés d’apprentissage
B8: Handicapés de l’ouïe
B9: Handicapés physiques
B10: Handicapés par suite de maladie
B11: Handicapés psychiques
B12: Handicapés de la vue
B13: Handicapés du langage | T13: Plausibilisierung der Totale
B14: Handicapés par suite de dépendance | V14: F | W14: G | X14: H | Z14: Kontrolle
B15: Total | C15: =SUM(C7:C14) -> 0 | D15: =SUM(D7:D14) -> 0 | E15: =SUM(E7:E14) -> 0 | V15: =IF(OR(C15-C19<>0,C15-C47<>0),1,0) -> 0 | W15: =IF(OR(D15-D19<>0,D15-D47<>0),1,0) -> 0 | X15: =IF(OR(E15-E19<>0,E15-E47<>0),1,0) -> 0 | Z15: =SUM(COUNTIF(V15:X15,"<>0")) -> 0
B16: dont plurihandicapés
B17: reconnus au titre de l'art. 74 LAI
B18: reconnus au titre de l'art.101bis LAVS | T18: Plausibilisierung Kostenträger Leistungsstatistik
B19: Total | C19: =ROUND(SUM(C17:C18),2) -> 0 | D19: =SUM(D17:D18) -> 0 | E19: =SUM(E17:E18) -> 0 | F19: =IF(X20=1,"Die blaue Markierung verschwindet, sobald die Angaben für diese Leistung sowohl in der Kostenrechnung als auch in der Leistungstatistik vorhanden sind.","") | U19: Kore BW | V19: BW
A20: Total des bénéficiaires non reconnus | U20: ='Kostenrechnung konsolidiert'!W18 -> 0 | V20: =E15 -> 0 | X20: =COUNTIF(U20:V20,">0") -> 0
A21: Bénéficiaires reconnus | B21: AG
B22: AI
B23: AR
B24: BE
B25: BL
B26: BS
B27: FR
B28: GE | F28: =IF(Z15<>0,"Die rote Markierung verschwindet, sobald die Totale übereinstimmen","")
B29: GL
B30: GR
B31: JU
B32: LU
B33: NE
B34: NW
B35: OW
B36: SG
B37: SH
B38: SO
B39: SZ
B40: TG
... B46: ZH
B47: Total | C47: =SUM(C21:C46) -> 0 | D47: =SUM(D21:D46) -> 0 | E47: =SUM(E21:E46) -> 0
B48: Nouveaux bénéficiaires
...

Sheet Realisiertes Arbeitsprog. LUFEB
B2: Programme de travail PROSPREH réalisé pour l'année | C2: ='Organisationsdaten (Basisinfo)'!D1 -> 2017 | D2: Contrat n°. | E2: ='Organisationsdaten (Basisinfo)'!H1 -> 3158
A4: Prestations effectives réalisées selon l'annexe 9.3 CSOAPH à décompter pour l'OFAS Liste des différentes activités à introduire dans les champs jaunes. Au besoin, insérez-y des lignes supplémentaires. | E4: Données sur la charge d'heures effectives doivent être insérées dans les champs en vert. | F4: Evaluation de l'atteinte des objectifs Les données suivantes peuvent être résumées pour chaque sous-catégorie de prestations ou présentées en détail pour toutes les activités exercées. Nombre d’évaluations requises : de 5 à 10
F5: Résultat visé selon le plan | G5: Evaluation de l'atteinte des objectifs (par rapport au résultat visé) | H5: Mesures / réorientations (brève description, le reste est à indiquer sous planification, évt délai prévu)
A6: Tâches générales d’information et de relations publiques (groupe de compensation B) | E6: Heures imputées1)
A7: Renseignements généraux (3158 VS) | E7: 69
A10: Total groupe de compensation B | E10: =SUM(E7:E9) -> 69
A11: Prestations spécifiques PROSPREH (groupe de compensation C) | E11: Heures imputées1)
A12: Médias et publications de l’organisation accessibles au public
A13: Bulletion Connaître (3158 VS) | E13: 150 | F13: Les bulletins d'information des associations régionales sont dans la langue locales et abordent les thèmes chers aux membres ciblés | G13: Appréciation des résulats
A14: Site internet et page Facebook (3158 VS) | E14: 134 | F14: Les groupes cibles connaissent les prestations et les produits de l'association Cerebral Suisse, et sont toujours tenus au courant des dernières nouveautés | G14: Appréciation des résulats
A16: Total médias et publications de l’organisation accessibles au public | E16: =SUM(E13:E15) -> 284
A17: Centre d’information et de documentation
A21: Total centre d’information et de documentation | E21: =SUM(E18:E20) -> 0
A22: Développement, élaboration et diffusion de matériel d’information et de supports médiatiques à l’attention des handicapés sensoriels ou mentaux, ou ayant des difficultés d'apprentissage
A26: Total Développement, élaboration et diffusion de matériel d’information et de supports médiatiques à l’attention des handicapés sensoriels ou mentaux, ou ayant des difficultés d'apprentissage | E26: =SUM(E23:E25) -> 0
A27: Travail de fond ou projets ayant pour objet un thème spécifique
A31: Total Travail de fond ou projets ayant pour objet un thème spécifique | E31: =SUM(E28:E30) -> 0
