Workbook

Sheet gescon_intervenant
A1: lgn_interven | B1: lien_contact | C1: Lu_matin | D1: Lu_repmid | E1: Lu_aprem | F1: Lu_repsoi | G1: Lu_soire | H1: Ma_matin | I1: Ma_repmid | J1: Ma_aprem | K1: Ma_repsoi | L1: Ma_soire | M1: Me_matin | N1: Me_repmid | O1: Me_aprem | P1: Me_repsoi | Q1: Me_soire | R1: Je_matin | S1: Je_repmid | T1: Je_aprem | U1: Je_repsoi | V1: Je_soire | W1: Ve_matin | X1: Ve_repmid | Y1: Ve_aprem | Z1: Ve_repsoi | AA1: Ve_soire | AB1: Sa_matin | AC1: Sa_repmid | AD1: Sa_aprem | AE1: Sa_repsoi | AF1: Sa_soire | AG1: Di_matin | AH1: Di_repmid | AI1: Di_aprem | AJ1: Di_repsoi | AK1: Di_soire | AL1: RegInter_prio | AM1: RegInter_event | AN1: RegInter_depan | AO1: Exper_Compet | AP1: References
A2: 1 | B2: 2072341970 | C2: FALSE | D2: FALSE | E2: FALSE | F2: FALSE | G2: FALSE | H2: FALSE | I2: FALSE | J2: FALSE | K2: FALSE | L2: FALSE | M2: FALSE | N2: FALSE | O2: FALSE | P2: FALSE | Q2: FALSE | R2: FALSE | S2: FALSE | T2: FALSE | U2: FALSE | V2: FALSE | W2: FALSE | X2: FALSE | Y2: FALSE | Z2: FALSE | AA2: FALSE | AB2: FALSE | AC2: FALSE | AD2: FALSE | AE2: FALSE | AF2: FALSE | AG2: FALSE | AH2: FALSE | AI2: FALSE | AJ2: FALSE | AK2: FALSE | AL2: Sion
A3: 2 | B3: -554084105 | C3: FALSE | D3: FALSE | E3: FALSE | F3: FALSE | G3: FALSE | H3: FALSE | I3: FALSE | J3: FALSE | K3: FALSE | L3: FALSE | M3: FALSE | N3: FALSE | O3: FALSE | P3: FALSE | Q3: FALSE | R3: FALSE | S3: FALSE | T3: FALSE | U3: FALSE | V3: FALSE | W3: FALSE | X3: FALSE | Y3: FALSE | Z3: FALSE | AA3: FALSE | AB3: FALSE | AC3: FALSE | AD3: FALSE | AE3: FALSE | AF3: FALSE | AG3: FALSE | AH3: FALSE | AI3: FALSE | AJ3: FALSE | AK3: FALSE | AL3: Sion | AO3: - Particiaption aux activités Cerebral
A4: 3 | B4: -1100872493 | C4: FALSE | D4: FALSE | E4: FALSE | F4: FALSE | G4: FALSE | H4: FALSE | I4: FALSE | J4: FALSE | K4: FALSE | L4: FALSE | M4: FALSE | N4: FALSE | O4: FALSE | P4: FALSE | Q4: FALSE | R4: FALSE | S4: FALSE | T4: FALSE | U4: FALSE | V4: FALSE | W4: FALSE | X4: FALSE | Y4: FALSE | Z4: FALSE | AA4: FALSE | AB4: FALSE | AC4: FALSE | AD4: FALSE | AE4: FALSE | AF4: FALSE | AG4: FALSE | AH4: FALSE | AI4: FALSE | AJ4: FALSE | AK4: FALSE | AL4: Monthey | AM4: Martigny | AO4: participe aux w-e et camps cerebral
A5: 4 | B5: 1291910802 | C5: FALSE | D5: FALSE | E5: FALSE | F5: FALSE | G5: FALSE | H5: FALSE | I5: FALSE | J5: FALSE | K5: FALSE | L5: FALSE | M5: FALSE | N5: FALSE | O5: FALSE | P5: FALSE | Q5: FALSE | R5: FALSE | S5: FALSE | T5: FALSE | U5: FALSE | V5: FALSE | W5: FALSE | X5: FALSE | Y5: FALSE | Z5: FALSE | AA5: FALSE | AB5: FALSE | AC5: FALSE | AD5: FALSE | AE5: FALSE | AF5: FALSE | AG5: FALSE | AH5: FALSE | AI5: FALSE | AJ5: FALSE | AK5: FALSE | AL5: Monthey | AM5: Martigny | AO5: participe aux activités cerebral
A6: 5 | B6: 1142412576 | C6: FALSE | D6: FALSE | E6: FALSE | F6: FALSE | G6: FALSE | H6: FALSE | I6: FALSE | J6: FALSE | K6: FALSE | L6: FALSE | M6: FALSE | N6: FALSE | O6: FALSE | P6: FALSE | Q6: FALSE | R6: FALSE | S6: FALSE | T6: FALSE | U6: FALSE | V6: FALSE | W6: FALSE | X6: FALSE | Y6: FALSE | Z6: FALSE | AA6: FALSE | AB6: FALSE | AC6: FALSE | AD6: FALSE | AE6: FALSE | AF6: FALSE | AG6: FALSE | AH6: FALSE | AI6: FALSE | AJ6: FALSE | AK6: FALSE | AL6: Sion | AM6: Sierre | AN6: Savièse | AO6: participe aux activité Cerebral
A7: 6 | B7: 1317305611 | C7: FALSE | D7: FALSE | E7: FALSE | F7: FALSE | G7: FALSE | H7: FALSE | I7: FALSE | J7: FALSE | K7: FALSE | L7: FALSE | M7: FALSE | N7: FALSE | O7: FALSE | P7: FALSE | Q7: FALSE | R7: FALSE | S7: FALSE | T7: FALSE | U7: FALSE | V7: FALSE | W7: FALSE | X7: TRUE | Y7: TRUE | Z7: TRUE | AA7: TRUE | AB7: FALSE | AC7: FALSE | AD7: FALSE | AE7: FALSE | AF7: FALSE | AG7: FALSE | AH7: FALSE | AI7: FALSE | AJ7: FALSE | AK7: FALSE | AL7: Conthey | AM7: Sion | AO7: pas disponible 1x par mois le vendredi entre 17h-18h participe aux activités cerebral
A8: 7 | B8: 1924663704 | C8: FALSE | D8: FALSE | E8: FALSE | F8: FALSE | G8: FALSE | H8: FALSE | I8: FALSE | J8: FALSE | K8: FALSE | L8: FALSE | M8: FALSE | N8: FALSE | O8: FALSE | P8: FALSE | Q8: FALSE | R8: FALSE | S8: FALSE | T8: FALSE | U8: FALSE | V8: FALSE | W8: FALSE | X8: FALSE | Y8: FALSE | Z8: FALSE | AA8: FALSE | AB8: FALSE | AC8: FALSE | AD8: FALSE | AE8: FALSE | AF8: FALSE | AG8: FALSE | AH8: FALSE | AI8: FALSE | AJ8: FALSE | AK8: FALSE | AL8: Sierre | AM8: Sion | AO8: participe aux activités Cerebral
A9: 8 | B9: 1315811525 | C9: FALSE | D9: FALSE | E9: FALSE | F9: FALSE | G9: FALSE | H9: FALSE | I9: FALSE | J9: FALSE | K9: FALSE | L9: FALSE | M9: FALSE | N9: FALSE | O9: FALSE | P9: FALSE | Q9: FALSE | R9: FALSE | S9: FALSE | T9: FALSE | U9: FALSE | V9: FALSE | W9: FALSE | X9: FALSE | Y9: FALSE | Z9: FALSE | AA9: FALSE | AB9: FALSE | AC9: FALSE | AD9: FALSE | AE9: FALSE | AF9: FALSE | AG9: FALSE | AH9: FALSE | AI9: FALSE | AJ9: FALSE | AK9: FALSE | AL9: Sion | AM9: Sierre | AN9: Martigny | AO9: permis de voiture participe aux activités Cerebral dimanche jusqu'à 20h30
A10: 9 | B10: 1493190852 | C10: FALSE | D10: FALSE | E10: FALSE | F10: FALSE | G10: FALSE | H10: FALSE | I10: FALSE | J10: FALSE | K10: FALSE | L10: FALSE | M10: FALSE | N10: FALSE | O10: FALSE | P10: FALSE | Q10: FALSE | R10: FALSE | S10: FALSE | T10: FALSE | U10: FALSE | V10: FALSE | W10: FALSE | X10: FALSE | Y10: FALSE | Z10: FALSE | AA10: FALSE | AB10: FALSE | AC10: FALSE | AD10: FALSE | AE10: FALSE | AF10: FALSE | AG10: FALSE | AH10: FALSE | AI10: FALSE | AJ10: FALSE | AK10: FALSE
A11: 10 | B11: 1314194184 | C11: FALSE | D11: FALSE | E11: FALSE | F11: FALSE | G11: FALSE | H11: FALSE | I11: FALSE | J11: TRUE | K11: FALSE | L11: FALSE | M11: FALSE | N11: FALSE | O11: FALSE | P11: FALSE | Q11: FALSE | R11: FALSE | S11: FALSE | T11: FALSE | U11: FALSE | V11: FALSE | W11: FALSE | X11: FALSE | Y11: FALSE | Z11: TRUE | AA11: TRUE | AB11: TRUE | AC11: TRUE | AD11: TRUE | AE11: TRUE | AF11: TRUE | AG11: TRUE | AH11: TRUE | AI11: TRUE | AJ11: TRUE | AK11: TRUE | AL11: Martigny | AM11: Monthey | AO11: participe aux activités Cerebral disponible du 16.11.11 au 16.03.12 et toutes les vacances scolaires
A12: 11 | B12: 1290764579 | C12: FALSE | D12: FALSE | E12: FALSE | F12: FALSE | G12: FALSE | H12: FALSE | I12: FALSE | J12: FALSE | K12: FALSE | L12: FALSE | M12: FALSE | N12: FALSE | O12: FALSE | P12: FALSE | Q12: FALSE | R12: FALSE | S12: FALSE | T12: FALSE | U12: FALSE | V12: FALSE | W12: FALSE | X12: FALSE | Y12: FALSE | Z12: FALSE | AA12: FALSE | AB12: FALSE | AC12: FALSE | AD12: FALSE | AE12: FALSE | AF12: FALSE | AG12: FALSE | AH12: FALSE | AI12: FALSE | AJ12: FALSE | AK12: FALSE | AL12: Monthey | AM12: Martigny | AO12: particiaption aux activités Cerebral + Asa stagiaire à Cerebral en 2011 permis de conduire
A13: 12 | B13: 558428742 | C13: FALSE | D13: FALSE | E13: FALSE | F13: FALSE | G13: FALSE | H13: FALSE | I13: FALSE | J13: FALSE | K13: FALSE | L13: FALSE | M13: FALSE | N13: FALSE | O13: FALSE | P13: FALSE | Q13: FALSE | R13: FALSE | S13: FALSE | T13: FALSE | U13: FALSE | V13: FALSE | W13: FALSE | X13: FALSE | Y13: FALSE | Z13: FALSE | AA13: FALSE | AB13: FALSE | AC13: FALSE | AD13: FALSE | AE13: FALSE | AF13: FALSE | AG13: FALSE | AH13: FALSE | AI13: FALSE | AJ13: FALSE | AK13: FALSE | AL13: Martigny | AM13: Monthey | AN13: Sion | AO13: participe aux activités Cerebral
A14: 13 | B14: 1229346852 | C14: FALSE | D14: FALSE | E14: FALSE | F14: FALSE | G14: FALSE | H14: FALSE | I14: FALSE | J14: FALSE | K14: FALSE | L14: FALSE | M14: FALSE | N14: FALSE | O14: FALSE | P14: FALSE | Q14: FALSE | R14: FALSE | S14: FALSE | T14: FALSE | U14: FALSE | V14: FALSE | W14: FALSE | X14: FALSE | Y14: FALSE | Z14: FALSE | AA14: FALSE | AB14: FALSE | AC14: FALSE | AD14: FALSE | AE14: FALSE | AF14: FALSE | AG14: FALSE | AH14: FALSE | AI14: FALSE | AJ14: FALSE | AK14: FALSE | AL14: Sierre | AM14: Rarogne | AN14: Viège | AO14: participe aux activités Cerebral
A15: 14 | B15: 1185283018 | C15: FALSE | D15: FALSE | E15: FALSE | F15: TRUE | G15: TRUE | H15: FALSE | I15: FALSE | J15: FALSE | K15: FALSE | L15: FALSE | M15: TRUE | N15: TRUE | O15: TRUE | P15: TRUE | Q15: TRUE | R15: TRUE | S15: TRUE | T15: TRUE | U15: TRUE | V15: TRUE | W15: TRUE | X15: FALSE | Y15: FALSE | Z15: FALSE | AA15: FALSE | AB15: TRUE | AC15: FALSE | AD15: FALSE | AE15: FALSE | AF15: FALSE | AG15: TRUE | AH15: FALSE | AI15: FALSE | AJ15: FALSE | AK15: FALSE | AL15: Conthey | AM15: Sion | AN15: Martigny | AO15: -participe aux activités Cerebral - permis +voiture pour mettre une cahisse pliable
A16: 15 | B16: 1283238740 | C16: FALSE | D16: FALSE | E16: FALSE | F16: FALSE | G16: FALSE | H16: FALSE | I16: FALSE | J16: FALSE | K16: FALSE | L16: FALSE | M16: FALSE | N16: FALSE | O16: FALSE | P16: FALSE | Q16: FALSE | R16: FALSE | S16: FALSE | T16: FALSE | U16: FALSE | V16: FALSE | W16: FALSE | X16: FALSE | Y16: FALSE | Z16: FALSE | AA16: FALSE | AB16: FALSE | AC16: FALSE | AD16: FALSE | AE16: FALSE | AF16: FALSE | AG16: FALSE | AH16: FALSE | AI16: FALSE | AJ16: FALSE | AK16: FALSE | AL16: Sion | AM16: Sierre | AO16: - participe aux activités Cerebral
A17: 16 | B17: 1272349759 | C17: FALSE | D17: FALSE | E17: FALSE | F17: TRUE | G17: TRUE | H17: FALSE | I17: FALSE | J17: FALSE | K17: TRUE | L17: TRUE | M17: FALSE | N17: FALSE | O17: FALSE | P17: TRUE | Q17: TRUE | R17: FALSE | S17: FALSE | T17: FALSE | U17: TRUE | V17: TRUE | W17: FALSE | X17: FALSE | Y17: FALSE | Z17: TRUE | AA17: TRUE | AB17: TRUE | AC17: TRUE | AD17: TRUE | AE17: TRUE | AF17: TRUE | AG17: TRUE | AH17: TRUE | AI17: TRUE | AJ17: TRUE | AK17: TRUE | AL17: Martigny | AM17: Monthey | AN17: Sion
A18: 17 | B18: 402979448 | C18: FALSE | D18: FALSE | E18: FALSE | F18: FALSE | G18: FALSE | H18: FALSE | I18: FALSE | J18: FALSE | K18: FALSE | L18: FALSE | M18: FALSE | N18: FALSE | O18: FALSE | P18: FALSE | Q18: FALSE | R18: FALSE | S18: FALSE | T18: FALSE | U18: FALSE | V18: FALSE | W18: FALSE | X18: FALSE | Y18: FALSE | Z18: FALSE | AA18: FALSE | AB18: FALSE | AC18: FALSE | AD18: FALSE | AE18: FALSE | AF18: FALSE | AG18: FALSE | AH18: FALSE | AI18: FALSE | AJ18: FALSE | AK18: FALSE | AL18: Sion | AM18: Sierre | AO18: - participe aux activités Cerebral
A19: 18 | B19: 1831959862 | C19: FALSE | D19: FALSE | E19: FALSE | F19: FALSE | G19: FALSE | H19: FALSE | I19: FALSE | J19: FALSE | K19: FALSE | L19: FALSE | M19: FALSE | N19: FALSE | O19: FALSE | P19: FALSE | Q19: FALSE | R19: FALSE | S19: FALSE | T19: FALSE | U19: FALSE | V19: FALSE | W19: FALSE | X19: FALSE | Y19: FALSE | Z19: FALSE | AA19: FALSE | AB19: FALSE | AC19: FALSE | AD19: FALSE | AE19: FALSE | AF19: FALSE | AG19: FALSE | AH19: FALSE | AI19: FALSE | AJ19: FALSE | AK19: FALSE | AL19: Sierre | AM19: Sion | AO19: - paricipe aux activités Cerebral
A20: 19 | B20: 1265008574 | C20: FALSE | D20: FALSE | E20: FALSE | F20: FALSE | G20: FALSE | H20: FALSE | I20: FALSE | J20: FALSE | K20: FALSE | L20: FALSE | M20: FALSE | N20: FALSE | O20: FALSE | P20: FALSE | Q20: FALSE | R20: FALSE | S20: FALSE | T20: FALSE | U20: FALSE | V20: FALSE | W20: FALSE | X20: FALSE | Y20: FALSE | Z20: FALSE | AA20: FALSE | AB20: FALSE | AC20: FALSE | AD20: FALSE | AE20: FALSE | AF20: FALSE | AG20: FALSE | AH20: FALSE | AI20: FALSE | AJ20: FALSE | AK20: FALSE | AL20: Sierre | AM20: Sion | AO20: -participation aux activités Cerebral - lundi de 15h30 à 22h30 - mardi idem - mercredi de 11h45 à 16h30 - jeudi de 15h30 à 22h30 vedredi de 15h30 à 22h30
A21: 20 | B21: 1273502716 | C21: FALSE | D21: FALSE | E21: FALSE | F21: FALSE | G21: FALSE | H21: FALSE | I21: FALSE | J21: FALSE | K21: FALSE | L21: FALSE | M21: FALSE | N21: FALSE | O21: FALSE | P21: FALSE | Q21: FALSE | R21: FALSE | S21: FALSE | T21: FALSE | U21: FALSE | V21: FALSE | W21: FALSE | X21: FALSE | Y21: FALSE | Z21: TRUE | AA21: TRUE | AB21: TRUE | AC21: TRUE | AD21: TRUE | AE21: TRUE | AF21: TRUE | AG21: TRUE | AH21: TRUE | AI21: TRUE | AJ21: TRUE | AK21: TRUE | AL21: Martigny | AM21: Sion | AO21: - participation aux activités Cerebral le lundi à partir de avril
A22: 21 | B22: 1322732912 | C22: FALSE | D22: FALSE | E22: FALSE | F22: FALSE | G22: FALSE | H22: FALSE | I22: FALSE | J22: FALSE | K22: FALSE | L22: FALSE | M22: FALSE | N22: FALSE | O22: FALSE | P22: FALSE | Q22: FALSE | R22: FALSE | S22: FALSE | T22: FALSE | U22: FALSE | V22: FALSE | W22: FALSE | X22: FALSE | Y22: FALSE | Z22: FALSE | AA22: FALSE | AB22: FALSE | AC22: FALSE | AD22: FALSE | AE22: FALSE | AF22: FALSE | AG22: FALSE | AH22: FALSE | AI22: FALSE | AJ22: FALSE | AK22: FALSE | AL22: Sierre | AM22: Sion | AO22: doit faire 2 W-e avant de faire partie des intervenants
A23: 22 | B23: 2541 | C23: FALSE | D23: FALSE | E23: FALSE | F23: FALSE | G23: FALSE | H23: FALSE | I23: FALSE | J23: FALSE | K23: FALSE | L23: FALSE | M23: FALSE | N23: FALSE | O23: FALSE | P23: FALSE | Q23: FALSE | R23: FALSE | S23: FALSE | T23: FALSE | U23: FALSE | V23: FALSE | W23: FALSE | X23: FALSE | Y23: FALSE | Z23: FALSE | AA23: FALSE | AB23: FALSE | AC23: FALSE | AD23: FALSE | AE23: FALSE | AF23: FALSE | AG23: FALSE | AH23: FALSE | AI23: FALSE | AJ23: FALSE | AK23: FALSE
A24: 23 | B24: 1319632834 | C24: TRUE | D24: FALSE | E24: FALSE | F24: FALSE | G24: FALSE | H24: FALSE | I24: FALSE | J24: FALSE | K24: FALSE | L24: FALSE | M24: FALSE | N24: FALSE | O24: FALSE | P24: FALSE | Q24: FALSE | R24: FALSE | S24: FALSE | T24: FALSE | U24: FALSE | V24: FALSE | W24: FALSE | X24: FALSE | Y24: FALSE | Z24: FALSE | AA24: FALSE | AB24: FALSE | AC24: FALSE | AD24: FALSE | AE24: FALSE | AF24: FALSE | AG24: FALSE | AH24: FALSE | AI24: FALSE | AJ24: FALSE | AK24: FALSE | AL24: Sion | AM24: Conthey | AN24: Sierre | AO24: école d'infirmier à fait 2 W-E à cerebral
A25: 24 | B25: 674820052 | C25: FALSE | D25: FALSE | E25: FALSE | F25: FALSE | G25: FALSE | H25: FALSE | I25: FALSE | J25: FALSE | K25: FALSE | L25: FALSE | M25: FALSE | N25: FALSE | O25: FALSE | P25: FALSE | Q25: FALSE | R25: FALSE | S25: FALSE | T25: FALSE | U25: FALSE | V25: FALSE | W25: FALSE | X25: FALSE | Y25: FALSE | Z25: FALSE | AA25: FALSE | AB25: FALSE | AC25: FALSE | AD25: FALSE | AE25: FALSE | AF25: FALSE | AG25: FALSE | AH25: FALSE | AI25: FALSE | AJ25: FALSE | AK25: FALSE | AL25: Sion | AM25: Sierre | AN25: Savièse
A26: 25 | B26: -1042748270 | C26: FALSE | D26: FALSE | E26: FALSE | F26: FALSE | G26: FALSE | H26: FALSE | I26: FALSE | J26: FALSE | K26: FALSE | L26: FALSE | M26: TRUE | N26: FALSE | O26: FALSE | P26: FALSE | Q26: FALSE | R26: FALSE | S26: FALSE | T26: FALSE | U26: FALSE | V26: FALSE | W26: FALSE | X26: FALSE | Y26: FALSE | Z26: TRUE | AA26: TRUE | AB26: TRUE | AC26: FALSE | AD26: TRUE | AE26: FALSE | AF26: FALSE | AG26: TRUE | AH26: FALSE | AI26: TRUE | AJ26: FALSE | AK26: FALSE | AL26: Monthey | AM26: Choëx | AN26: Martigny
A27: 26 | B27: -1820907060 | C27: FALSE | D27: FALSE | E27: FALSE | F27: FALSE | G27: FALSE | H27: FALSE | I27: FALSE | J27: FALSE | K27: FALSE | L27: FALSE | M27: FALSE | N27: FALSE | O27: FALSE | P27: FALSE | Q27: FALSE | R27: FALSE | S27: FALSE | T27: FALSE | U27: FALSE | V27: FALSE | W27: FALSE | X27: FALSE | Y27: FALSE | Z27: FALSE | AA27: FALSE | AB27: FALSE | AC27: FALSE | AD27: FALSE | AE27: FALSE | AF27: FALSE | AG27: FALSE | AH27: FALSE | AI27: FALSE | AJ27: FALSE | AK27: FALSE | AL27: Sierre | AM27: Sion | AN27: Martigny
A28: 27 | B28: 1316707040 | C28: FALSE | D28: FALSE | E28: FALSE | F28: FALSE | G28: FALSE | H28: FALSE | I28: FALSE | J28: FALSE | K28: FALSE | L28: FALSE | M28: FALSE | N28: FALSE | O28: FALSE | P28: FALSE | Q28: FALSE | R28: FALSE | S28: FALSE | T28: FALSE | U28: FALSE | V28: FALSE | W28: FALSE | X28: FALSE | Y28: FALSE | Z28: FALSE | AA28: FALSE | AB28: FALSE | AC28: FALSE | AD28: FALSE | AE28: FALSE | AF28: FALSE | AG28: FALSE | AH28: FALSE | AI28: FALSE | AJ28: FALSE | AK28: FALSE | AL28: Sion | AM28: Sierre | AN28: Martigny
A29: 28 | B29: 1017724288 | C29: FALSE | D29: FALSE | E29: FALSE | F29: FALSE | G29: FALSE | H29: FALSE | I29: FALSE | J29: FALSE | K29: FALSE | L29: FALSE | M29: FALSE | N29: FALSE | O29: FALSE | P29: FALSE | Q29: FALSE | R29: FALSE | S29: FALSE | T29: FALSE | U29: FALSE | V29: FALSE | W29: FALSE | X29: FALSE | Y29: FALSE | Z29: FALSE | AA29: FALSE | AB29: FALSE | AC29: FALSE | AD29: FALSE | AE29: FALSE | AF29: FALSE | AG29: FALSE | AH29: FALSE | AI29: FALSE | AJ29: FALSE | AK29: FALSE | AL29: Sion | AM29: Sierre
A30: 29 | B30: 2146188959 | C30: FALSE | D30: FALSE | E30: FALSE | F30: FALSE | G30: FALSE | H30: FALSE | I30: FALSE | J30: FALSE | K30: FALSE | L30: FALSE | M30: FALSE | N30: FALSE | O30: FALSE | P30: FALSE | Q30: FALSE | R30: FALSE | S30: FALSE | T30: FALSE | U30: FALSE | V30: FALSE | W30: FALSE | X30: FALSE | Y30: FALSE | Z30: FALSE | AA30: FALSE | AB30: FALSE | AC30: FALSE | AD30: FALSE | AE30: FALSE | AF30: FALSE | AG30: FALSE | AH30: FALSE | AI30: FALSE | AJ30: FALSE | AK30: FALSE | AL30: Sierre | AM30: Sion | AN30: Martigny
A31: 30 | B31: 2780 | C31: FALSE | D31: FALSE | E31: FALSE | F31: FALSE | G31: FALSE | H31: FALSE | I31: FALSE | J31: FALSE | K31: FALSE | L31: FALSE | M31: FALSE | N31: FALSE | O31: FALSE | P31: FALSE | Q31: FALSE | R31: FALSE | S31: FALSE | T31: FALSE | U31: FALSE | V31: FALSE | W31: FALSE | X31: FALSE | Y31: FALSE | Z31: FALSE | AA31: FALSE | AB31: FALSE | AC31: FALSE | AD31: FALSE | AE31: FALSE | AF31: FALSE | AG31: FALSE | AH31: FALSE | AI31: FALSE | AJ31: FALSE | AK31: FALSE | AL31: Sion | AM31: Sierre | AN31: Martigny
A32: 31 | B32: 1472015652 | C32: FALSE | D32: FALSE | E32: FALSE | F32: FALSE | G32: FALSE | H32: FALSE | I32: FALSE | J32: FALSE | K32: FALSE | L32: FALSE | M32: FALSE | N32: FALSE | O32: FALSE | P32: FALSE | Q32: FALSE | R32: FALSE | S32: FALSE | T32: FALSE | U32: FALSE | V32: FALSE | W32: FALSE | X32: FALSE | Y32: FALSE | Z32: FALSE | AA32: FALSE | AB32: FALSE | AC32: FALSE | AD32: FALSE | AE32: FALSE | AF32: FALSE | AG32: FALSE | AH32: FALSE | AI32: FALSE | AJ32: FALSE | AK32: FALSE | AL32: Sierre | AM32: Sion | AN32: Martigny
A33: 32 | B33: 1231232923 | C33: FALSE | D33: FALSE | E33: FALSE | F33: FALSE | G33: FALSE | H33: FALSE | I33: FALSE | J33: FALSE | K33: FALSE | L33: FALSE | M33: FALSE | N33: FALSE | O33: FALSE | P33: FALSE | Q33: FALSE | R33: FALSE | S33: FALSE | T33: FALSE | U33: FALSE | V33: FALSE | W33: FALSE | X33: FALSE | Y33: FALSE | Z33: FALSE | AA33: FALSE | AB33: TRUE | AC33: TRUE | AD33: TRUE | AE33: TRUE | AF33: TRUE | AG33: TRUE | AH33: TRUE | AI33: TRUE | AJ33: TRUE | AK33: TRUE | AL33: Martigny | AM33: Sion | AN33: Monthey | AO33: plusieurs w-e à cerebral
A34: 33 | B34: 1293630950 | C34: FALSE | D34: FALSE | E34: FALSE | F34: FALSE | G34: FALSE | H34: FALSE | I34: FALSE | J34: FALSE | K34: FALSE | L34: FALSE | M34: FALSE | N34: FALSE | O34: FALSE | P34: FALSE | Q34: FALSE | R34: FALSE | S34: FALSE | T34: FALSE | U34: FALSE | V34: FALSE | W34: FALSE | X34: FALSE | Y34: FALSE | Z34: FALSE | AA34: FALSE | AB34: FALSE | AC34: FALSE | AD34: FALSE | AE34: FALSE | AF34: FALSE | AG34: FALSE | AH34: FALSE | AI34: FALSE | AJ34: FALSE | AK34: FALSE | AL34: Sion | AM34: Martigny
A35: 34 | B35: 2146188964 | C35: FALSE | D35: FALSE | E35: FALSE | F35: FALSE | G35: FALSE | H35: FALSE | I35: FALSE | J35: FALSE | K35: FALSE | L35: FALSE | M35: FALSE | N35: FALSE | O35: FALSE | P35: FALSE | Q35: FALSE | R35: FALSE | S35: FALSE | T35: FALSE | U35: FALSE | V35: FALSE | W35: FALSE | X35: FALSE | Y35: FALSE | Z35: FALSE | AA35: FALSE | AB35: FALSE | AC35: FALSE | AD35: FALSE | AE35: FALSE | AF35: FALSE | AG35: FALSE | AH35: FALSE | AI35: FALSE | AJ35: FALSE | AK35: FALSE | AL35: Sion | AM35: Sierre | AN35: Martigny
A36: 35 | B36: 1300885603 | C36: FALSE | D36: FALSE | E36: FALSE | F36: FALSE | G36: FALSE | H36: FALSE | I36: FALSE | J36: FALSE | K36: FALSE | L36: FALSE | M36: FALSE | N36: FALSE | O36: FALSE | P36: FALSE | Q36: FALSE | R36: FALSE | S36: FALSE | T36: FALSE | U36: FALSE | V36: FALSE | W36: FALSE | X36: FALSE | Y36: FALSE | Z36: FALSE | AA36: FALSE | AB36: FALSE | AC36: FALSE | AD36: FALSE | AE36: FALSE | AF36: FALSE | AG36: FALSE | AH36: FALSE | AI36: FALSE | AJ36: FALSE | AK36: FALSE | AL36: Conthey | AM36: Sion | AN36: Martigny
A37: 36 | B37: 2146188936 | C37: FALSE | D37: FALSE | E37: FALSE | F37: FALSE | G37: FALSE | H37: FALSE | I37: FALSE | J37: FALSE | K37: FALSE | L37: FALSE | M37: FALSE | N37: FALSE | O37: FALSE | P37: FALSE | Q37: FALSE | R37: FALSE | S37: FALSE | T37: FALSE | U37: FALSE | V37: FALSE | W37: FALSE | X37: FALSE | Y37: FALSE | Z37: FALSE | AA37: FALSE | AB37: FALSE | AC37: FALSE | AD37: FALSE | AE37: FALSE | AF37: FALSE | AG37: FALSE | AH37: FALSE | AI37: FALSE | AJ37: FALSE | AK37: FALSE | AL37: Sion | AM37: Martigny
A38: 37 | B38: 2146189030 | C38: TRUE | D38: TRUE | E38: TRUE | F38: TRUE | G38: TRUE | H38: TRUE | I38: TRUE | J38: TRUE | K38: TRUE | L38: TRUE | M38: TRUE | N38: TRUE | O38: TRUE | P38: TRUE | Q38: TRUE | R38: TRUE | S38: TRUE | T38: TRUE | U38: TRUE | V38: TRUE | W38: TRUE | X38: TRUE | Y38: TRUE | Z38: TRUE | AA38: TRUE | AB38: TRUE | AC38: TRUE | AD38: TRUE | AE38: TRUE | AF38: TRUE | AG38: TRUE | AH38: TRUE | AI38: TRUE | AJ38: TRUE | AK38: TRUE | AL38: Sion | AM38: Sierre | AN38: Conthey
A39: 38 | B39: 2146189075 | C39: FALSE | D39: FALSE | E39: FALSE | F39: FALSE | G39: FALSE | H39: FALSE | I39: FALSE | J39: FALSE | K39: FALSE | L39: FALSE | M39: FALSE | N39: FALSE | O39: FALSE | P39: FALSE | Q39: FALSE | R39: FALSE | S39: FALSE | T39: FALSE | U39: FALSE | V39: FALSE | W39: FALSE | X39: FALSE | Y39: FALSE | Z39: FALSE | AA39: FALSE | AB39: FALSE | AC39: FALSE | AD39: FALSE | AE39: FALSE | AF39: FALSE | AG39: FALSE | AH39: FALSE | AI39: FALSE | AJ39: FALSE | AK39: FALSE
A40: 39 | B40: 2146189068 | C40: FALSE | D40: FALSE | E40: FALSE | F40: FALSE | G40: FALSE | H40: FALSE | I40: FALSE | J40: FALSE | K40: FALSE | L40: FALSE | M40: FALSE | N40: FALSE | O40: FALSE | P40: FALSE | Q40: FALSE | R40: FALSE | S40: FALSE | T40: FALSE | U40: FALSE | V40: FALSE | W40: FALSE | X40: FALSE | Y40: FALSE | Z40: FALSE | AA40: FALSE | AB40: FALSE | AC40: FALSE | AD40: FALSE | AE40: FALSE | AF40: FALSE | AG40: FALSE | AH40: FALSE | AI40: FALSE | AJ40: FALSE | AK40: FALSE | AL40: Sion | AM40: Martigny | AN40: Sierre
...

Sheet migration
A1: dispId | B1: tblContact_conId | C1: dispLMatin | D1: dispLSoir | E1: dispLSouper | F1: dispLaMidi | G1: dispLMidi | H1: dispMmatin | I1: dispMMidi | J1: dispMaMidi | K1: dispMSouper | L1: dispMSoir | M1: dispMEmatin | N1: dispMEMidi | O1: dispMEaMidi | P1: dispMESouper | Q1: dispMESoir | R1: dispJmatin | S1: dispJMidi | T1: dispJaMidi | U1: dispJSouper | V1: dispJSoir | W1: dispVmatin | X1: dispVMidi | Y1: dispVaMidi | Z1: dispVSouper | AA1: dispVSoir | AB1: dispSmatin | AC1: dispSMidi | AD1: dispSaMidi | AE1: dispSSouper | AF1: dispSSoir | AG1: dispDmatin | AH1: dispDMidi | AI1: dispDaMidi | AJ1: dispDSouper | AK1: dispDSoir | AL1: dispRegion1 | AM1: dispRegion2 | AN1: dispRegion3 | AO1: dispExperiance | AP1: dispReference
B2: =gescon_intervenant!B1 -> lien_contact | C2: =gescon_intervenant!C1 -> Lu_matin | D2: =gescon_intervenant!D1 -> Lu_repmid | E2: =gescon_intervenant!E1 -> Lu_aprem | F2: =gescon_intervenant!F1 -> Lu_repsoi | G2: =gescon_intervenant!G1 -> Lu_soire | H2: =gescon_intervenant!H1 -> Ma_matin | I2: =gescon_intervenant!I1 -> Ma_repmid | ... AP2: =gescon_intervenant!AP1 -> References
A3: 1 | B3: =gescon_intervenant!B2 -> 2072341970 | C3: =IF(gescon_intervenant!C2=FALSE,0,1) -> 0 | D3: =IF(gescon_intervenant!D2=FALSE,0,1) -> 0 | E3: =IF(gescon_intervenant!E2=FALSE,0,1) -> 0 | F3: =IF(gescon_intervenant!F2=FALSE,0,1) -> 0 | G3: =IF(gescon_intervenant!G2=FALSE,0,1) -> 0 | H3: =IF(gescon_intervenant!H2=FALSE,0,1) -> 0 | I3: =IF(gescon_intervenant!I2=FALSE,0,1) -> 0 | J3: =IF(gescon_intervenant!J2=FALSE,0,1) -> 0 | ... AK3: =IF(gescon_intervenant!AK2=FALSE,0,1) -> 0 | AL3: =gescon_intervenant!AL2 -> Sion | AM3: =gescon_intervenant!AM2 | AN3: =gescon_intervenant!AN2 | AO3: =gescon_intervenant!AO2 | AP3: =gescon_intervenant!AP2
A4: 2 | B4: =gescon_intervenant!B3 -> -554084105 | C4: =IF(gescon_intervenant!C3=FALSE,0,1) -> 0 | D4: =IF(gescon_intervenant!D3=FALSE,0,1) -> 0 | E4: =IF(gescon_intervenant!E3=FALSE,0,1) -> 0 | F4: =IF(gescon_intervenant!F3=FALSE,0,1) -> 0 | G4: =IF(gescon_intervenant!G3=FALSE,0,1) -> 0 | H4: =IF(gescon_intervenant!H3=FALSE,0,1) -> 0 | I4: =IF(gescon_intervenant!I3=FALSE,0,1) -> 0 | J4: =IF(gescon_intervenant!J3=FALSE,0,1) -> 0 | ... AK4: =IF(gescon_intervenant!AK3=FALSE,0,1) -> 0 | AL4: =gescon_intervenant!AL3 -> Sion | AM4: =gescon_intervenant!AM3 | AN4: =gescon_intervenant!AN3 | AO4: =gescon_intervenant!AO3 -> - Particiaption aux activités Cerebral | AP4: =gescon_intervenant!AP3
A5: 3 | B5: =gescon_intervenant!B4 -> -1100872493 | C5: =IF(gescon_intervenant!C4=FALSE,0,1) -> 0 | D5: =IF(gescon_intervenant!D4=FALSE,0,1) -> 0 | E5: =IF(gescon_intervenant!E4=FALSE,0,1) -> 0 | F5: =IF(gescon_intervenant!F4=FALSE,0,1) -> 0 | G5: =IF(gescon_intervenant!G4=FALSE,0,1) -> 0 | H5: =IF(gescon_intervenant!H4=FALSE,0,1) -> 0 | I5: =IF(gescon_intervenant!I4=FALSE,0,1) -> 0 | J5: =IF(gescon_intervenant!J4=FALSE,0,1) -> 0 | ... AK5: =IF(gescon_intervenant!AK4=FALSE,0,1) -> 0 | AL5: =gescon_intervenant!AL4 -> Monthey | AM5: =gescon_intervenant!AM4 -> Martigny | AN5: =gescon_intervenant!AN4 | AO5: =gescon_intervenant!AO4 -> participe aux w-e et camps cerebral | AP5: =gescon_intervenant!AP4
A6: 4 | B6: =gescon_intervenant!B5 -> 1291910802 | C6: =IF(gescon_intervenant!C5=FALSE,0,1) -> 0 | D6: =IF(gescon_intervenant!D5=FALSE,0,1) -> 0 | E6: =IF(gescon_intervenant!E5=FALSE,0,1) -> 0 | F6: =IF(gescon_intervenant!F5=FALSE,0,1) -> 0 | G6: =IF(gescon_intervenant!G5=FALSE,0,1) -> 0 | H6: =IF(gescon_intervenant!H5=FALSE,0,1) -> 0 | I6: =IF(gescon_intervenant!I5=FALSE,0,1) -> 0 | J6: =IF(gescon_intervenant!J5=FALSE,0,1) -> 0 | ... AK6: =IF(gescon_intervenant!AK5=FALSE,0,1) -> 0 | AL6: =gescon_intervenant!AL5 -> Monthey | AM6: =gescon_intervenant!AM5 -> Martigny | AN6: =gescon_intervenant!AN5 | AO6: =gescon_intervenant!AO5 -> participe aux activités cerebral | AP6: =gescon_intervenant!AP5
A7: 5 | B7: =gescon_intervenant!B6 -> 1142412576 | C7: =IF(gescon_intervenant!C6=FALSE,0,1) -> 0 | D7: =IF(gescon_intervenant!D6=FALSE,0,1) -> 0 | E7: =IF(gescon_intervenant!E6=FALSE,0,1) -> 0 | F7: =IF(gescon_intervenant!F6=FALSE,0,1) -> 0 | G7: =IF(gescon_intervenant!G6=FALSE,0,1) -> 0 | H7: =IF(gescon_intervenant!H6=FALSE,0,1) -> 0 | I7: =IF(gescon_intervenant!I6=FALSE,0,1) -> 0 | J7: =IF(gescon_intervenant!J6=FALSE,0,1) -> 0 | ... AK7: =IF(gescon_intervenant!AK6=FALSE,0,1) -> 0 | AL7: =gescon_intervenant!AL6 -> Sion | AM7: =gescon_intervenant!AM6 -> Sierre | AN7: =gescon_intervenant!AN6 -> Savièse | AO7: =gescon_intervenant!AO6 -> participe aux activité Cerebral | AP7: =gescon_intervenant!AP6
A8: 6 | B8: =gescon_intervenant!B7 -> 1317305611 | C8: =IF(gescon_intervenant!C7=FALSE,0,1) -> 0 | D8: =IF(gescon_intervenant!D7=FALSE,0,1) -> 0 | E8: =IF(gescon_intervenant!E7=FALSE,0,1) -> 0 | F8: =IF(gescon_intervenant!F7=FALSE,0,1) -> 0 | G8: =IF(gescon_intervenant!G7=FALSE,0,1) -> 0 | H8: =IF(gescon_intervenant!H7=FALSE,0,1) -> 0 | I8: =IF(gescon_intervenant!I7=FALSE,0,1) -> 0 | J8: =IF(gescon_intervenant!J7=FALSE,0,1) -> 0 | ... AK8: =IF(gescon_intervenant!AK7=FALSE,0,1) -> 0 | AL8: =gescon_intervenant!AL7 -> Conthey | AM8: =gescon_intervenant!AM7 -> Sion | AN8: =gescon_intervenant!AN7 | AO8: =gescon_intervenant!AO7 -> pas disponible 1x par mois le vendredi entre 17h-18h participe aux activités cerebral | AP8: =gescon_intervenant!AP7
A9: 7 | B9: =gescon_intervenant!B8 -> 1924663704 | C9: =IF(gescon_intervenant!C8=FALSE,0,1) -> 0 | D9: =IF(gescon_intervenant!D8=FALSE,0,1) -> 0 | E9: =IF(gescon_intervenant!E8=FALSE,0,1) -> 0 | F9: =IF(gescon_intervenant!F8=FALSE,0,1) -> 0 | G9: =IF(gescon_intervenant!G8=FALSE,0,1) -> 0 | H9: =IF(gescon_intervenant!H8=FALSE,0,1) -> 0 | I9: =IF(gescon_intervenant!I8=FALSE,0,1) -> 0 | J9: =IF(gescon_intervenant!J8=FALSE,0,1) -> 0 | ... AK9: =IF(gescon_intervenant!AK8=FALSE,0,1) -> 0 | AL9: =gescon_intervenant!AL8 -> Sierre | AM9: =gescon_intervenant!AM8 -> Sion | AN9: =gescon_intervenant!AN8 | AO9: =gescon_intervenant!AO8 -> participe aux activités Cerebral | AP9: =gescon_intervenant!AP8
A10: 8 | B10: =gescon_intervenant!B9 -> 1315811525 | C10: =IF(gescon_intervenant!C9=FALSE,0,1) -> 0 | D10: =IF(gescon_intervenant!D9=FALSE,0,1) -> 0 | E10: =IF(gescon_intervenant!E9=FALSE,0,1) -> 0 | F10: =IF(gescon_intervenant!F9=FALSE,0,1) -> 0 | G10: =IF(gescon_intervenant!G9=FALSE,0,1) -> 0 | H10: =IF(gescon_intervenant!H9=FALSE,0,1) -> 0 | I10: =IF(gescon_intervenant!I9=FALSE,0,1) -> 0 | J10: =IF(gescon_intervenant!J9=FALSE,0,1) -> 0 | ... AK10: =IF(gescon_intervenant!AK9=FALSE,0,1) -> 0 | AL10: =gescon_intervenant!AL9 -> Sion | AM10: =gescon_intervenant!AM9 -> Sierre | AN10: =gescon_intervenant!AN9 -> Martigny | AO10: =gescon_intervenant!AO9 -> permis de voiture participe aux activités Cerebral dimanche jusqu'à 20h30 | AP10: =gescon_intervenant!AP9
A11: 9 | B11: =gescon_intervenant!B10 -> 1493190852 | C11: =IF(gescon_intervenant!C10=FALSE,0,1) -> 0 | D11: =IF(gescon_intervenant!D10=FALSE,0,1) -> 0 | E11: =IF(gescon_intervenant!E10=FALSE,0,1) -> 0 | F11: =IF(gescon_intervenant!F10=FALSE,0,1) -> 0 | G11: =IF(gescon_intervenant!G10=FALSE,0,1) -> 0 | H11: =IF(gescon_intervenant!H10=FALSE,0,1) -> 0 | I11: =IF(gescon_intervenant!I10=FALSE,0,1) -> 0 | J11: =IF(gescon_intervenant!J10=FALSE,0,1) -> 0 | ... AK11: =IF(gescon_intervenant!AK10=FALSE,0,1) -> 0 | AL11: =gescon_intervenant!AL10 | AM11: =gescon_intervenant!AM10 | AN11: =gescon_intervenant!AN10 | AO11: =gescon_intervenant!AO10 | AP11: =gescon_intervenant!AP10
A12: 10 | B12: =gescon_intervenant!B11 -> 1314194184 | C12: =IF(gescon_intervenant!C11=FALSE,0,1) -> 0 | D12: =IF(gescon_intervenant!D11=FALSE,0,1) -> 0 | E12: =IF(gescon_intervenant!E11=FALSE,0,1) -> 0 | F12: =IF(gescon_intervenant!F11=FALSE,0,1) -> 0 | G12: =IF(gescon_intervenant!G11=FALSE,0,1) -> 0 | H12: =IF(gescon_intervenant!H11=FALSE,0,1) -> 0 | I12: =IF(gescon_intervenant!I11=FALSE,0,1) -> 0 | J12: =IF(gescon_intervenant!J11=FALSE,0,1) -> 1 | ... AK12: =IF(gescon_intervenant!AK11=FALSE,0,1) -> 1 | AL12: =gescon_intervenant!AL11 -> Martigny | AM12: =gescon_intervenant!AM11 -> Monthey | AN12: =gescon_intervenant!AN11 | AO12: =gescon_intervenant!AO11 -> participe aux activités Cerebral disponible du 16.11.11 au 16.03.12 et toutes les vacances scolaires | AP12: =gescon_intervenant!AP11
A13: 11 | B13: =gescon_intervenant!B12 -> 1290764579 | C13: =IF(gescon_intervenant!C12=FALSE,0,1) -> 0 | D13: =IF(gescon_intervenant!D12=FALSE,0,1) -> 0 | E13: =IF(gescon_intervenant!E12=FALSE,0,1) -> 0 | F13: =IF(gescon_intervenant!F12=FALSE,0,1) -> 0 | G13: =IF(gescon_intervenant!G12=FALSE,0,1) -> 0 | H13: =IF(gescon_intervenant!H12=FALSE,0,1) -> 0 | I13: =IF(gescon_intervenant!I12=FALSE,0,1) -> 0 | J13: =IF(gescon_intervenant!J12=FALSE,0,1) -> 0 | ... AK13: =IF(gescon_intervenant!AK12=FALSE,0,1) -> 0 | AL13: =gescon_intervenant!AL12 -> Monthey | AM13: =gescon_intervenant!AM12 -> Martigny | AN13: =gescon_intervenant!AN12 | AO13: =gescon_intervenant!AO12 -> particiaption aux activités Cerebral + Asa stagiaire à Cerebral en 2011 permis de conduire | AP13: =gescon_intervenant!AP12
A14: 12 | B14: =gescon_intervenant!B13 -> 558428742 | C14: =IF(gescon_intervenant!C13=FALSE,0,1) -> 0 | D14: =IF(gescon_intervenant!D13=FALSE,0,1) -> 0 | E14: =IF(gescon_intervenant!E13=FALSE,0,1) -> 0 | F14: =IF(gescon_intervenant!F13=FALSE,0,1) -> 0 | G14: =IF(gescon_intervenant!G13=FALSE,0,1) -> 0 | H14: =IF(gescon_intervenant!H13=FALSE,0,1) -> 0 | I14: =IF(gescon_intervenant!I13=FALSE,0,1) -> 0 | J14: =IF(gescon_intervenant!J13=FALSE,0,1) -> 0 | ... AK14: =IF(gescon_intervenant!AK13=FALSE,0,1) -> 0 | AL14: =gescon_intervenant!AL13 -> Martigny | AM14: =gescon_intervenant!AM13 -> Monthey | AN14: =gescon_intervenant!AN13 -> Sion | AO14: =gescon_intervenant!AO13 -> participe aux activités Cerebral | AP14: =gescon_intervenant!AP13
... A132: 130 | B132: =gescon_intervenant!B131 -> 2146190076 | C132: =IF(gescon_intervenant!C131=FALSE,0,1) -> 1 | D132: =IF(gescon_intervenant!D131=FALSE,0,1) -> 0 | E132: =IF(gescon_intervenant!E131=FALSE,0,1) -> 0 | F132: =IF(gescon_intervenant!F131=FALSE,0,1) -> 0 | G132: =IF(gescon_intervenant!G131=FALSE,0,1) -> 0 | H132: =IF(gescon_intervenant!H131=FALSE,0,1) -> 1 | I132: =IF(gescon_intervenant!I131=FALSE,0,1) -> 0 | J132: =IF(gescon_intervenant!J131=FALSE,0,1) -> 0 | ... AK132: =IF(gescon_intervenant!AK131=FALSE,0,1) -> 1 | AL132: =gescon_intervenant!AL131 -> Conthey | AM132: =gescon_intervenant!AM131 -> Sion | AN132: =gescon_intervenant!AN131 -> Sierre | AO132: =gescon_intervenant!AO131 -> certains après-midi tous les matins soirées weekends | AP132: =gescon_intervenant!AP131

Sheet Feuil2
