Workbook

Sheet gescon_infosparticip
A1: membre | B1: Dernière mise à jour | C1: Fils de(Père) | D1: Fils de(Mère) | E1: Tuteur | F1: Institution | G1: Adresse urgence | H1: Referent_institut | I1: arpo_gereseul | J1: arpo_avecaidephys | K1: arpo_avecconseil | L1: arpo_negerepas | M1: Mobil_marcheseul | N1: Mobil_marchaide | O1: Mobil_marchauxi | P1: Mobil_fauteuilman | Q1: Mobil_fauteuilelec | R1: Long_dep | S1: Piscine_coment | T1: Piscine_gilet | U1: Publication | V1: habillement | W1: someil | X1: acnuit_atache | Y1: acnuit_drapspec | Z1: acnuit_gilet | AA1: acnuit_barriere | AB1: Expresssion | AC1: Famille | AD1: Fraterie | AE1: Amis | AF1: Passions_Loisirs | AG1: Activités peu appréciées | AH1: autonomierepas | AI1: alim_prefere | AJ1: alim_regime | AK1: alim_decons | AL1: alim_interdit | AM1: bois_condition | AN1: bois_prefere | AO1: bois_regime | AP1: bois_decons | AQ1: bois_interdit | AR1: impot | AS1: Interv_A | AT1: Interv_B | AU1: Interv_C | AV1: Interv_R | AW1: CR_urgence | AX1: CR_surcharge | AY1: CR_loisirs | AZ1: CR_famille | BA1: Medecin 1 | BB1: Medecin 2 | BC1: Medecin 3 | BD1: Caisse maladie | BE1: Accident | BF1: no_assuré | BG1: Type de handicap | BH1: Handicaps Associés | BI1: deg_impot | BJ1: Allergies | BK1: toilette | BL1: incontinence | BM1: escarres | BN1: change_pos | BO1: frequence_change
A2: -2138585887 | B2: 41092 | I2: FALSE | J2: FALSE | K2: FALSE | L2: FALSE | M2: FALSE | N2: FALSE | O2: FALSE | P2: FALSE | Q2: FALSE | R2: ligne1 ligne 2 Ligne 3 | T2: FALSE | U2: FALSE | X2: FALSE | Y2: FALSE | Z2: FALSE | AA2: FALSE | AH2: Incliner légèrement son fauteuil en arrière pour facilier la déglutition. Alimentation normale. Couper fin, très petit, si trop secd rajouter du lait et lui donner à manger. | AM2: II boit à la paille | AN2: café | BG2: IMC profond | BH2: Handicap mental, troubles moteurs | BI2: Elevé | BJ2: protéger Alain du soleil (chapeau, crème). Il a une peau très sensible, faire attention aux coups de soleil dans la nuque! | BK2: Aide complète. Attention a bien mettre son plateau pour évtier les blessures aux genoux. Chaise percée pour douche tous les jours. | BL2: lain a une autonomie moyenne. Par commodité, il est langé à l'extérieur de la maison. Au changement de lange (matin, midi, soir, avant le coucher), lui demander s'il veut aller aux toillettes | BM2: massage des pieds et des fesses
A3: -1974002318 | B3: 42780 | C3: 1241531093 | G3: 2146189445 | I3: FALSE | J3: FALSE | K3: FALSE | L3: FALSE | M3: FALSE | N3: FALSE | O3: FALSE | P3: TRUE | Q3: FALSE | R3: Elle supporte les longs trajets en bus | S3: Elle apprécie l'eau | T3: TRUE | U3: TRUE | V3: Aide totale | X3: FALSE | Y3: FALSE | Z3: FALSE | AA3: FALSE | AB3: Elle n'a pas l'expression verbal. Elle communique par le regard, le toucher, les mimiques. C'est une petite fille très facile qui apprécie tout. Si elle pleure il faut s'inquiéter (il peut y avoir des coliques ou mal positionnement). Donc à observer et la prendre dans les bras car elle a besoin d'être rassurée. | AC3: Elle apprécie beaucoup sa grand-maman. | AD3: Alycia a une petite sœur qui s'appelle Léanne | AF3: Activités en plein air. Elle aime bien écouter de la musiquen et des histoires. Elle apprécie les balades et le vélo. | AH3: Alycia est alimentée par sonde. 150 ml de frébini 300m/h avec la pompe. (peg) matin, midi et soir avec la pompe et le sachet alimentaire. Donner de l'eau 3x/jours 150ml Prend environs 30 min pour le repas trois fois limentation avec les sachet pour la boisson. On peut l'alimenter durant les transports ou en déplacement sur la chaise. | BA3: 226884306 | BD3: 2146189019 | BF3: 00807.17.515.7 | BG3: Polyhandicap | BH3: A mettre lunettes médicales la journée | BK3: Changer les protections matin, midi et soir. Aussi si ell a été à selle. | BN3: oui | BO3: changement de position pendant la journée.
A4: -1949668449 | B4: 37859.411 | C4: 2643 | D4: 2210 | E4: 0 | F4: 0 | G4: 1424 | I4: FALSE | J4: FALSE | K4: FALSE | L4: FALSE | M4: FALSE | N4: FALSE | O4: FALSE | P4: FALSE | Q4: FALSE | S4: Le faire marcher dans l'eau rester tout le temps à ses côtés. | T4: FALSE | U4: TRUE | X4: FALSE | Y4: FALSE | Z4: FALSE | AA4: FALSE | AB4: Expression verbale, mimiques, écholalie, stéréotipie | AC4: Il aime beaucoup la musique: écouter Mylène Farmer, et chanter. Ne pas lui donner trop d'ordres, pas trop d'exigences, juste lui indiquer ce que l'on fait. Si il se fâche, il se donne des claques. | AG4: Elle est destabilisée par la foule. | BA4: 107 | BB4: 0 | BC4: 0 | BE4: 0 | BG4: IMC | BH4: Diplégie spastique, retard mental, comportement autistique, handicap mental
A5: -1887115141 | B5: 42517 | C5: 106817863 | F5: 1424 | H5: Groupe - C4 Beate Friedberger | I5: FALSE | J5: TRUE | K5: TRUE | L5: FALSE | M5: FALSE | N5: FALSE | O5: FALSE | P5: TRUE | Q5: FALSE | R5: Elle supporte les trajets en bus. | S5: Il faut l’accompagner. Si elle ne veut pas, il ne faut pas la forcer | T5: FALSE | U5: TRUE | W5: dort bien mais discute parfois longtemps. Danièla demande pour aller au lit. Le matin, au lever elle boit volontiers un verre d’eau. Protection pour la nuit | X5: FALSE | Y5: FALSE | Z5: FALSE | AA5: TRUE | AB5: s’exprime en allemand et en français à sa manière. Elle mélange les mots allemands avec les mots français. | AC5: Son papa est décédé. | AD5: Elle a 2 sœurs : Claudia et Andrea. | AF5: Danièla possède un cahier avec des photos de sa famille et de son entourage. Danièla s’exprime bien et montre ce qu’elle souhaite. Elle arrive à faire des choix. Elle apprécie les différents styles de musique. Elle aime faire des jeux d’encastrement ex : mettre les pièces dans le jeu du puissance 4. Elle arrive à faire du vélo à 3 roues. | AG5: Toutes les activités avec des bruits, Danièla sursaute beaucoup | AH5: les aliments sont à couper, elle mange seule avec une fourchette dans une assiette creuse ; fait le mouvement de pelle côté droit et elle doit mettre la main gauche à plat sur la table les doigts légèrement écartés. | AM5: elle boit dans un gobelet spécial avec 2 anses. Lors de déplacement elle arrive à boire dans un verre normal. Matin : Tartine au beurre, confiture et café et fruit habituellement. Les autres repas elle mange de tout et sait dire lorsqu’elle ne veut plus. Elle apprécie boire de l’eau, du sirop ou autre minéralesIl faut l'asseoir sur une chaise avec des accoudoirs. | BA5: 107 | BD5: 2146189028 | BE5: 2146189028 | BF5: 3705 | BG5: IMC | BH5: Handicap mental, troubles moteurs, hémiplégie côté gauche | BI5: Elevé | BK5: oui Danièla participe à l’habillage (= pousser les bras, monter les chaussettes) pour le reste elle a besoin d’aide (= se tient debout si elle a une barrière pour se tenir) Elle a des attelles aux jambes. Masser les pieds pour les détendres et ensuite bien mettre le talon au fond de l’attelle. Pour vérifier si le talon est bein au fond regarder le trou sur le talon de l’attelle. Douche : assise sur une chaise, elle se lève pour se faire laver les parties intimes. | BL5: Elle demande si elle a besoin d’uriner. Se déplace dans la salle de bain et se lève avec la barrière. Appelle pour qu’on l’aide à se remettre dans son fauteuil. Le matin, lui proposer d’aller aux WC avant de déjeuner. Protection pour la nuit!
A6: -1756164214 | B6: 41087 | C6: 0 | D6: 0 | E6: 0 | F6: 0 | G6: 0 | I6: FALSE | J6: FALSE | K6: FALSE | L6: FALSE | M6: FALSE | N6: FALSE | O6: FALSE | P6: FALSE | Q6: FALSE | S6: si Laurent n'a pas fond, il a besoin d'aide. | T6: FALSE | U6: TRUE | X6: FALSE | Y6: FALSE | Z6: FALSE | AA6: FALSE | AB6: Parle | AC6: Ses parents sont séparés. Son papa habite dans le canton de Berne et sa maman à Betten près de Naters. Il a deux frères: Jean-Luc (1965) et Yves (1964). Laurent apprécie la piscine, les ballades.Il travaille un après-midi par semaine dans un atelier et le | BA6: 0 | BB6: 0 | BC6: 0 | BD6: 0 | BE6: 0 | BG6: IMC | BH6: Handicap mental | BJ6: Non
A7: -1735727011 | B7: 37861.394 | C7: 0 | D7: 0 | E7: 0 | F7: 0 | G7: 0 | I7: FALSE | J7: FALSE | K7: FALSE | L7: FALSE | M7: FALSE | N7: FALSE | O7: FALSE | P7: FALSE | Q7: FALSE | S7: Il sait nager, il faut être à côté | T7: FALSE | U7: FALSE | X7: FALSE | Y7: FALSE | Z7: FALSE | AA7: FALSE | AB7: oral | BA7: 107 | BB7: 0 | BC7: 0 | BD7: 0 | BE7: 0 | BG7: IMC | BJ7: Rhume des foins
A8: -1690129297 | B8: 37858.563 | C8: 1007640806 | D8: 2210 | E8: 0 | F8: 0 | I8: FALSE | J8: FALSE | K8: FALSE | L8: FALSE | M8: FALSE | N8: FALSE | O8: FALSE | P8: FALSE | Q8: FALSE | S8: Patrice a besoin de l’aide d’un adulte. | T8: FALSE | U8: TRUE | X8: FALSE | Y8: FALSE | Z8: FALSE | AA8: FALSE | AB8: oral, mais avec difficulté. Il faut lui poser des questions pour qu’il participe à la conversation. | AC8: Patrice aime les animaux, la musique, les magazines et regarder la télévision. Il a depuis une année un neveu qu’il aime beaucoup. Sa deuxième sœur dirige une société d’accordéoniste. Son papa est passionné de pétanque. | BA8: 1217 | BB8: 0 | BC8: 0 | BE8: 0 | BG8: Ataxie, syndrome de Marinesco | BH8: troubles moteurs | BJ8: A protéger du Soleil (casquette, crème).
A9: -1579856298 | B9: 38154.441 | C9: 0 | D9: 0 | F9: 0 | G9: 0 | I9: FALSE | J9: FALSE | K9: FALSE | L9: FALSE | M9: FALSE | N9: FALSE | O9: FALSE | P9: FALSE | Q9: FALSE | T9: FALSE | U9: FALSE | X9: FALSE | Y9: FALSE | Z9: FALSE | AA9: FALSE | BA9: 0 | BB9: 0 | BC9: 0 | BD9: 0 | BE9: 0
A10: -1475569285 | B10: 42405 | C10: 2146188951 | F10: 2146189395 | G10: 2146188951 | I10: FALSE | J10: TRUE | K10: FALSE | L10: TRUE | M10: TRUE | N10: FALSE | O10: FALSE | P10: FALSE | Q10: FALSE | R10: Il supporte les longs trajets et se déplace seul. | S10: Il nage seul, sans manchon. Il n'a pas peur de l'eau. | T10: FALSE | U10: TRUE | V10: Il faut l'aider à choisir ses vêtements en fonction du temps. | W10: Il dort beaucoup, de plus en plus. Il n'a pas d'horaires particuliers. | X10: FALSE | Y10: FALSE | Z10: FALSE | AA10: FALSE | AB10: Langage verbal avec des gestes. | AC10: Il n'a plus que sa maman et l'ami de celle-ci. | AD10: décédés | AF10: Avec sa maman et l'ami de celle-ci, ils vont à vélo, au camping, nager, voir des matchs de foot, manger au restaurant, danser, ect. Il a des cousins et cousines mais ne les voit jamais, seul Fritz Karafiat l'amène faire des raquettes parfois l'hiver. Il aime les activités de groupe, est très sociable mains ne parle pas beaucoup. Il aime le cinéma et le foot, les trains à la gare, les avions à l'aéroport, mais surtout voir des gens ! S'il va au ciné, il ne comprend pas le film, c'est juste pour sortir. Attention, quand il voit des jeux de cartes, il les pique pour s'amuser avec. Il aime les avions et les trains. | AG10: Aucune, il est agréable et facile à vivre. | AH10: Il mange seul et se débrouille bien. | BA10: 2146189227 | BB10: 2146189396 | BD10: 2146188987 | BE10: 2146188982 | BF10: 644702 | BG10: Syndrôme de William's | BH10: handicap mental - Malformation cardiaque | BI10: Faible | BJ10: N.B. Il a une bonne santé, rarement malade. Il a un souffle au cœur mais sans conséquences jusqu'à présent. | BK10: N'a pas besoin d'aide. | BL10: Il est sensible aux diarrhées. Il est autonome et va souvent aux toilettes.
A11: -1435346384 | B11: 42886 | I11: FALSE | J11: FALSE | K11: FALSE | L11: FALSE | M11: FALSE | N11: FALSE | O11: FALSE | P11: FALSE | Q11: FALSE | T11: FALSE | U11: FALSE | X11: FALSE | Y11: FALSE | Z11: FALSE | AA11: FALSE
A12: -1354980006 | B12: 42885 | C12: -362773667 | F12: 67 | I12: FALSE | J12: TRUE | K12: TRUE | L12: TRUE | M12: FALSE | N12: FALSE | O12: FALSE | P12: TRUE | Q12: FALSE | R12: Elle supporte les trajets en bus. | S12: Elle aime l'eau, elle y va avec un gilet et une personne en soutenance. | T12: TRUE | U12: TRUE | V12: aide complète, elle aime être propre et être lavée. | W12: Elle dort sur le dos avec un coussin d’allaitement sous les genoux et un coussin sous la tête selon sa position. Elle apprécie avoir un mobile au dessus de sa tête et des nounours autour d’elle. Le soir, elle se couche vers les 20h-21h00. Elle a besoin de temps pour s’endormir et parfois, après avoir mis la sonde, il est nécessaire de la changée. Si non, elle a un bon sommeil. La nuit à vérifier son lange env. 1/ 2heure après l’application de la sonde. | X12: FALSE | Y12: FALSE | Z12: FALSE | AA12: TRUE | AB12: Elle n’a pas une communication verbale mais Cloé communique avec des petits cris. L’intonation varie selon son humeur. (Contente, dérangée, douleur, etc.). Cloé ne peut pas se positionner dans le « oui » ou le « non ». | AD12: Cloé a des frères (Léandre de 2005, Joaquim de 2002). | AF12: Elle aime sortir et faire des balades. Elle apprécie rester dans son lit et jouer avec des mobiles poser au dessus de sa tête. | AH12: médic du matin: dans la seringue et relié à la sonde -> rincer ensuite avec 1-2 seringue d'eau Cloé a besoin d’une aide complète pour les repas. Elle est nourrie essentiellement par le biais de la sonde. Il ne faut pas la forcer. Elle mange de tout et la nourriture est mixée, lisse. Ni trop liquide, ni trop sèche. Elle préfère plutôt salé. Le MATIN : en principe, elle ne mange pas. Il est important de rincer la sonde avec 1 à 2 seringues. MIDI : nourriture mixée lisse en petites quantités. SOIR : nourriture mixée lisse ou des yaourts en petites quantités. Petit sachet pour la nourriture durant la nuit | AJ12: débit EAU : 180 ml/h débit L'ALIMENTATION : 50 ml/h | AM12: alimentation et sonde: s'il fait chaud, on peut donner jusqu'à 1litre d'eau par la sonde. Pour bouillon et eau mettre dans le grand sachet - possibilité de donner à boire en promenade, prendre la pompe et mettre eau dans gd sachet. | AS12: 2146189479 | AT12: 2146189314 | AU12: 2146189314 | BA12: 107 | BD12: 2146188987 | BE12: 2146188987 | BF12: 429923 | BG12: IMC -Polyhandicap, épilepsie (stabilisé) | BH12: Ne doit pas dépasser les 1700m d'altitude. Car elle risque d'avoir des problèmes respiratoires | BI12: Elevé | BJ12: Bien la protéger du soleil car elle a la peau très sensible | BK12: Elle aime être propre. | BL12: En cas de diarrhée, Bioflorin au Perenterol. Elle fait souvent les selles après la prise des médicaments | BM12: Changement de position, il faut lui mettre le harnais quand elle se trouve dans la chaise. | BN12: Sur le dos avec un coussin d'allaitement sous les genoux et un coussin sous la tête selon sa position. Elle est souvent couchle sur le dos. Pas de changement de position la nuit. | BO12: Chaque 4 heures
A13: -1336383801 | B13: 41430 | I13: FALSE | J13: FALSE | K13: FALSE | L13: FALSE | M13: FALSE | N13: FALSE | O13: FALSE | P13: FALSE | Q13: FALSE | T13: FALSE | U13: FALSE | X13: FALSE | Y13: FALSE | Z13: FALSE | AA13: FALSE
A14: -1226171744 | B14: 42941 | I14: FALSE | J14: FALSE | K14: FALSE | L14: FALSE | M14: FALSE | N14: FALSE | O14: FALSE | P14: FALSE | Q14: FALSE | T14: FALSE | U14: FALSE | X14: FALSE | Y14: FALSE | Z14: FALSE | AA14: FALSE
A15: -1213086902 | B15: 41058 | I15: FALSE | J15: FALSE | K15: FALSE | L15: FALSE | M15: FALSE | N15: FALSE | O15: FALSE | P15: FALSE | Q15: FALSE | T15: FALSE | U15: FALSE | X15: FALSE | Y15: FALSE | Z15: FALSE | AA15: FALSE
A16: -1120356771 | B16: 42705 | C16: -1123050406 | F16: 1424 | I16: FALSE | J16: TRUE | K16: FALSE | L16: TRUE | M16: FALSE | N16: FALSE | O16: FALSE | P16: TRUE | Q16: FALSE | R16: Il faut lui mettre les anches droites dès qu'on l'installe dans la chaise. Elle supporte les longs trajets | S16: Elle apprécie beaucoup l'eau, aide complète. | T16: FALSE | U16: TRUE | V16: aide complète | W16: Elle se couche vers les 19h00 et se lève vers 7h30 en général. Durant la nuit changement de position. Elle s’endort sur le dos avec la gouttière. Puis, vers 23h00, la mettre sur le côté gauche, puis sur le côté droit. Si elle est endormie, il n’est pas nécessaire de faire de changement de position. | X16: FALSE | Y16: FALSE | Z16: FALSE | AA16: TRUE | AB16: Non verbal, elle communique avec des cris. | AD16: Elle a un frère Maxime de 1989 et deux sœurs Blanche et Rose de 2002 qui sont jumelles. | AF16: Elle se montre très conviviale lorsqu'elle se retrouve à l'extérieur. Elle apprécie la musique et le rythme. Elle aime tenir des objets dans ses mains et jouer avec, elle apprécie les câlins. | AG16: Rien à signaler. | AH16: Elle mange de tout, plutôt sucré. Pour lui donner à manger elle a une cuillère spéciale, s’assoir en face d’elle et déposer d’abord sur sa lèvre inférieure bien lui faire sentir l’aliment, lui tenir les mains l’une sur l’autre puis elle mange sans problème. Elle mange mixé, sans fil. Si vous avez des difficultés à lui donner à manger, il ne faut pas se faire de soucis. Dans les bagages, Il y aura des boissons (frésubin) qui ont les mêmes calories qu’un repas normal. | AM16: pour boire : Amandine a une sonde reliée directement à l'estomac. Installer le tuyau sur la valve. Ne pas se gener de prendre la valve bien en main pour mettre le tuyau, ça ne lui fait pas mal. Ensuite remplir la seringue dans un verre et placer la seringue dans l'embout du tuyau, puis presser dans le tuyau. Pour terminer, rincer le tout avec de l'eau sans aucun produit (elle boit en général 1 verre d'une quelconque boisson SANS GAZ + 1 verre d'eau) Ne jamais mettre le tuyau au lave vaisselle !! | AN16: le matin et le soir : café ou cacao, presser la seringue plus lentement. A midi : n'importe quelle boisson SANS GAZ. Au goûter : boisson enérgétique (fébrini) | AQ16: Ne pas lui donner de boisson gazeuses. | BA16: 107 | BD16: 2146188984 | BE16: 2146188984 | BF16: 010930279 | BG16: IMC | BH16: Handicap mental, troubles moteurs | BI16: Elevé | BJ16: Aucune | BK16: Si elle a des rougeurs autour du « bouton », sécher au foehn et lui mettre un tampon de ouate démaquillante coupée en Y entre le tampon et la peau. Si elle se mord les doigts lui mettre un sparadrap en cas de saignements. Ne pas lui brosser les dents, elle ne le supporte pas. Pour sa toilette, utiliser de préférence le lit douche, mais elle est peu habituée car elle prend de préférence des bains. | BL16: Elle est langée 24h/24. La changer en général après chaque repas. | BM16: Transferts : Amandine met les bras autour de l'accompagnant, mettre un bras sous sa jambre, l'autre sous son épaule puis la mettre sur le lit. Pour la remettre dans sa chaise, faire pareil. Incliner sa chaise pour la mettre au fond | BN16: Elle apprécie être par terre, la mettre sur le dos sur un tapis.
A17: -1100872493 | B17: 40764.668 | C17: 0 | D17: 0 | E17: 0 | F17: 0 | G17: 0 | I17: FALSE | J17: FALSE | K17: FALSE | L17: FALSE | M17: FALSE | N17: FALSE | O17: FALSE | P17: FALSE | Q17: FALSE | T17: FALSE | U17: FALSE | X17: FALSE | Y17: FALSE | Z17: FALSE | AA17: FALSE | BA17: 0 | BB17: 0 | BC17: 0 | BD17: 0 | BE17: 0
A18: -1029621688 | B18: 41766 | F18: 1434 | G18: 1434 | H18: Loic accompagnement, Linda soin, Lydia infirmière | I18: TRUE | J18: FALSE | K18: FALSE | L18: FALSE | M18: FALSE | N18: FALSE | O18: FALSE | P18: TRUE | Q18: TRUE | R18: Il peut se lever pour un transfert mais il faut le tenir. Il supporte les longs trajets en bus. | S18: René n'aime pas trop, il a besoin d'aide. Pas de gilet mais il faut le soutenir. | T18: FALSE | U18: TRUE | V18: Il est autonome pour l'habillement. Il faut l'aider pour mettre ses chaussettes et ses chaussures. | W18: Urinal à proximité. Il bouge beaucoup. | X18: FALSE | Y18: FALSE | Z18: FALSE | AA18: FALSE | AB18: René parle et il a un appareil auditif. Bien articuler et parler un peu fort bien en face de lui. | AD18: René a deux sœurs, deux nièces et une petite nièce. | AF18: Ordinateur, la ville, les mots croisés, l'astrologie, discuter, les voyages. | AH18: Il faut lui couper la viande | BA18: 2146188983 | BD18: 2146188969 | BE18: 2146188969 | BF18: 267.50.370.119 / 000-02 | BG18: IMC | BH18: Malentendant, il a un appareil. | BI18: Elevé | BJ18: Aucune | BK18: René est autonome. Supervision pour la douche. | BL18: René est autonome. | BN18: Sur sa chaise électrique
A19: -959706217 | B19: 42886 | C19: 1203348545 | F19: 1434 | G19: 1434 | I19: FALSE | J19: TRUE | K19: TRUE | L19: FALSE | M19: FALSE | N19: FALSE | O19: FALSE | P19: TRUE | Q19: FALSE | R19: Se déplace seul à l'intérieur et accompagné à l'extérieur même muni du servomatic.Transfert lit chaise avec cigogne. Antidry sur le dos et les démengeaisons. | S19: Oui avec un grand plaisir. Faire attention à l'eau froide, sait nager seul mais le surveiller. | T19: FALSE | U19: TRUE | V19: S'habille seul le haut et lui donner un coup de main pour le bas. Pour les transfets il a besoin d'avoir ses souliers aux pieds. | W19: Il choisit quand il veut se coucher. Généralement il va au lit tôt. Ne pas oublier de brancher son uriflac sur l'uriflac qu'il a spécialement pour la nuit.Enlever Slip. Mettres des pants si diahrées. | X19: FALSE | Y19: FALSE | Z19: FALSE | AA19: FALSE | AB19: Oral, au premier abord il est qqun de timide mais une fois à l'aise, il se montre très jovial. Il est souvent de bonne humeur, très souriant et galant. Il bagaye. | AF19: Natation, rafroball, puzzles, dessin, peinture, activités manuelles en général et aussi simplement aller boire un verre. Christophe aime parler des sports qu'il pratique et participe volontiers aux discussions et est ouvert à tout. Il aime faire la vaisselle ! | AG19: S'il n'aime pas faire quelque chose il le dit. L'ami de sa maman est décédé et son souvenir lui donne parfois des coups de blues, surtout en janvier. | AH19: Aider à couper les aliments mais mange seul. Pour le temps de midi il reste dans sa chaise | AJ19: lui donner 1 service | AK19: les aliments qui activent son transit intestinal : choux, raisins, poires, pruneaux, fromage car cela lui cause de fortes diahrées. | AM19: il boit seul | AP19: les boissons trop sucrées | BA19: 2146188983 | BD19: 2146189010 | BF19: 8766 | BG19: IMC, retard mental et handicap physique | BH19: Retard mental, malvoyance | BI19: Moyen | BJ19: pas à la connaissance | BL19: Il a une sonde urinaire depuis 2008. Il a toujours sa bouteille avec lui. Il ne dit pas s'il est mouillé car ça le gêne, veiller à lui vider souvent souvent la poche. Le matin et le soir env. 15 min. sur les toilettes pour les selles. | BN19: non | BO19: Mettre en charge la chaise tous les soirs.
A20: -953224796 | B20: 42468 | C20: 2034 | F20: 1434 | G20: 2034 | H20: Quadranti Yann 079/404.86.02 | I20: TRUE | J20: TRUE | K20: TRUE | L20: FALSE | M20: FALSE | N20: FALSE | O20: FALSE | P20: TRUE | Q20: FALSE | R20: Julien supporte les longs trajets sur un siège du bus. Julien a un moteur dans les roues de son fauteil, il faut donc le recharger tous les soirs. | S20: Sortir Julien de sa chaise et le mettre au bord de la piscine. Il faut être à ses côtés lorsqu'il nage. Il nage sur le dos. | T20: FALSE | U20: TRUE | V20: Julien a besoin d'une légère aide pour l'habillement. Toujours mettre les affaires de Julien à sa portée et de manière accessible afin qu'il puisse s'habiller seul. | X20: FALSE | Y20: FALSE | Z20: FALSE | AA20: FALSE | AB20: Il s'exprime bien pour tout ce qui est courant: envies, joies et tristesses. | AD20: Céline | AE20: Thierry, Carole, Sabine, Pierre-Yves, Anne-Françoise, Pierre, Paul | AF20: Il est très attaché à sa famille. Il a des oncles et des tantes à Gèneve, à Zurich et à Neuchâtel. Julien aime la musique, la nature, la fête, les amis et le chant. Il aime aussi son travail aux ateliers du Foyer Valais de Cœur à Sierre. Le karaoké. Il fait partie du Cœur du Cœur. Il vit en appartement protégé. | AH20: Il est autonome pour les repas. | AJ20: Il prend toujours des pruneaux secs au déjeuner | AK20: le Lait | AM20: Verre d'eau chaude au réveil pour faciliter son transit. Un kiwi ou jus d'orange pour déjeuner serait idéal. | AN20: Il aime les bières. Un café après les repas. Un verre de jus d'orange au déjeuner. | AP20: le fromage | BA20: 2146188983 | BD20: 2146188985 | BE20: 2146188985 | BF20: 190 51 144 | BG20: IMC | BH20: Handicap mental | BI20: Faible | BJ20: Protéger Julien du soleil (casquette, crème) | BK20: Besoin d'aide pour l'habillement, surtout pour attaché ses chaussures. Surveiller sa toilette sauf si douche. Il a besoin d'aide pour se laver le dos.. | BL20: Julien est autonome mais il faut vérifier qu'il aille à selle. (si possible chaque deux jours). | BM20: Prévention escarres, douche (avec de l'aide). Pour la douche, si le siège est adapté à hauter du fauteuil roulant. Julien se débrouille bien, il faut surveiller qu'il fasse bien le passage. | BN20: Il fait une sieste après le repas ou en fonction de nos activités.
A21: -587438322 | B21: 42507 | D21: 0 | E21: 0 | F21: 0 | H21: Groupe B2 Claudia Balet - 024 473 51 42 | I21: FALSE | J21: TRUE | K21: TRUE | L21: FALSE | M21: FALSE | N21: FALSE | O21: FALSE | P21: TRUE | Q21: FALSE | R21: Supporte les longs trajets en bus. Dans le fauteuil : bien l'attacher à la taille et au torse | S21: René n'aime pas et ne veut pas aller à la piscine. Présence d'une personne obligatoire pour le tenir. | T21: TRUE | U21: TRUE | V21: Aide totale (complétement dépendant du soignant) | W21: si possible, il fait la sieste après le dîner. Lui mettre un coussin entre les jambes et sous les pieds. Au coucher : mettre un coussin entre ses jambes et sous ses pieds | X21: FALSE | Y21: FALSE | Z21: FALSE | AA21: TRUE | AB21: oral. René comprend tout ce qu’on lui dit en français et en allemand. Il répond aux questions posées par oui ou par non. | AC21: Mère : décédée | AD21: Jean-Claude - décédé | AF21: Il aime participer à toutes sortes d'activités et aime surtout dialoguer et écouter des contes ou histoires. Il aime l’humour et se montre très jovial. | AG21: René n'aime pas trop regarder la télévision. | AH21: couper très, très fin, voir mixer certains aliments sinon fausse route.couper fin, lui donner à manger | AL21: Biscuits secs et gros morceaux | AM21: René boit avec de l’aide. 2 gobelets par repas avec de l’épaississant. | AO21: n'aime pas le lait | BA21: 107 | BB21: 0 | BC21: 0 | BD21: 2146189018 | BE21: 2146189008 | BF21: 158 18 100 | BG21: leucodystrophie à évolution lente | BH21: troubles moteurs | BI21: Elevé | BJ21: Protéger René du soleil (chapeau, crème). | BK21: René est tout à fait dépendant du soignant. Il prend une douche chaque jour ou lui faire une toilette au lit. Il sait cracher dans le haricot après le brossage des dents. Lui masser les jambes avec du lait corporel. Bien lui sécher les mains, les pieds et sous les bras (risque de mycose). Il faut éviter les plis des habits lors de l’installation dans sa chaise et bien le positionner au fond de la chaise et toujours l’attacher (risque de chutes). | BL21: René est langé jour et nuit (le changer 3x par jour, 1x par nuit) | BM21: A prévenir - douche | BN21: Il dort sur le côté, mais il faut le tourner de l’autre côté une fois durant la nuit. Avec un coussin entre les jambes et sous les pieds (éviter les frottements). Après le repos de midi. | BO21: 1Xnuit et après le repos de midi
A22: -568750303 | B22: 42524 | C22: -464138546 | E22: -464138546 | G22: 2146189132 | H22: B3 - 0244735143 | I22: FALSE | J22: FALSE | K22: FALSE | L22: TRUE | M22: FALSE | N22: FALSE | O22: FALSE | P22: TRUE | Q22: TRUE | R22: aucun problème | S22: Aide de l'accompagnement + gillet. N'apprécie pas beaucoup la piscine | T22: FALSE | U22: FALSE | V22: Stéphane aime choisir ses habits la veille.Il a besoin d'une aide complète pour l'habillement et la toilette. | W22: Il a tendance à aller au lit tôt. Il se fatigue vite. Dort sur le ventre | X22: FALSE | Y22: FALSE | Z22: FALSE | AA22: TRUE | AB22: Il utilise un classeur de communication et se montre expressif dans sa gestuelle. Il montre avec la tête quelle option il choisit. Stéphane est quelqu'un de jovial, souvent de bonne humeur. Quand ça n'est pas le cas, il peut pincer ou donner des coups de pieds. | AF22: Il aime l'émission "N'oubliez pas les paroles" sur France2 et le foot. Il apprécie jouer au bowling, regarder les films sentimentaux. Il aime aller au cinéma, au spectacle. Est un très bon spectateur, karaoké | AH22: Il a besoin d'une aide pour lui donner à manger à et boire. Un verre avec une pipette à donner par l'éducateur. IL aime les jus de fruits sans gaz ou sirop. IL préfère le cacao le matin. Il mange avec une cuillère ou fourchette normale. Il sait dire ce qu'il apprécie ou pas. Lui donner qu'un service. Nourriture coupée fine, donnée par l'éducateur | AM22: verre à bec verseur : il mord un peu mais il arrive à boire sans problème avec de l'aide | AN22: jus de fruits sans gaz ou sirop. Préfère le cacao le matin | BA22: 107 | BD22: 2146188969 | BF22: 756.1168.7015.03 | BG22: IMC mixte. Athétosique/spastique | BH22: Handicap mental | BI22: Elevé | BK22: Aide totale : douche, sur chaise percée | BL22: Aide totale : n'est pas langé. Aux toilettes en principe après les repas - avec chaise percée. Urinoir dans son sac derrière la chaise pour les déplacements. | BN22: après le diner | BO22: couché
A23: -486550603 | B23: 42886 | D23: 166 | F23: 1434 | G23: 2146189000 | H23: Danaëlle Savioz 027 451 21 81 (027 451 21 81 infir | I23: TRUE | J23: FALSE | K23: FALSE | L23: FALSE | M23: FALSE | N23: FALSE | O23: FALSE | P23: TRUE | Q23: TRUE | R23: Supporte les longs trajets en bus en principe, oui. Mais voir la route devant. Prend de l’Itinerol pour les trajets sinueux | S23: Faire attention à sa sonde et soutenir Janique selon son besoin. | T23: FALSE | U23: TRUE | V23: Aide totale | W23: à voir avec Janique 1 barrière + lit contre mur. Attention, choisir un lit ou elle tourne le dos au mur pour faire pendre ensuite son uriflak. Attention, elle ne voit pas la nuit. Pas la laisser seule pour les toilettes. | X23: FALSE | Y23: FALSE | Z23: FALSE | AA23: TRUE | AB23: Oral. Janique sait bien se faire comprendre. | AC23: Elle s’exprime elle-même à se sujet. | AD23: Fabian et Nathalie | AF23: Elle croque la vie à pleine dents. Musique française, karaoké, chante à l'ASA-Valais, lecture, shopping | AG23: les jeux de société style « Hâte-toi lentement », les jeux de cartes | AH23: couper. Aider à manger vers la fin du repas. Janique emploie une cuillère spéciale et une assiette + collerette posée sur un sous plat antiglisse. Il faut parfois l’aider, si elle est trop fatiguée.Il faut faire attention à son poids, donc surveiller la quantité. Pour encourager Janique à suivre son régime, servir son repas plutôt dans une assiette à dessert, limiter les féculents et la viande mais pas les légumes. Essayer d’être à table avec des personnes ayant aussi besoin de s’encourager à perdre du poids (accompagnant ou participant).lui mettre des demi.portions. Prend le dessert à 16h. Si tousse lors des repas, la conduire à l'écart, attitude rassurante | AI23: gratin, papé vaudois | AJ23: éviter sucreries en grande quantité et le grignotage et les aliments trop gras. | AK23: limiter les produits laitiers. Elle peut manger un yogourt (à la place d’autre chose) Fenouille, fruits de mer, œuf dur, choux fleurs -> attention à sa toux. | AM23: A la paille / lui donner à la fin du repas 1 dl eau + souhait 1 dl de café | AN23: eau-café noir et 2 assugrines | AO23: éviter les choses sucrées | AP23: sodas / Boissons sucrées ou grasses | BA23: 2146189022 | BD23: 2146189011 | BE23: 2146189011 | BF23: 184 25 597 / 0002 | BG23: IMC | BH23: troubles moteurs, troubles visuels,très vite angoisée | BI23: Elevé | BJ23: protéger Janique du soleil (chapeau, crème) | BK23: Aide totale,Janique à une sonde urinaire elle à tendance à être souvent constipée,si pas de selles pendant 3 jours,il faut lui faire un mycrocliste. Petite toilette Lactacyd | BL23: sonde sous-pubienne. Janique a une sonde sous-pubienne. Elle demande pour aller aux toilettes. Attention à ce qu’elle ne soit pas penchée trop en avant pour éviter de faire une pression sur sonde. Ne pas changer l'uriflac sauf s'il est percé ou s'il est abimé.Pensement cysto Ma et Ve. | BM23: Matin et soir toilette intime minutieuse, bien sécher au foehn car risque important de rougeur. A chaque changement de protection lui faire une peite toilette intime et bien la sécher. | BN23: Elle le fait elle-même avec sa chaise. Lui rappeler de lever ses jambes (surtout au niveau des pieds). Avec aide. Au lit: Coussin "banane" de positionnement autour de la jambe gauche. Bas de soutien le matin
A24: -479406894 | B24: 42969 | C24: 166 | D24: 0 | E24: 0 | F24: 0 | G24: 166 | H24: Vs Coeur - Annick Savioz 027 451 21 84 | I24: FALSE | J24: TRUE | K24: FALSE | L24: FALSE | M24: FALSE | N24: TRUE | O24: FALSE | P24: TRUE | Q24: TRUE | R24: Argent de poche : connaît la valeur de l'argent Supporte les longs trajets en bus | S24: Présence d'une personne obligatoire pour le tenir, de préférence un gilet, Fabian n'aime pas l'eau froide. | T24: TRUE | U24: TRUE | V24: Aide nécessaire complète. Protocole Pansement:siège,pli interfessier:laver avec protosan solution,mettre bépanthène onguent autour-Plis inguinaux:Laver avec bétadine-sécher-talc-compresse- Verge:si rougeur ou lésion,mettre Cavilon,laisser sécher avant de remettre le condom | W24: Il apprécie avoir le lit contre le mur. Il se fatigue vite le soir. Il dort sur le côté avec un grand coussin entre les jambes. Il n'a pas de coussin sous la tête. Comme il devient vite fatigué regarder avec lui quand il veut aller se coucher. | X24: FALSE | Y24: FALSE | Z24: FALSE | AA24: TRUE | AB24: langage oral : parle et comprend tout - a besoin de temps pour répondre - lui parler lentement Apprécie les questions aux réponses oui/non. Il bégaie | AC24: Mère Christiane : y va régulièrement avec sa sœur Janique | AD24: Janique : résidente au foyer Valais de Cœur Nathalie : : mariée - 2 enfants . Maxime (1993) - Marie (1995) | AF24: Passion : cirque et cirque Knie en particulier promenades en ville - restaurants, voir et être en contact avec les gens Travail : 50 % à Valais de Cœur - avec un ordinateur | AG24: Discothèque | AH24: Couper les aliments, lui donner à manger | AI24: Fabian aime le chocolat | AJ24: N'aime pas : poisson, œufs,beurre Lui remplir l'assiette ca il a tendance à peu manger surtout les légumes. | AK24: fatigue en fin de repas ou spasmes durant le repas | AM24: Il boit avec une paille. | AN24: Sirop et coca | AQ24: Boissons alcoolisées | BA24: 2146189022 | BB24: 0 | BC24: 0 | BD24: 2146189011 | BE24: 2146189011 | BF24: 168 58 945 | BG24: IMC | BH24: troubles moteurs | BI24: Elevé | BJ24: Protéger du soleil - Rhume des foins - (voir médicaments) | BK24: Aide complète - crème protectrice sur les fesses et les pieds (matin et soir) - fesses : compresses pour le protéger - Bien sécher les plis de la peau à l'aine, en cas de rougeur (crème Pévary) idem à la hanche droite - talon : mettre la peau de mouton Huile Antidry après la toilette. | BL24: Urine : bouteille à la demande ou lors de longues sorties. Condom chaque matin - poche. Selles : chaise percée 2x/semaine (mercredi et samedi matin) | BM24: Appliquer crème protectrice sur les fesses et les pieds. Sièges : Mopilex border nettoyer au protan si nécessaire bépanthène onguent autour. Verge : si rougeur de lésion, mettre cavillon laisser sécher avant de remettre le condom. | BN24: oui sur demande Transfert avec l'élévateur. Laissez la sangle lorsqu'il est sur les WC. | BO24: la nuit
A25: -414006540 | B25: 42557 | C25: 2092442015 | I25: FALSE | J25: FALSE | K25: FALSE | L25: TRUE | M25: TRUE | N25: FALSE | O25: FALSE | P25: FALSE | Q25: FALSE | R25: Il supporte les trajet en bus. Il porte une atelle à la jambe gauche. ATTENTION aux passages piétons, il traverse toujours sans regarder. | S25: Il adore la piscine. Il faut rester avec lui, il n'a pas de manchons. S'il n'a pas le fond, il coule. | T25: FALSE | U25: TRUE | V25: Il se débrouille bien pour l'habillage et le déshabillage. A besoin d'aide pour finaliser mais demande de l'aide. | W25: Il va au lit vers les 20h00 et dors jusque vers les 7h00. En principe, il ne fait pas la sieste l’après-midi. Le soir, lui raconter une histoire avant de dormir ou une chanson. Il dort avec son doudou. | X25: FALSE | Y25: FALSE | Z25: FALSE | AA25: FALSE | AB25: Il parle distinctement avec un vocabulaire varié. Il ne tient pas toujours un discours très "à propos". Il faut parfois s'armer de patientes questions afin de réellement comprendre le fond de sa pensée. | AC25: Il vit avec sa maman et son compagnon Manu. Son papi s'appelle Alain. Son papa habite à Pont-de-la-Morge avec son amie Laurence. Il a de très bon contact familial : Tonton Jean, Tata Marina, Isa, Pépé Raoul et grand-maman Marie françoise. | AF25: Il aime les trains, les télécabines, les moyens de transport en général. Il aime aussi la musique et gentiment la lecture. Il aime la cuisine grâce à 1 chaîne Youtube. Il aime fabriquer ses propres doudous. | AG25: Il n’apprécie guère la télévision et n’aime pas se salir les mains (ex : peinture à doigt) | AH25: Alexandre mange de tout en bonne quantité. Il faut lui couper ses aliments. | AI25: Bonbons, fruits | AK25: Attention avec le sel sur la table. | AN25: Le thé froid, le sirop | AP25: il ne boit plus de lait | BA25: 2146188990 | BD25: 2146188986 | BE25: 2146188986 | BF25: 00008 375-80-187 | BG25: hydrocéphalie avec hémiparésie à gauche | BH25: trouble de l'attention, du langage, frustration avec crises de larmes et colères. | BJ25: Tendance à avoir le rhume | BK25: Il a besoin d'aide pour sa toilette. Il n'aime pas la douche. Alexandre à un drain qui passe dans son cou, à gauche. En cas de fièvre, cela pourrait indiquer que ce dernier est infecté. Prévenir la Maman de suite. | BL25: Bien veiller à le mettre aux toilettes avant/après une activité avant d'aller au lit.
A26: -362773667 | B26: 41597 | I26: FALSE | J26: FALSE | K26: FALSE | L26: FALSE | M26: TRUE | N26: FALSE | O26: FALSE | P26: TRUE | Q26: FALSE | T26: FALSE | U26: FALSE | X26: FALSE | Y26: FALSE | Z26: FALSE | AA26: FALSE | AS26: -509124961
A27: -22390883 | B27: 42886 | C27: 1201536087 | E27: 1201536087 | F27: 2146189132 | G27: 2146189132 | I27: FALSE | J27: FALSE | K27: FALSE | L27: TRUE | M27: FALSE | N27: FALSE | O27: FALSE | P27: TRUE | Q27: FALSE | R27: Supporte les longs trajets en bus - Changement de position en déplacement : basculer sa chaise. Laisser de l'espace (10cm) entre le dossier et la poignée, incliner la chaise pour éviter que le pose-pieds se coince avec les roues. | S27: Aide totale : ne flotte pas, manchons et autres moyens auxiliaires - Gesticule beaucoup | T27: FALSE | U27: TRUE | V27: Aide totale : bouge beaucoup - lui demander de se calmer | W27: Sur le dos à l'intérieur d'un drap "Zewi" - en haut de pyjama, langé et en slip. Lit avec barrières en bois car il bouge beaucoup ses bras Se fatigue vite et va tôt au lit (22h00) | X27: FALSE | Y27: TRUE | Z27: FALSE | AA27: TRUE | AB27: Pas d'expression verbale : Communication par ipad fixé sur sa table. Bouge la tête à droite pour dire "oui" à gauche pour dire "non" - Agenda pour noter les faits marquants de la journée - Comprend le français et le portugais Quand il tire la langue cela veut dire qu'il a soif | AC27: Maman : Ana Cristina Amaral - Papa : Adelino Gonçalves - séparés. (1 week-end de garde chacun) | AD27: Tania (1994) - Demi-frère Tiago (2006) | AF27: Piscine, musique, mécanique et voitures, télé. | AH27: Aide totale : Se mettre derrière lui et lui tenir le menton avec une main - bouge beaucoup - Manger : cuillère en inox - couper très fin. Couper le pain en petit morceau et mouiller les aliments. Utiliser le Masticateur. | AI27: matin : du pain,confiture (couper le pain en petits morceaux ou faire imbiber les morceaux) | AJ27: Ajouter du liquide avec les aliments c'est plus facile pour Claudio mange mieux | AM27: Claudio boit avec un verre avec un bec verseur et une bavette sous son menton | AN27: matin : café au lait ou cacao. Midi : il boit volontiers des sirops au citron ou orange et le soir des tisanes après avoir mangé ou café. | BD27: 2146188974 | BE27: 2146188974 | BF27: 092322 | BG27: IMC athétosique. Déficience mentale et toubles de vision d'origine centrale | BH27: Problèmes aux poumons il lui reste 1 seul poumon. Rhume des foins | BI27: Elevé | BJ27: Asthme en cas de trop grande excitation ou en période de floraison. Changer tout de suite le pull si celui-ci est mouillé au niveau des poumons. | BK27: Aide totale : Il bouge beaucoup - lui demander de rester calme | BL27: Lange : jour et nuit - Ne va pas sur les WC. Sur demande il arrive à faire "le pont" pour mettre une protection, enfiler ses culottes et ses pantalons | BN27: En déplacement on peut basculer sa chaise. | BO27: env. Chaque 4 heures
A28: 0 | C28: 0 | D28: 0 | E28: 0 | F28: 0 | G28: 0 | I28: FALSE | J28: FALSE | K28: FALSE | L28: FALSE | M28: FALSE | N28: FALSE | O28: FALSE | P28: FALSE | Q28: FALSE | T28: FALSE | U28: TRUE | X28: FALSE | Y28: FALSE | Z28: FALSE | AA28: FALSE | BA28: 0 | BB28: 0 | BC28: 0 | BD28: 0 | BE28: 0
A29: 107 | B29: 40980 | I29: FALSE | J29: FALSE | K29: FALSE | L29: FALSE | M29: FALSE | N29: FALSE | O29: FALSE | P29: FALSE | Q29: FALSE | T29: FALSE | U29: FALSE | X29: FALSE | Y29: FALSE | Z29: FALSE | AA29: FALSE
A30: 111 | B30: 41642 | I30: FALSE | J30: FALSE | K30: FALSE | L30: FALSE | M30: FALSE | N30: FALSE | O30: FALSE | P30: FALSE | Q30: FALSE | T30: FALSE | U30: FALSE | X30: FALSE | Y30: FALSE | Z30: FALSE | AA30: FALSE
A31: 118 | B31: 37833.434 | C31: 352 | D31: 1924 | E31: 0 | F31: 1040296365 | G31: 1040296841 | I31: FALSE | J31: FALSE | K31: FALSE | L31: FALSE | M31: FALSE | N31: FALSE | O31: FALSE | P31: FALSE | Q31: FALSE | S31: Marie-Noëlle ne sait pas nager. Il faut toujours rester près d’elle ; possibilité de faire quelques exercices (planche…). Elle aime beaucoup aller à la piscine et y va régulièrement, mais elle n’aime pas trop l’eau froide. | T31: FALSE | U31: TRUE | X31: FALSE | Y31: FALSE | Z31: FALSE | AA31: FALSE | AB31: Oral. Parle très bien. | AC31: Marie-Noëlle aime aller à la piscine, les jeux de société, la peinture, la musique française (Garou, Goldmann…) et discuter (attention : la stopper tout de suite si elle aborde des sujet tels que sa famille, le sexe et la médisance envers les autres. | AF31: Marie-Noëlle aime aller à la piscine, les jeux de société, la peinture, la musique et discuter (attention : la stopper tout de suite si elle aborde des sujet tels que sa famille, le sexe et la médisance envers les autres. | BA31: 107 | BC31: 0 | BE31: 0 | BG31: IMC | BH31: handicap mental, malvoyant, troubles moteurs | BJ31: Protéger Marie-Noëlle du soleil. | BM31: TROP PETIT??'
A32: 119 | B32: 37833.473 | C32: 138 | D32: 2210 | E32: 0 | I32: FALSE | J32: FALSE | K32: FALSE | L32: FALSE | M32: FALSE | N32: FALSE | O32: FALSE | P32: FALSE | Q32: FALSE | S32: Danielo n’a pas de problèmes pour aller à la piscine. | T32: FALSE | U32: TRUE | X32: FALSE | Y32: FALSE | Z32: FALSE | AA32: FALSE | AB32: langage oral | AC32: Danielo aime bien aller à la piscine, au cinéma et faire des promenades. | BB32: 0 | BC32: 0 | BE32: 0 | BG32: IMC | BJ32: Protéger Danielo du soleil
A33: 129 | B33: 37846.648 | C33: 0 | D33: 0 | E33: 0 | F33: 269 | G33: 269 | I33: FALSE | J33: FALSE | K33: FALSE | L33: FALSE | M33: FALSE | N33: FALSE | O33: FALSE | P33: FALSE | Q33: FALSE | S33: Elle se débrouille, mais une présence à ses côtés est préférable. | T33: FALSE | U33: FALSE | X33: FALSE | Y33: FALSE | Z33: FALSE | AA33: FALSE | AB33: Langage oral | AC33: Anne-Claude apprécie le cinéma, la piscine, etc. Elle se montre intéressée par les différentes activités proposées. | BB33: 0 | BC33: 0 | BE33: 0 | BH33: Dysmorphysme congénital, lambosciatalgie gauche | BJ33: propyphenazare, protéger du soleil, utiliser des pansements hypoallergéniques
A34: 138 | B34: 42858 | C34: -2099377383 | I34: FALSE | J34: FALSE | K34: FALSE | L34: TRUE | M34: TRUE | N34: FALSE | O34: FALSE | P34: TRUE | Q34: FALSE | R34: Il supporte bien les longs trajets. Daniélo marche avec des cannes. Et pour les sorties plus longues il a un fauteil manuel. | S34: Rester attentif et l'aider en cas de besoin | T34: TRUE | U34: FALSE | V34: Il s'habille seul, mais il a besoin de temps | W34: - | X34: FALSE | Y34: FALSE | Z34: FALSE | AA34: FALSE | AB34: Il s'exprime oralement. | AC34: Les parents sont mariés Danièlo est au Foyer St-Hubert à Martigny | AD34: Il a un frère (Fabrice) | AE34: - | AF34: Daniélo aime la piscine, le cinéma et les promenades. | AG34: - | AH34: Daniélo mange seul | AI34: - | AJ34: - | AK34: - | AL34: - | AM34: Il boit seul | AN34: - | AO34: - | AP34: - | AQ34: - | BA34: 2146188992 | BD34: 2146189294 | BE34: 2146189294 | BF34: 482-64-270 | BG34: IMC | BH34: - | BI34: Moyen | BJ34: protéger du soleil (casquette + crème) | BK34: autonome mais a besoin de temps | BL34: il va seul aux toilettes | BM34: - | BN34: pas nécessaire | BO34: 0
A35: 160 | B35: 37847.64 | C35: 2210 | D35: 2210 | E35: 0 | F35: 0 | I35: FALSE | J35: FALSE | K35: FALSE | L35: FALSE | M35: FALSE | N35: FALSE | O35: FALSE | P35: FALSE | Q35: FALSE | S35: Il nage avec un gilet de sauvetage | T35: TRUE | U35: FALSE | X35: FALSE | Y35: FALSE | Z35: FALSE | AA35: FALSE | AB35: Il parle | AC35: Ce qu'il préfère c'est aller au cinéma. | BB35: 0 | BC35: 0 | BD35: 0 | BE35: 0 | BG35: IMC | BH35: troubles moteurs | BJ35: supporte le soleil avec un chapeau
A36: 166 | B36: 41927 | I36: FALSE | J36: FALSE | K36: FALSE | L36: FALSE | M36: FALSE | N36: FALSE | O36: FALSE | P36: FALSE | Q36: FALSE | T36: FALSE | U36: FALSE | X36: FALSE | Y36: FALSE | Z36: FALSE | AA36: FALSE
A37: 167 | B37: 37858.51 | C37: 2210 | D37: 166 | F37: 0 | G37: 269 | I37: FALSE | J37: FALSE | K37: FALSE | L37: FALSE | M37: FALSE | N37: FALSE | O37: FALSE | P37: FALSE | Q37: FALSE | S37: Faire attention à sa sonde et soutenir Janique selon son besoin. | T37: FALSE | U37: TRUE | X37: FALSE | Y37: FALSE | Z37: FALSE | AA37: FALSE | AB37: oral | AC37: Elle s’exprime elle-même à se sujet. | AG37: cartes, jeux de société (Hâte-toi lentement...) | BB37: 0 | BC37: 0 | BE37: 0 | BG37: IMC | BH37: troubles moteurs, troubles visuels. | BJ37: protéger Janique du soleil (chapeau, crème).
A38: 175 | B38: 37858.71 | C38: 0 | D38: 174 | E38: 0 | F38: 269 | G38: 269 | I38: FALSE | J38: FALSE | K38: FALSE | L38: FALSE | M38: FALSE | N38: FALSE | O38: FALSE | P38: FALSE | Q38: FALSE | S38: Christophe a besoin d’une bouée adaptée et d’être soutenu. | T38: FALSE | U38: TRUE | X38: FALSE | Y38: FALSE | Z38: FALSE | AA38: FALSE | AB38: Christophe s’exprime à l’aide d’un tableau « Bliss ». | AC38: Christophe aime bien le football, le hockey et le tennis. Il aime bien discuter avec les acompagnant(e)s. | AG38: Les expositions de peinture etc. | BA38: 107 | BB38: 0 | BC38: 0 | BD38: 0 | BE38: 0 | BG38: IMC | BH38: troubles moteurs | BJ38: protéger Christophe du soleil (chapeau, crème)
A39: 177 | B39: 42888 | D39: 2210 | E39: -1226171744 | F39: 2146189103 | G39: -1226171744 | H39: Steve Quarroz 024 473 52 30 | I39: FALSE | J39: TRUE | K39: FALSE | L39: TRUE | M39: FALSE | N39: FALSE | O39: FALSE | P39: TRUE | Q39: TRUE | R39: Supporte les longs trajets en bus. Se déplace quelquefois à 4 pattes. | S39: Vlada a besoin d'être soutenue. | T39: FALSE | U39: TRUE | V39: Aide totale pour s'habiller - Arrive à se déshabiller | W39: Position: plutôt sur le ventre et sans coussin. ETRE ATTENTIF DURANT LA VEILLE (fait des crises d'épilepsie durant le nuit) | X39: FALSE | Y39: FALSE | Z39: FALSE | AA39: TRUE | AB39: Langage oral | AC39: Parents mariés | AD39: Vlada a une sœur (Malina de 1984 qui est mariée à Davide). 3 neveux (Avril née en 2007, Maorie née en 2010, Siloé né en 2015) | AF39: Elle aime bien écouter de la musique et des histoires d’enfants. Elle aime danser. Elle cherche le contact avec les adultes. Elle aime aussi les poupées, les chiens et les chats (mais de loin). Elle aime aussi les motos. | AH39: A besoin d'aide pour couper fin les aliments. Elle mélange le chaud et le froid; ce qui est froid elle dit chaud. | AI39: Poisson, moules et fruits de mer | AJ39: éviter les aliments trop sucré, proposer des fruits à la place. Etre attentif à son régime alimentaire : beaucoup de salades, de légumes et de fruits. | AK39: N'aime pas les carottes cuites et les petits pois. | AL39: crème, fromage et viande grasse | AM39: Boit normalement sans paille | AO39: Pas de boissons trop sucrées | AP39: le lait entier (de préférence lait maigre) | BA39: 107 | BB39: 2146189422 | BC39: 0 | BD39: 2146188971 | BE39: 2146188971 | BF39: 95278823 | BG39: hémiplégie côté droit IMC | BH39: Handicap mental, épilepsie | BI39: Elevé | BJ39: Vlada doit être protégée du soleil (crème, chapeau) | BK39: Durant week-end toilette au lit 1fois par jour. Durant les camps regarder avec elle pour prendre la douche. Pour chaque soins bien rincer le savon et bien essuyer. | BL39: Elle demande "j'ai mal au ventre" pour aller au WC. Elle s'essuie toute seule pour l'urine mais avec aide pour les selles. Elle va au lever à selles tous les jours. | BM39: faire au minimum 1 changement de position par jour | BN39: soit assise par terre avec les jambes devant, soit dans le lit. En lui tenant les 2 main, elle arrive à marcher sur des courtts trajets (WC-Pour aller au lit) | BO39: min. 1 fois par jour
A40: 179 | B40: 38104.568 | C40: 0 | D40: 0 | E40: 0 | F40: 0 | G40: 0 | I40: FALSE | J40: FALSE | K40: FALSE | L40: FALSE | M40: FALSE | N40: FALSE | O40: FALSE | P40: FALSE | Q40: FALSE | S40: Surveiller Kathia à cause des crises d'épilepsie | T40: FALSE | U40: TRUE | X40: FALSE | Y40: FALSE | Z40: FALSE | AA40: FALSE | AB40: Oral | AC40: Kathia a un frère qui s'appelle Gabriel (1979) et qui a une copine (Chimène). Elle aime bien Roch Voisine. Elle travaille aux ateliers de la FOVHAM à Sion. | BA40: 0 | BB40: 0 | BC40: 0 | BD40: 0 | BE40: 0 | BG40: IMC Légère | BH40: Epilepsie de 1x par semestre à 4x par mois. Facteur déclencheur: boisons sucrée et dessert et émotion forte | BJ40: Rhume des foins
...

Sheet migInfoMédical
A1: medId | B1: medConId | C1: medAlimCommentair | D1: medAlimPrefere | E1: medAlimRegime | F1: medAlimDecons | G1: medAlimInterdit | H1: medBoisCondition | I1: medBoisPrefere | J1: medBoisRegime | K1: medBoisDecons | L1: medBoisInterdit | M1: medMedecin1 | N1: medMedecin2 | O1: medMedecin3 | P1: medCaisseMaladie | Q1: medAccident | R1: medNoAssure | S1: medTypeHandicap | T1: medHandicapsAsso | U1: medDegre | V1: medAllergies | W1: medToilette | X1: medEncontinence | Y1: medEscarres | Z1: medOfasType | AA1: medOfasPluri | AB1: medOfasReconnu | AC1: medMaj
B2: =gescon_infosparticip!A1 -> membre | C2: =gescon_infosparticip!AH1 -> autonomierepas | D2: =gescon_infosparticip!AI1 -> alim_prefere | E2: =gescon_infosparticip!AJ1 -> alim_regime | F2: =gescon_infosparticip!AK1 -> alim_decons | G2: =gescon_infosparticip!AL1 -> alim_interdit | H2: =gescon_infosparticip!AM1 -> bois_condition | I2: =gescon_infosparticip!AN1 -> bois_prefere | J2: =gescon_infosparticip!AO1 -> bois_regime | ... L2: =gescon_infosparticip!AQ1 -> bois_interdit | M2: =gescon_infosparticip!BA1 -> Medecin 1 | N2: =gescon_infosparticip!BB1 -> Medecin 2 | O2: =gescon_infosparticip!BC1 -> Medecin 3 | P2: =gescon_infosparticip!BD1 -> Caisse maladie | Q2: =gescon_infosparticip!BE1 -> Accident | R2: =gescon_infosparticip!BF1 -> no_assuré | S2: =gescon_infosparticip!BG1 -> Type de handicap | T2: =gescon_infosparticip!BH1 -> Handicaps Associés | ... Y2: =gescon_infosparticip!BM1 -> escarres

Sheet migAloIntervenant
A1: aloIntId | B1: aloIntBeneficiare | C1: aloIntA | D1: aloIntB | E1: aloIntC | F1: aloIntD
B2: =gescon_infosparticip!A1 -> membre | C2: =gescon_infosparticip!AS1 -> Interv_A | D2: =gescon_infosparticip!AT1 -> Interv_B | E2: =gescon_infosparticip!AU1 -> Interv_C | F2: =gescon_infosparticip!AV1 -> Interv_R

Sheet migInfoSocial
A1: socId | B1: socConId | C1: socMaj | D1: socPere | E1: socMere | F1: socTuteur | G1: socInstitution | H1: socUrgence | I1: socReferentInstitut | J1: socGereseul | K1: socAvecaidephys | L1: socAvecconseil | M1: socNegerepas | N1: socMarcheseul | O1: socMarchaide | P1: socMarchauxi | Q1: socFauteuilMan | R1: socFauteuilElec | S1: socDeplacement | T1: socHabillement | U1: socPiscine | V1: socPublication | W1: socPiscineGilet | X1: socSomeil | Y1: socatache | Z1: socdrapspec | AA1: socgilet | AB1: socbarriere | AC1: socExpresssion | AD1: socFamille | AE1: socFraterie | AF1: socAmis | AG1: socPassions | AH1: socAimePas | AI1: socPossitionJour | AJ1: socFrequenceJour
B2: =gescon_infosparticip!A1 -> membre | C2: =gescon_infosparticip!B1 -> Dernière mise à jour | D2: =gescon_infosparticip!C1 -> Fils de(Père) | E2: =gescon_infosparticip!D1 -> Fils de(Mère) | F2: =gescon_infosparticip!E1 -> Tuteur | G2: =gescon_infosparticip!F1 -> Institution | H2: =gescon_infosparticip!G1 -> Adresse urgence | I2: =gescon_infosparticip!H1 -> Referent_institut | ... S2: =gescon_infosparticip!R1 -> Long_dep | T2: =gescon_infosparticip!V1 -> habillement | U2: =gescon_infosparticip!S1 -> Piscine_coment | V2: =gescon_infosparticip!U1 -> Publication | W2: =gescon_infosparticip!T1 -> Piscine_gilet | X2: =gescon_infosparticip!W1 -> someil | Y2: =gescon_infosparticip!X1 -> acnuit_atache | Z2: =gescon_infosparticip!Y1 -> acnuit_drapspec | AA2: =gescon_infosparticip!Z1 -> acnuit_gilet | AB2: =gescon_infosparticip!AA1 -> acnuit_barriere | AC2: =gescon_infosparticip!AB1 -> Expresssion | AD2: =gescon_infosparticip!AC1 -> Famille | AE2: =gescon_infosparticip!AD1 -> Fraterie | ... AH2: =gescon_infosparticip!AG1 -> Activités peu appréciées | AI2: =gescon_infosparticip!BN1 -> change_pos | AJ2: =gescon_infosparticip!BO1 -> frequence_change
